Workbook

Sheet 1

Sheet Annual Summary
D11: 2022 | E11: =+D11+1 | F11: Variance | G11: =+E11+1 | H11: Variance | I11: =+G11+1 | J11: Variance | K11: =+I11+1 | L11: =+K11+1 | M11: =+L11+1 | N11: =+M11+1 | O11: =+N11+1
C13: Service Income | D13: =SUMIF('Monthly Detail'!$1:$1,'Annual Summary'!D$11, 'Monthly Detail'!12:12) | E13: =SUMIF('Monthly Detail'!$1:$1,'Annual Summary'!E$11, 'Monthly Detail'!12:12) | F13: =+E13-D13 | G13: =SUMIF('Monthly Detail'!$1:$1,'Annual Summary'!G$11, 'Monthly Detail'!12:12) | H13: =+G13-E13 | I13: =SUMIF('Monthly Detail'!$1:$1,'Annual Summary'!I$11, 'Monthly Detail'!12:12) | J13: =+I13-G13 | K13: =SUMIF('Monthly Detail'!$1:$1,'Annual Summary'!K$11, 'Monthly Detail'!12:12) | L13: =SUMIF('Monthly Detail'!$1:$1,'Annual Summary'!L$11, 'Monthly Detail'!12:12) | M13: =SUMIF('Monthly Detail'!$1:$1,'Annual Summary'!M$11, 'Monthly Detail'!12:12) | N13: =SUMIF('Monthly Detail'!$1:$1,'Annual Summary'!N$11, 'Monthly Detail'!12:12) | O13: =SUMIF('Monthly Detail'!$1:$1,'Annual Summary'!O$11, 'Monthly Detail'!12:12)
C14: Tips | D14: =SUMIF('Monthly Detail'!$1:$1,'Annual Summary'!D$11, 'Monthly Detail'!13:13) | E14: =SUMIF('Monthly Detail'!$1:$1,'Annual Summary'!E$11, 'Monthly Detail'!13:13) | F14: =+E14-D14 | G14: =SUMIF('Monthly Detail'!$1:$1,'Annual Summary'!G$11, 'Monthly Detail'!13:13) | H14: =+G14-E14 | I14: =SUMIF('Monthly Detail'!$1:$1,'Annual Summary'!I$11, 'Monthly Detail'!13:13) | J14: =+I14-G14 | K14: =SUMIF('Monthly Detail'!$1:$1,'Annual Summary'!K$11, 'Monthly Detail'!13:13) | L14: =SUMIF('Monthly Detail'!$1:$1,'Annual Summary'!L$11, 'Monthly Detail'!13:13) | M14: =SUMIF('Monthly Detail'!$1:$1,'Annual Summary'!M$11, 'Monthly Detail'!13:13) | N14: =SUMIF('Monthly Detail'!$1:$1,'Annual Summary'!N$11, 'Monthly Detail'!13:13) | O14: =SUMIF('Monthly Detail'!$1:$1,'Annual Summary'!O$11, 'Monthly Detail'!13:13)
C15: Total Income | D15: =SUM(D13:D14) | E15: =SUM(E13:E14) | F15: =+E15-D15 | G15: =SUM(G13:G14) | H15: =+G15-E15 | I15: =SUM(I13:I14) | J15: =+I15-G15 | K15: =SUM(K13:K14) | L15: =SUM(L13:L14) | M15: =SUM(M13:M14) | N15: =SUM(N13:N14) | O15: =SUM(O13:O14)
C16: EOY # of Students | D16: =+SUMIFS('Monthly Detail'!17:17,'Monthly Detail'!4:4,DATE(D11,12,31)) | E16: =+SUMIFS('Monthly Detail'!17:17,'Monthly Detail'!4:4,DATE(E11,12,31)) | F16: =+E16-D16 | G16: =+SUMIFS('Monthly Detail'!17:17,'Monthly Detail'!4:4,DATE(G11,12,31)) | H16: =+G16-E16 | I16: =+SUMIFS('Monthly Detail'!17:17,'Monthly Detail'!4:4,DATE(I11,12,31)) | J16: =+I16-G16 | K16: =+SUMIFS('Monthly Detail'!17:17,'Monthly Detail'!4:4,DATE(K11,12,31)) | L16: =+SUMIFS('Monthly Detail'!17:17,'Monthly Detail'!4:4,DATE(L11,12,31)) | M16: =+SUMIFS('Monthly Detail'!17:17,'Monthly Detail'!4:4,DATE(M11,12,31)) | N16: =+SUMIFS('Monthly Detail'!17:17,'Monthly Detail'!4:4,DATE(N11,12,31)) | O16: =+SUMIFS('Monthly Detail'!17:17,'Monthly Detail'!4:4,DATE(O11,12,31))
C17: YOY Compounded Growth % | E17: =(E15/D15)-1 | F17: =+E17-D17 | G17: =(G15/E15)-1 | H17: =+G17-E17 | I17: =(I15/G15)-1 | J17: =+I17-G17 | K17: =(K15/I15)-1 | L17: =(L15/K15)-1 | M17: =(M15/L15)-1 | N17: =(N15/M15)-1 | O17: =(O15/N15)-1
C19: Subcontractor Expenses | D19: =SUMIF('Monthly Detail'!$1:$1,'Annual Summary'!D$11, 'Monthly Detail'!$65:$65) | E19: =SUMIF('Monthly Detail'!$1:$1,'Annual Summary'!E$11, 'Monthly Detail'!$65:$65) | F19: =+E19-D19 | G19: =SUMIF('Monthly Detail'!$1:$1,'Annual Summary'!G$11, 'Monthly Detail'!$65:$65) | H19: =+G19-E19 | I19: =SUMIF('Monthly Detail'!$1:$1,'Annual Summary'!I$11, 'Monthly Detail'!$65:$65) | J19: =+I19-G19 | K19: =SUMIF('Monthly Detail'!$1:$1,'Annual Summary'!K$11, 'Monthly Detail'!$65:$65) | L19: =SUMIF('Monthly Detail'!$1:$1,'Annual Summary'!L$11, 'Monthly Detail'!$65:$65) | M19: =SUMIF('Monthly Detail'!$1:$1,'Annual Summary'!M$11, 'Monthly Detail'!$65:$65) | N19: =SUMIF('Monthly Detail'!$1:$1,'Annual Summary'!N$11, 'Monthly Detail'!$65:$65) | O19: =SUMIF('Monthly Detail'!$1:$1,'Annual Summary'!O$11, 'Monthly Detail'!$65:$65)
C20: Gross Margin | D20: =D15-D19 | E20: =E15-E19 | F20: =+E20-D20 | G20: =G15-G19 | H20: =+G20-E20 | I20: =I15-I19 | J20: =+I20-G20 | K20: =K15-K19 | L20: =L15-L19 | M20: =M15-M19 | N20: =N15-N19 | O20: =O15-O19
C21: GM % | D21: =+D20/D15 | E21: =+E20/E15 | F21: =+E21-D21 | G21: =+G20/G15 | H21: =+G21-E21 | I21: =+I20/I15 | J21: =+I21-G21 | K21: =+K20/K15 | L21: =+L20/L15 | M21: =+M20/M15 | N21: =+N20/N15 | O21: =+O20/O15
C23: Sales & Marketing Expenses | D23: =SUMIF('Monthly Detail'!$1:$1,'Annual Summary'!D$11, 'Monthly Detail'!$72:$72) | E23: =SUMIF('Monthly Detail'!$1:$1,'Annual Summary'!E$11, 'Monthly Detail'!$72:$72) | F23: =+E23-D23 | G23: =SUMIF('Monthly Detail'!$1:$1,'Annual Summary'!G$11, 'Monthly Detail'!$72:$72) | H23: =+G23-E23 | I23: =SUMIF('Monthly Detail'!$1:$1,'Annual Summary'!I$11, 'Monthly Detail'!$72:$72) | J23: =+I23-G23 | K23: =SUMIF('Monthly Detail'!$1:$1,'Annual Summary'!K$11, 'Monthly Detail'!$72:$72) | L23: =SUMIF('Monthly Detail'!$1:$1,'Annual Summary'!L$11, 'Monthly Detail'!$72:$72) | M23: =SUMIF('Monthly Detail'!$1:$1,'Annual Summary'!M$11, 'Monthly Detail'!$72:$72) | N23: =SUMIF('Monthly Detail'!$1:$1,'Annual Summary'!N$11, 'Monthly Detail'!$72:$72) | O23: =SUMIF('Monthly Detail'!$1:$1,'Annual Summary'!O$11, 'Monthly Detail'!$72:$72)
C24: General & Admintrative Expenses | D24: =SUMIF('Monthly Detail'!$1:$1,'Annual Summary'!D$11, 'Monthly Detail'!$95:$95) | E24: =SUMIF('Monthly Detail'!$1:$1,'Annual Summary'!E$11, 'Monthly Detail'!$95:$95) | F24: =+E24-D24 | G24: =SUMIF('Monthly Detail'!$1:$1,'Annual Summary'!G$11, 'Monthly Detail'!$95:$95) | H24: =+G24-E24 | I24: =SUMIF('Monthly Detail'!$1:$1,'Annual Summary'!I$11, 'Monthly Detail'!$95:$95) | J24: =+I24-G24 | K24: =SUMIF('Monthly Detail'!$1:$1,'Annual Summary'!K$11, 'Monthly Detail'!$95:$95) | L24: =SUMIF('Monthly Detail'!$1:$1,'Annual Summary'!L$11, 'Monthly Detail'!$95:$95) | M24: =SUMIF('Monthly Detail'!$1:$1,'Annual Summary'!M$11, 'Monthly Detail'!$95:$95) | N24: =SUMIF('Monthly Detail'!$1:$1,'Annual Summary'!N$11, 'Monthly Detail'!$95:$95) | O24: =SUMIF('Monthly Detail'!$1:$1,'Annual Summary'!O$11, 'Monthly Detail'!$95:$95)
C25: Owner Guarenteed Payments | D25: =SUMIF('Monthly Detail'!$1:$1,'Annual Summary'!D$11, 'Monthly Detail'!96:96) | E25: =SUMIF('Monthly Detail'!$1:$1,'Annual Summary'!E$11, 'Monthly Detail'!96:96) | F25: =+E25-D25 | G25: =SUMIF('Monthly Detail'!$1:$1,'Annual Summary'!G$11, 'Monthly Detail'!96:96) | H25: =+G25-E25 | I25: =SUMIF('Monthly Detail'!$1:$1,'Annual Summary'!I$11, 'Monthly Detail'!96:96) | J25: =+I25-G25 | K25: =SUMIF('Monthly Detail'!$1:$1,'Annual Summary'!K$11, 'Monthly Detail'!96:96) | L25: =SUMIF('Monthly Detail'!$1:$1,'Annual Summary'!L$11, 'Monthly Detail'!96:96) | M25: =SUMIF('Monthly Detail'!$1:$1,'Annual Summary'!M$11, 'Monthly Detail'!96:96) | N25: =SUMIF('Monthly Detail'!$1:$1,'Annual Summary'!N$11, 'Monthly Detail'!96:96) | O25: =SUMIF('Monthly Detail'!$1:$1,'Annual Summary'!O$11, 'Monthly Detail'!96:96)
C26: Operating Expense | D26: =SUM(D23:D25) | E26: =SUM(E23:E25) | F26: =+E26-D26 | G26: =SUM(G23:G25) | H26: =+G26-E26 | I26: =SUM(I23:I25) | J26: =+I26-G26 | K26: =SUM(K23:K25) | L26: =SUM(L23:L25) | M26: =SUM(M23:M25) | N26: =SUM(N23:N25) | O26: =SUM(O23:O25)
C28: Net Operating Income (EBITDA) | D28: =D20-D26 | E28: =E20-E26 | F28: =+E28-D28 | G28: =G20-G26 | H28: =+G28-E28 | I28: =I20-I26 | J28: =+I28-G28 | K28: =K20-K26 | L28: =L20-L26 | M28: =M20-M26 | N28: =N20-N26 | O28: =O20-O26
C29: EBITDA % | D29: =D28/D15 | E29: =E28/E15 | F29: =+E29-D29 | G29: =G28/G15 | H29: =+G29-E29 | I29: =I28/I15 | J29: =+I29-G29 | K29: =K28/K15 | L29: =L28/L15 | M29: =M28/M15 | N29: =N28/N15 | O29: =O28/O15
C31: Other Income / (Expense) | D31: 0 | E31: 0 | F31: =+E31-D31 | G31: =SUMIF('Monthly Detail'!$1:$1,'Annual Summary'!G$11, 'Monthly Detail'!109:109) | H31: =+G31-E31 | I31: =SUMIF('Monthly Detail'!$1:$1,'Annual Summary'!I$11, 'Monthly Detail'!109:109) | J31: =+I31-G31 | K31: =SUMIF('Monthly Detail'!$1:$1,'Annual Summary'!K$11, 'Monthly Detail'!109:109) | L31: =SUMIF('Monthly Detail'!$1:$1,'Annual Summary'!L$11, 'Monthly Detail'!109:109) | M31: =SUMIF('Monthly Detail'!$1:$1,'Annual Summary'!M$11, 'Monthly Detail'!109:109) | N31: =SUMIF('Monthly Detail'!$1:$1,'Annual Summary'!N$11, 'Monthly Detail'!109:109) | O31: =SUMIF('Monthly Detail'!$1:$1,'Annual Summary'!O$11, 'Monthly Detail'!109:109)
C32: Net Income | D32: =D28+D31 | E32: =E28+E31 | F32: =+E32-D32 | G32: =G28+G31 | H32: =+G32-E32 | I32: =I28+I31 | J32: =+I32-G32 | K32: =K28+K31 | L32: =L28+L31 | M32: =M28+M31 | N32: =N28+N31 | O32: =O28+O31
C33: NI % | D33: =D32/D15 | E33: =E32/E15 | F33: =+E33-D33 | G33: =G32/G15 | H33: =+G33-E33 | I33: =I32/I15 | J33: =+I33-G33 | K33: =K32/K15 | L33: =L32/L15 | M33: =M32/M15 | N33: =N32/N15 | O33: =O32/O15
C34: Estimated Tax Burden | D34: =+IF(D32>0, D32*0.25, 0) | E34: =+IF(E32>0, E32*0.25, 0) | G34: =+IF(G32>0, G32*0.25, 0) | H34: =+G34-E34 | I34: =+IF(I32>0, I32*0.25, 0) | J34: =+I34-G34 | K34: =+IF(K32>0, K32*0.25, 0) | L34: =+IF(L32>0, L32*0.25, 0)
C35: S-Corp Tax Savings | I35: =+((I15-G15)+(I32-G32))*0.153 | K35: =+((K15-I15)+(K32-I32))*0.153 | L35: =+((L15-K15)+(L32-K32))*0.153
C36: Cash Balance | E36: =+SUMIF('Monthly Detail'!$4:$4, DATE(E11, 12, 31),'Monthly Detail'!$174:$174) | F36: =+SUMIF('Monthly Detail'!$4:$4, DATE(F11, 12, 31),'Monthly Detail'!$174:$174) | G36: =+SUMIF('Monthly Detail'!$4:$4, DATE(G11, 12, 31),'Monthly Detail'!$174:$174) | H36: =+G36-E36 | I36: =+SUMIF('Monthly Detail'!$4:$4, DATE(I11, 12, 31),'Monthly Detail'!$174:$174) | J36: =+I36-G36 | K36: =+SUMIF('Monthly Detail'!$4:$4, DATE(K11, 12, 31),'Monthly Detail'!$174:$174) | L36: =+SUMIF('Monthly Detail'!$4:$4, DATE(L11, 12, 31),'Monthly Detail'!$174:$174)

Sheet 2025 AOP
B8: 2025 Annual Operating Plan
C10: January | D10: February | E10: March | F10: April | G10: May | H10: June | I10: July | J10: August | K10: September | L10: October | M10: November | N10: December | P10: Total
C11: 45688 | D11: 45716 | E11: 45747 | F11: 45777 | G11: 45808 | H11: 45838 | I11: 45869 | J11: 45900 | K11: 45930 | L11: 45961 | M11: 45991 | N11: 46022 | O11: 46053
B12: Service Income | C12: 7677.1321 | D12: 12691.952 | E12: 7473.9 | F12: 9831.9706 | G12: 10732.473 | H12: 5809.4312 | I12: 10858.9 | J12: 15862.285 | K12: 12122.449 | L12: 15626.953 | M12: 8797.317 | N12: 6287.4785 | P12: 123772.24
B13: Tips | C13: 13.919186 | D13: 23.011412 | E13: 13.550712 | F13: 17.826062 | G13: 19.458736 | H13: 10.532912 | I13: 19.687958 | J13: 28.75945 | K13: 21.978862 | L13: 28.332777 | M13: 15.950161 | N13: 11.399646 | P13: 224.40787
B14: Total Income | C14: 7691.0513 | D14: 12714.964 | E14: 7487.4507 | F14: 9849.7967 | G14: 10751.932 | H14: 5819.9642 | I14: 10878.588 | J14: 15891.044 | K14: 12144.428 | L14: 15655.286 | M14: 8813.2671 | N14: 6298.8782 | P14: 123996.65
B15: # of Students | C15: 34.8 | D15: 35.8 | E15: 33.6 | F15: 32.4 | G15: 33.4 | H15: 29.2 | I15: 31.2 | J15: 37.2 | K15: 43.2 | L15: 45 | M15: 43.6 | N15: 42.2
B16: # of Sessions | C16: 34 | D16: 56 | E16: 36 | F16: 49 | G16: 76 | H16: 45 | I16: 118 | J16: 169 | K16: 125 | L16: 173 | M16: 90 | N16: 129.33333
B18: Subcontractor Expenses | C18: 0 | D18: 919.6069 | E18: 450 | F18: 1073.0882 | G18: 2850.0435 | H18: 1050 | I18: 1894.25 | J18: 4130.1794 | K18: 1256.4172 | L18: 1439.8958 | M18: 524 | N18: 0 | P18: 15587.481
B19: Gross Margin | C19: 7691.0513 | D19: 11795.357 | E19: 7037.4507 | F19: 8776.7084 | G19: 7901.8881 | H19: 4769.9642 | I19: 8984.338 | J19: 11760.865 | K19: 10888.011 | L19: 14215.39 | M19: 8289.2671 | N19: 6298.8782 | P19: 108409.17
B20: GM % | C20: 1 | D20: 0.92767522 | E20: 0.93989944 | F20: 0.89105478 | G20: 0.7349273 | H20: 0.81958652 | I20: 0.82587354 | J20: 0.74009389 | K20: 0.89654373 | L20: 0.90802494 | M20: 0.94054418 | N20: 1 | P20: 0.87429111
B22: Sales & Marketing Expenses | C22: 0 | D22: 0 | E22: 0 | F22: 0 | G22: 0 | H22: 0 | I22: 0 | J22: 0 | K22: 0 | L22: 0 | M22: 0 | N22: 0 | P22: 0
B23: General & Admintrative Expenses | C23: 1454.0336 | D23: 1416.0203 | E23: 1647.4689 | F23: 1523.6384 | G23: 1352.726 | H23: 1193.7039 | I23: 1556.8098 | J23: 2008.4271 | K23: 1397.6245 | L23: 1973.3255 | M23: 1340.2174 | N23: 1635.3956 | P23: 18499.391
B24: Operating Expenses | C24: 1454.0336 | D24: 1416.0203 | E24: 1647.4689 | F24: 1523.6384 | G24: 1352.726 | H24: 1193.7039 | I24: 1556.8098 | J24: 2008.4271 | K24: 1397.6245 | L24: 1973.3255 | M24: 1340.2174 | N24: 1635.3956 | P24: 18499.391
B26: Net Operating Income (EBITDA) | C26: 6237.0177 | D26: 10379.337 | E26: 5389.9818 | F26: 7253.0701 | G26: 6549.1621 | H26: 3576.2603 | I26: 7427.5281 | J26: 9752.4376 | K26: 9490.3861 | L26: 12242.065 | M26: 6949.0498 | N26: 4663.4826 | P26: 89909.777
B27: EBITDA % | C27: 0.81094475 | D27: 0.81630878 | E27: 0.71986875 | F27: 0.73636749 | G27: 0.60911493 | H27: 0.61448149 | I27: 0.68276583 | J27: 0.61370653 | K27: 0.78146013 | L27: 0.78197643 | M27: 0.78847601 | N27: 0.74036716 | P27: 0.72509844
B29: Other Income / (Expense) | C29: -800 | D29: -800 | E29: -800 | F29: -800 | G29: -800 | H29: -800 | I29: -800 | J29: -800 | K29: -800 | L29: -800 | M29: -800 | N29: -800 | P29: -9600
B30: Net Income | C30: 5437.0177 | D30: 9579.3366 | E30: 4589.9818 | F30: 6453.0701 | G30: 5749.1621 | H30: 2776.2603 | I30: 6627.5281 | J30: 8952.4376 | K30: 8690.3861 | L30: 11442.065 | M30: 6149.0498 | N30: 3863.4826 | P30: 80309.777
B31: NI % | C31: 0.70692776 | D31: 0.75339079 | E31: 0.61302331 | F31: 0.65514754 | G31: 0.5347097 | H31: 0.4770236 | I31: 0.60922687 | J31: 0.56336371 | K31: 0.7155863 | L31: 0.73087548 | M31: 0.69770377 | N31: 0.61336042 | P31: 0.64767699
B32: Cash Contributions | C32: 0 | D32: 0 | E32: 0 | F32: 2400 | G32: 0 | H32: 0 | I32: 0 | J32: 0 | K32: 0 | L32: 0 | M32: 0 | N32: 0 | P32: 2400
... B34: Accrued Tax Burden | C34: 1631.1053 | D34: 4744.9063 | E34: 6361.9008 | F34: 8537.8218 | G34: 10502.57 | H34: 11575.449 | I34: 13803.707 | J34: 16729.438 | K34: 19576.554 | L34: 23249.173 | M34: 25333.888 | N34: 26732.933 | P34: 26732.933
B36: Operating Cash | C36: 5910.492 | D36: 11084.272 | E36: 13626.641 | F36: 16286.345 | G36: 18578.006 | H36: 19238.674 | I36: 21452.662 | J36: 26002.178 | K36: 32304.328 | L36: 39688.856 | M36: 44161.647 | N36: 45353.467
B37: Cash Inflow (Outflow) | C37: 1691.5453 | D37: 5173.7804 | E37: 2542.3684 | F37: 2659.704 | G37: 2291.6609 | H37: 660.66802 | I37: 2213.988 | J37: 4549.5165 | K37: 6302.1499 | L37: 7384.5278 | M37: 4472.7907 | N37: 1191.8202

Sheet 2023 Overview
C10: =TEXT('Monthly Detail'!D4,"mmmm") | D10: =TEXT('Monthly Detail'!E4,"mmmm") | E10: =TEXT('Monthly Detail'!F4,"mmmm") | F10: =TEXT('Monthly Detail'!G4,"mmmm") | G10: =TEXT('Monthly Detail'!H4,"mmmm") | H10: =TEXT('Monthly Detail'!I4,"mmmm") | I10: =TEXT('Monthly Detail'!J4,"mmmm") | J10: =TEXT('Monthly Detail'!K4,"mmmm") | ... N10: =TEXT('Monthly Detail'!O4,"mmmm") | P10: Total
C11: 44957 | D11: 44985 | E11: 45016 | F11: 45046 | G11: 45077 | H11: 45107 | I11: 45138 | J11: 45169 | K11: 45199 | L11: 45230 | M11: 45260 | N11: 45291 | O11: 45322
B12: Service Income | C12: =SUMIF('Monthly Detail'!$4:$4, '2023 Overview'!C$11, 'Monthly Detail'!12:12) | D12: =SUMIF('Monthly Detail'!$4:$4, '2023 Overview'!D$11, 'Monthly Detail'!12:12) | E12: =SUMIF('Monthly Detail'!$4:$4, '2023 Overview'!E$11, 'Monthly Detail'!12:12) | F12: =SUMIF('Monthly Detail'!$4:$4, '2023 Overview'!F$11, 'Monthly Detail'!12:12) | G12: =SUMIF('Monthly Detail'!$4:$4, '2023 Overview'!G$11, 'Monthly Detail'!12:12) | H12: =SUMIF('Monthly Detail'!$4:$4, '2023 Overview'!H$11, 'Monthly Detail'!12:12) | I12: =SUMIF('Monthly Detail'!$4:$4, '2023 Overview'!I$11, 'Monthly Detail'!12:12) | J12: =SUMIF('Monthly Detail'!$4:$4, '2023 Overview'!J$11, 'Monthly Detail'!12:12) | ... N12: =SUMIF('Monthly Detail'!$4:$4, '2023 Overview'!N$11, 'Monthly Detail'!12:12) | P12: =SUM(C12:O12)
B13: Misc. | C13: =SUMIF('Monthly Detail'!$4:$4, '2023 Overview'!C$11, 'Monthly Detail'!13:13) | D13: =SUMIF('Monthly Detail'!$4:$4, '2023 Overview'!D$11, 'Monthly Detail'!13:13) | E13: =SUMIF('Monthly Detail'!$4:$4, '2023 Overview'!E$11, 'Monthly Detail'!13:13) | F13: =SUMIF('Monthly Detail'!$4:$4, '2023 Overview'!F$11, 'Monthly Detail'!13:13) | G13: =SUMIF('Monthly Detail'!$4:$4, '2023 Overview'!G$11, 'Monthly Detail'!13:13) | H13: =SUMIF('Monthly Detail'!$4:$4, '2023 Overview'!H$11, 'Monthly Detail'!13:13) | I13: =SUMIF('Monthly Detail'!$4:$4, '2023 Overview'!I$11, 'Monthly Detail'!13:13) | J13: =SUMIF('Monthly Detail'!$4:$4, '2023 Overview'!J$11, 'Monthly Detail'!13:13) | ... N13: =SUMIF('Monthly Detail'!$4:$4, '2023 Overview'!N$11, 'Monthly Detail'!13:13)
B14: Total Income | C14: =SUM(C12:C13) | D14: =SUM(D12:D13) | E14: =SUM(E12:E13) | F14: =SUM(F12:F13) | G14: =SUM(G12:G13) | H14: =SUM(H12:H13) | I14: =SUM(I12:I13) | J14: =SUM(J12:J13) | ... N14: =SUM(N12:N13) | P14: =SUM(P12:P12)
B16: Gross Margin | C16: =C14 | D16: =D14 | E16: =E14 | F16: =F14 | G16: =G14 | H16: =H14 | I16: =I14 | J16: =J14 | ... N16: =N14 | P16: =P14
B17: GM % | C17: =C16/C14 | D17: =D16/D14 | E17: =E16/E14 | F17: =F16/F14 | G17: =G16/G14 | H17: =H16/H14 | I17: =I16/I14 | J17: =J16/J14 | ... N17: =N16/N14 | P17: =P16/P14
B19: General & Admintrative Expenses | C19: =SUMIF('Monthly Detail'!$4:$4, '2023 Overview'!C$11, 'Monthly Detail'!$95:$95) | D19: =SUMIF('Monthly Detail'!$4:$4, '2023 Overview'!D$11, 'Monthly Detail'!$95:$95) | E19: =SUMIF('Monthly Detail'!$4:$4, '2023 Overview'!E$11, 'Monthly Detail'!$95:$95) | F19: =SUMIF('Monthly Detail'!$4:$4, '2023 Overview'!F$11, 'Monthly Detail'!$95:$95) | G19: =SUMIF('Monthly Detail'!$4:$4, '2023 Overview'!G$11, 'Monthly Detail'!$95:$95) | H19: =SUMIF('Monthly Detail'!$4:$4, '2023 Overview'!H$11, 'Monthly Detail'!$95:$95) | I19: =SUMIF('Monthly Detail'!$4:$4, '2023 Overview'!I$11, 'Monthly Detail'!$95:$95) | J19: =SUMIF('Monthly Detail'!$4:$4, '2023 Overview'!J$11, 'Monthly Detail'!$95:$95) | ... N19: =SUMIF('Monthly Detail'!$4:$4, '2023 Overview'!N$11, 'Monthly Detail'!$95:$95) | P19: =SUM(C19:O19)
B20: Operating Expenses | C20: =SUM(C19:C19) | D20: =SUM(D19:D19) | E20: =SUM(E19:E19) | F20: =SUM(F19:F19) | G20: =SUM(G19:G19) | H20: =SUM(H19:H19) | I20: =SUM(I19:I19) | J20: =SUM(J19:J19) | ... N20: =SUM(N19:N19) | P20: =SUM(P19:P19)
B22: Net Operating Income (EBITDA) | C22: =C16-C20 | D22: =D16-D20 | E22: =E16-E20 | F22: =F16-F20 | G22: =G16-G20 | H22: =H16-H20 | I22: =I16-I20 | J22: =J16-J20 | ... N22: =N16-N20 | P22: =P16-P20
B23: EBITDA % | C23: =C22/C14 | D23: =D22/D14 | E23: =E22/E14 | F23: =F22/F14 | G23: =G22/G14 | H23: =H22/H14 | I23: =I22/I14 | J23: =J22/J14 | ... N23: =N22/N14 | P23: =P22/P14
B25: Other Income / (Expense) | C25: =SUMIF('Monthly Detail'!$4:$4, '2023 Overview'!C$11, 'Monthly Detail'!104:104) | D25: =SUMIF('Monthly Detail'!$4:$4, '2023 Overview'!D$11, 'Monthly Detail'!104:104) | E25: =SUMIF('Monthly Detail'!$4:$4, '2023 Overview'!E$11, 'Monthly Detail'!104:104) | F25: =SUMIF('Monthly Detail'!$4:$4, '2023 Overview'!F$11, 'Monthly Detail'!104:104) | G25: =SUMIF('Monthly Detail'!$4:$4, '2023 Overview'!G$11, 'Monthly Detail'!104:104) | H25: =SUMIF('Monthly Detail'!$4:$4, '2023 Overview'!H$11, 'Monthly Detail'!104:104) | I25: =SUMIF('Monthly Detail'!$4:$4, '2023 Overview'!I$11, 'Monthly Detail'!104:104) | J25: =SUMIF('Monthly Detail'!$4:$4, '2023 Overview'!J$11, 'Monthly Detail'!104:104) | ... N25: =SUMIF('Monthly Detail'!$4:$4, '2023 Overview'!N$11, 'Monthly Detail'!104:104) | P25: =SUM(C25:O25)
B26: Net Income | C26: =C22+SUM(C25:C25) | D26: =D22+SUM(D25:D25) | E26: =E22+SUM(E25:E25) | F26: =F22+SUM(F25:F25) | G26: =G22+SUM(G25:G25) | H26: =H22+SUM(H25:H25) | I26: =I22+SUM(I25:I25) | J26: =J22+SUM(J25:J25) | ... N26: =N22+SUM(N25:N25) | P26: =P22+SUM(P25:P25)
B27: NI % | C27: =C26/C14 | D27: =D26/D14 | E27: =E26/E14 | F27: =F26/F14 | G27: =G26/G14 | H27: =H26/H14 | I27: =I26/I14 | J27: =J26/J14 | ... N27: =N26/N14 | P27: =P26/P14
B29: Operating Cash | C29: =SUMIF('Monthly Detail'!$4:$4, '2023 Overview'!C$11, 'Monthly Detail'!174:174) | D29: =SUMIF('Monthly Detail'!$4:$4, '2023 Overview'!D$11, 'Monthly Detail'!174:174) | E29: =SUMIF('Monthly Detail'!$4:$4, '2023 Overview'!E$11, 'Monthly Detail'!174:174) | F29: =SUMIF('Monthly Detail'!$4:$4, '2023 Overview'!F$11, 'Monthly Detail'!174:174) | G29: =SUMIF('Monthly Detail'!$4:$4, '2023 Overview'!G$11, 'Monthly Detail'!174:174) | H29: =SUMIF('Monthly Detail'!$4:$4, '2023 Overview'!H$11, 'Monthly Detail'!174:174) | I29: =SUMIF('Monthly Detail'!$4:$4, '2023 Overview'!I$11, 'Monthly Detail'!174:174) | J29: =SUMIF('Monthly Detail'!$4:$4, '2023 Overview'!J$11, 'Monthly Detail'!174:174) | ... N29: =SUMIF('Monthly Detail'!$4:$4, '2023 Overview'!N$11, 'Monthly Detail'!174:174)
B30: Cash Inflow (Outflow) | C30: =SUMIF('Monthly Detail'!$4:$4, '2023 Overview'!C$11, 'Monthly Detail'!171:171) | D30: =SUMIF('Monthly Detail'!$4:$4, '2023 Overview'!D$11, 'Monthly Detail'!171:171) | E30: =SUMIF('Monthly Detail'!$4:$4, '2023 Overview'!E$11, 'Monthly Detail'!171:171) | F30: =SUMIF('Monthly Detail'!$4:$4, '2023 Overview'!F$11, 'Monthly Detail'!171:171) | G30: =SUMIF('Monthly Detail'!$4:$4, '2023 Overview'!G$11, 'Monthly Detail'!171:171) | H30: =SUMIF('Monthly Detail'!$4:$4, '2023 Overview'!H$11, 'Monthly Detail'!171:171) | I30: =SUMIF('Monthly Detail'!$4:$4, '2023 Overview'!I$11, 'Monthly Detail'!171:171) | J30: =SUMIF('Monthly Detail'!$4:$4, '2023 Overview'!J$11, 'Monthly Detail'!171:171) | ... N30: =SUMIF('Monthly Detail'!$4:$4, '2023 Overview'!N$11, 'Monthly Detail'!171:171)

Sheet 2026 AOP
B8: 2026 Annual Operating Plan
C10: =TEXT('Monthly Detail'!D4,"mmmm") | D10: =TEXT('Monthly Detail'!E4,"mmmm") | E10: =TEXT('Monthly Detail'!F4,"mmmm") | F10: =TEXT('Monthly Detail'!G4,"mmmm") | G10: =TEXT('Monthly Detail'!H4,"mmmm") | H10: =TEXT('Monthly Detail'!I4,"mmmm") | I10: =TEXT('Monthly Detail'!J4,"mmmm") | J10: =TEXT('Monthly Detail'!K4,"mmmm") | ... N10: =TEXT('Monthly Detail'!O4,"mmmm") | P10: Total
C11: 46053 | D11: 46081 | E11: 46112 | F11: 46142 | G11: 46173 | H11: 46203 | I11: 46234 | J11: 46265 | K11: 46295 | L11: 46326 | M11: 46356 | N11: 46387 | O11: 45322
B12: Service Income | C12: =SUMIF('Monthly Detail'!$4:$4, '2026 AOP'!C$11, 'Monthly Detail'!12:12) | D12: =SUMIF('Monthly Detail'!$4:$4, '2026 AOP'!D$11, 'Monthly Detail'!12:12) | E12: =SUMIF('Monthly Detail'!$4:$4, '2026 AOP'!E$11, 'Monthly Detail'!12:12) | F12: =SUMIF('Monthly Detail'!$4:$4, '2026 AOP'!F$11, 'Monthly Detail'!12:12) | G12: =SUMIF('Monthly Detail'!$4:$4, '2026 AOP'!G$11, 'Monthly Detail'!12:12) | H12: =SUMIF('Monthly Detail'!$4:$4, '2026 AOP'!H$11, 'Monthly Detail'!12:12) | I12: =SUMIF('Monthly Detail'!$4:$4, '2026 AOP'!I$11, 'Monthly Detail'!12:12) | J12: =SUMIF('Monthly Detail'!$4:$4, '2026 AOP'!J$11, 'Monthly Detail'!12:12) | ... N12: =SUMIF('Monthly Detail'!$4:$4, '2026 AOP'!N$11, 'Monthly Detail'!12:12) | P12: =SUM(C12:O12)
B13: Tips | C13: =SUMIF('Monthly Detail'!$4:$4, '2026 AOP'!C$11, 'Monthly Detail'!13:13) | D13: =SUMIF('Monthly Detail'!$4:$4, '2026 AOP'!D$11, 'Monthly Detail'!13:13) | E13: =SUMIF('Monthly Detail'!$4:$4, '2026 AOP'!E$11, 'Monthly Detail'!13:13) | F13: =SUMIF('Monthly Detail'!$4:$4, '2026 AOP'!F$11, 'Monthly Detail'!13:13) | G13: =SUMIF('Monthly Detail'!$4:$4, '2026 AOP'!G$11, 'Monthly Detail'!13:13) | H13: =SUMIF('Monthly Detail'!$4:$4, '2026 AOP'!H$11, 'Monthly Detail'!13:13) | I13: =SUMIF('Monthly Detail'!$4:$4, '2026 AOP'!I$11, 'Monthly Detail'!13:13) | J13: =SUMIF('Monthly Detail'!$4:$4, '2026 AOP'!J$11, 'Monthly Detail'!13:13) | ... N13: =SUMIF('Monthly Detail'!$4:$4, '2026 AOP'!N$11, 'Monthly Detail'!13:13) | P13: =+SUM(C13:N13)
B14: Total Income | C14: =SUM(C12:C13) | D14: =SUM(D12:D13) | E14: =SUM(E12:E13) | F14: =SUM(F12:F13) | G14: =SUM(G12:G13) | H14: =SUM(H12:H13) | I14: =SUM(I12:I13) | J14: =SUM(J12:J13) | ... N14: =SUM(N12:N13) | P14: =SUM(P12:P13)
B15: # of Students | C15: =SUMIF('Monthly Detail'!$4:$4, '2026 AOP'!C$11, 'Monthly Detail'!17:17) | D15: =SUMIF('Monthly Detail'!$4:$4, '2026 AOP'!D$11, 'Monthly Detail'!17:17) | E15: =SUMIF('Monthly Detail'!$4:$4, '2026 AOP'!E$11, 'Monthly Detail'!17:17) | F15: =SUMIF('Monthly Detail'!$4:$4, '2026 AOP'!F$11, 'Monthly Detail'!17:17) | G15: =SUMIF('Monthly Detail'!$4:$4, '2026 AOP'!G$11, 'Monthly Detail'!17:17) | H15: =SUMIF('Monthly Detail'!$4:$4, '2026 AOP'!H$11, 'Monthly Detail'!17:17) | I15: =SUMIF('Monthly Detail'!$4:$4, '2026 AOP'!I$11, 'Monthly Detail'!17:17) | J15: =SUMIF('Monthly Detail'!$4:$4, '2026 AOP'!J$11, 'Monthly Detail'!17:17) | ... N15: =SUMIF('Monthly Detail'!$4:$4, '2026 AOP'!N$11, 'Monthly Detail'!17:17)
B16: # of Sessions | C16: =SUMIF('Monthly Detail'!$4:$4, '2026 AOP'!C$11, 'Monthly Detail'!22:22) | D16: =SUMIF('Monthly Detail'!$4:$4, '2026 AOP'!D$11, 'Monthly Detail'!22:22) | E16: =SUMIF('Monthly Detail'!$4:$4, '2026 AOP'!E$11, 'Monthly Detail'!22:22) | F16: =SUMIF('Monthly Detail'!$4:$4, '2026 AOP'!F$11, 'Monthly Detail'!22:22) | G16: =SUMIF('Monthly Detail'!$4:$4, '2026 AOP'!G$11, 'Monthly Detail'!22:22) | H16: =SUMIF('Monthly Detail'!$4:$4, '2026 AOP'!H$11, 'Monthly Detail'!22:22) | I16: =SUMIF('Monthly Detail'!$4:$4, '2026 AOP'!I$11, 'Monthly Detail'!22:22) | J16: =SUMIF('Monthly Detail'!$4:$4, '2026 AOP'!J$11, 'Monthly Detail'!22:22) | ... N16: =SUMIF('Monthly Detail'!$4:$4, '2026 AOP'!N$11, 'Monthly Detail'!22:22)
B18: Subcontractor Expenses | C18: =SUMIF('Monthly Detail'!$4:$4, '2026 AOP'!C$11, 'Monthly Detail'!65:65) | D18: =SUMIF('Monthly Detail'!$4:$4, '2026 AOP'!D$11, 'Monthly Detail'!65:65) | E18: =SUMIF('Monthly Detail'!$4:$4, '2026 AOP'!E$11, 'Monthly Detail'!65:65) | F18: =SUMIF('Monthly Detail'!$4:$4, '2026 AOP'!F$11, 'Monthly Detail'!65:65) | G18: =SUMIF('Monthly Detail'!$4:$4, '2026 AOP'!G$11, 'Monthly Detail'!65:65) | H18: =SUMIF('Monthly Detail'!$4:$4, '2026 AOP'!H$11, 'Monthly Detail'!65:65) | I18: =SUMIF('Monthly Detail'!$4:$4, '2026 AOP'!I$11, 'Monthly Detail'!65:65) | J18: =SUMIF('Monthly Detail'!$4:$4, '2026 AOP'!J$11, 'Monthly Detail'!65:65) | ... N18: =SUMIF('Monthly Detail'!$4:$4, '2026 AOP'!N$11, 'Monthly Detail'!65:65) | P18: =SUM(C18:O18)
B19: Gross Margin | C19: =C14-C18 | D19: =D14-D18 | E19: =E14-E18 | F19: =F14-F18 | G19: =G14-G18 | H19: =H14-H18 | I19: =I14-I18 | J19: =J14-J18 | ... N19: =N14-N18 | P19: =P14-P18
B20: GM % | C20: =C19/C14 | D20: =D19/D14 | E20: =E19/E14 | F20: =F19/F14 | G20: =G19/G14 | H20: =H19/H14 | I20: =I19/I14 | J20: =J19/J14 | ... N20: =N19/N14 | P20: =P19/P14
B22: Sales & Marketing Expenses | C22: =SUMIF('Monthly Detail'!$4:$4, '2026 AOP'!C$11, 'Monthly Detail'!$72:$72) | D22: =SUMIF('Monthly Detail'!$4:$4, '2026 AOP'!D$11, 'Monthly Detail'!$72:$72) | E22: =SUMIF('Monthly Detail'!$4:$4, '2026 AOP'!E$11, 'Monthly Detail'!$72:$72) | F22: =SUMIF('Monthly Detail'!$4:$4, '2026 AOP'!F$11, 'Monthly Detail'!$72:$72) | G22: =SUMIF('Monthly Detail'!$4:$4, '2026 AOP'!G$11, 'Monthly Detail'!$72:$72) | H22: =SUMIF('Monthly Detail'!$4:$4, '2026 AOP'!H$11, 'Monthly Detail'!$72:$72) | I22: =SUMIF('Monthly Detail'!$4:$4, '2026 AOP'!I$11, 'Monthly Detail'!$72:$72) | J22: =SUMIF('Monthly Detail'!$4:$4, '2026 AOP'!J$11, 'Monthly Detail'!$72:$72) | ... N22: =SUMIF('Monthly Detail'!$4:$4, '2026 AOP'!N$11, 'Monthly Detail'!$72:$72) | P22: =SUM(C22:O22)
B23: General & Admintrative Expenses | C23: =SUMIF('Monthly Detail'!$4:$4, '2026 AOP'!C$11, 'Monthly Detail'!$95:$95) | D23: =SUMIF('Monthly Detail'!$4:$4, '2026 AOP'!D$11, 'Monthly Detail'!$95:$95) | E23: =SUMIF('Monthly Detail'!$4:$4, '2026 AOP'!E$11, 'Monthly Detail'!$95:$95) | F23: =SUMIF('Monthly Detail'!$4:$4, '2026 AOP'!F$11, 'Monthly Detail'!$95:$95) | G23: =SUMIF('Monthly Detail'!$4:$4, '2026 AOP'!G$11, 'Monthly Detail'!$95:$95) | H23: =SUMIF('Monthly Detail'!$4:$4, '2026 AOP'!H$11, 'Monthly Detail'!$95:$95) | I23: =SUMIF('Monthly Detail'!$4:$4, '2026 AOP'!I$11, 'Monthly Detail'!$95:$95) | J23: =SUMIF('Monthly Detail'!$4:$4, '2026 AOP'!J$11, 'Monthly Detail'!$95:$95) | ... N23: =SUMIF('Monthly Detail'!$4:$4, '2026 AOP'!N$11, 'Monthly Detail'!$95:$95) | P23: =SUM(C23:O23)
B24: Operating Expenses | C24: =SUM(C23:C23) | D24: =SUM(D22:D23) | E24: =SUM(E22:E23) | F24: =SUM(F22:F23) | G24: =SUM(G22:G23) | H24: =SUM(H22:H23) | I24: =SUM(I22:I23) | J24: =SUM(J22:J23) | K24: =SUM(K22:K23) | ... N24: =SUM(N22:N23) | P24: =SUM(P22:P23)
B26: Net Operating Income (EBITDA) | C26: =C19-C24 | D26: =D19-D24 | E26: =E19-E24 | F26: =F19-F24 | G26: =G19-G24 | H26: =H19-H24 | I26: =I19-I24 | J26: =J19-J24 | ... N26: =N19-N24 | P26: =P19-P24
B27: EBITDA % | C27: =C26/C14 | D27: =D26/D14 | E27: =E26/E14 | F27: =F26/F14 | G27: =G26/G14 | H27: =H26/H14 | I27: =I26/I14 | J27: =J26/J14 | ... N27: =N26/N14 | P27: =P26/P14
B29: Other Income / (Expense) | C29: =SUMIF('Monthly Detail'!$4:$4, '2026 AOP'!C$11, 'Monthly Detail'!109:109) | D29: =SUMIF('Monthly Detail'!$4:$4, '2026 AOP'!D$11, 'Monthly Detail'!109:109) | E29: =SUMIF('Monthly Detail'!$4:$4, '2026 AOP'!E$11, 'Monthly Detail'!109:109) | F29: =SUMIF('Monthly Detail'!$4:$4, '2026 AOP'!F$11, 'Monthly Detail'!109:109) | G29: =SUMIF('Monthly Detail'!$4:$4, '2026 AOP'!G$11, 'Monthly Detail'!109:109) | H29: =SUMIF('Monthly Detail'!$4:$4, '2026 AOP'!H$11, 'Monthly Detail'!109:109) | I29: =SUMIF('Monthly Detail'!$4:$4, '2026 AOP'!I$11, 'Monthly Detail'!109:109) | J29: =SUMIF('Monthly Detail'!$4:$4, '2026 AOP'!J$11, 'Monthly Detail'!109:109) | ... N29: =SUMIF('Monthly Detail'!$4:$4, '2026 AOP'!N$11, 'Monthly Detail'!109:109) | P29: =SUM(C29:O29)
B30: Net Income | C30: =C26+SUM(C29:C29) | D30: =D26+SUM(D29:D29) | E30: =E26+SUM(E29:E29) | F30: =F26+SUM(F29:F29) | G30: =G26+SUM(G29:G29) | H30: =H26+SUM(H29:H29) | I30: =I26+SUM(I29:I29) | J30: =J26+SUM(J29:J29) | ... N30: =N26+SUM(N29:N29) | P30: =P26+SUM(P29:P29)
B31: NI % | C31: =C30/C14 | D31: =D30/D14 | E31: =E30/E14 | F31: =F30/F14 | G31: =G30/G14 | H31: =H30/H14 | I31: =I30/I14 | J31: =J30/J14 | ... N31: =N30/N14 | P31: =P30/P14
B32: Cash Contributions | C32: ='Monthly Detail'!AN149-'Monthly Detail'!AM149 | D32: ='Monthly Detail'!AO149-'Monthly Detail'!AN149 | E32: ='Monthly Detail'!AP149-'Monthly Detail'!AO149 | F32: ='Monthly Detail'!AQ149-'Monthly Detail'!AP149 | G32: ='Monthly Detail'!AR149-'Monthly Detail'!AQ149 | H32: ='Monthly Detail'!AS149-'Monthly Detail'!AR149 | I32: ='Monthly Detail'!AT149-'Monthly Detail'!AS149 | J32: ='Monthly Detail'!AU149-'Monthly Detail'!AT149 | ... N32: ='Monthly Detail'!AY149-'Monthly Detail'!AX149 | P32: =+SUM(C32:N32)
B33: Owner Cash Distributions/Taxes | C33: =+SUM('Monthly Detail'!AN150,'Monthly Detail'!AN152:AN153)-SUM('Monthly Detail'!AM150,'Monthly Detail'!AM152:AM153) | D33: =+SUM('Monthly Detail'!AO150,'Monthly Detail'!AO152:AO153)-SUM('Monthly Detail'!AN150,'Monthly Detail'!AN152:AN153) | E33: =+SUM('Monthly Detail'!AP150,'Monthly Detail'!AP152:AP153)-SUM('Monthly Detail'!AO150,'Monthly Detail'!AO152:AO153) | F33: =+SUM('Monthly Detail'!AQ150,'Monthly Detail'!AQ152:AQ153)-SUM('Monthly Detail'!AP150,'Monthly Detail'!AP152:AP153) | G33: =+SUM('Monthly Detail'!AR150,'Monthly Detail'!AR152:AR153)-SUM('Monthly Detail'!AQ150,'Monthly Detail'!AQ152:AQ153) | H33: =+SUM('Monthly Detail'!AS150,'Monthly Detail'!AS152:AS153)-SUM('Monthly Detail'!AR150,'Monthly Detail'!AR152:AR153) | I33: =+SUM('Monthly Detail'!AT150,'Monthly Detail'!AT152:AT153)-SUM('Monthly Detail'!AS150,'Monthly Detail'!AS152:AS153) | J33: =+SUM('Monthly Detail'!AU150,'Monthly Detail'!AU152:AU153)-SUM('Monthly Detail'!AT150,'Monthly Detail'!AT152:AT153) | ... N33: =+SUM('Monthly Detail'!AY150,'Monthly Detail'!AY152:AY153)-SUM('Monthly Detail'!AX150,'Monthly Detail'!AX152:AX153) | P33: =+SUM(C33:N33)
B34: Accrued Tax Burden | C34: =+C30*0.3 | D34: =+C34+(D26*0.3)-SUMIF('Monthly Detail'!$4:$4, '2026 AOP'!D$11, 'Monthly Detail'!77:77) | E34: =+D34+(E26*0.3)-SUMIF('Monthly Detail'!$4:$4, '2026 AOP'!E$11, 'Monthly Detail'!77:77) | F34: =+E34+(F26*0.3)-SUMIF('Monthly Detail'!$4:$4, '2026 AOP'!F$11, 'Monthly Detail'!77:77) | G34: =+F34+(G26*0.3)-SUMIF('Monthly Detail'!$4:$4, '2026 AOP'!G$11, 'Monthly Detail'!77:77) | H34: =+G34+(H26*0.3)-SUMIF('Monthly Detail'!$4:$4, '2026 AOP'!H$11, 'Monthly Detail'!77:77) | I34: =+H34+(I26*0.3)-SUMIF('Monthly Detail'!$4:$4, '2026 AOP'!I$11, 'Monthly Detail'!77:77) | J34: =+I34+(J26*0.3)-SUMIF('Monthly Detail'!$4:$4, '2026 AOP'!J$11, 'Monthly Detail'!77:77) | K34: =+J34+(K26*0.3)-SUMIF('Monthly Detail'!$4:$4, '2026 AOP'!K$11, 'Monthly Detail'!77:77) | ... N34: =+M34+(N26*0.3)-SUMIF('Monthly Detail'!$4:$4, '2026 AOP'!N$11, 'Monthly Detail'!77:77) | P34: =+N34
B36: Operating Cash | C36: =SUMIF('Monthly Detail'!$4:$4, '2026 AOP'!C$11, 'Monthly Detail'!174:174) | D36: =SUMIF('Monthly Detail'!$4:$4, '2026 AOP'!D$11, 'Monthly Detail'!174:174) | E36: =SUMIF('Monthly Detail'!$4:$4, '2026 AOP'!E$11, 'Monthly Detail'!174:174) | F36: =SUMIF('Monthly Detail'!$4:$4, '2026 AOP'!F$11, 'Monthly Detail'!174:174) | G36: =SUMIF('Monthly Detail'!$4:$4, '2026 AOP'!G$11, 'Monthly Detail'!174:174) | H36: =SUMIF('Monthly Detail'!$4:$4, '2026 AOP'!H$11, 'Monthly Detail'!174:174) | I36: =SUMIF('Monthly Detail'!$4:$4, '2026 AOP'!I$11, 'Monthly Detail'!174:174) | J36: =SUMIF('Monthly Detail'!$4:$4, '2026 AOP'!J$11, 'Monthly Detail'!174:174) | ... N36: =SUMIF('Monthly Detail'!$4:$4, '2026 AOP'!N$11, 'Monthly Detail'!174:174)
B37: Cash Inflow (Outflow) | C37: =SUMIF('Monthly Detail'!$4:$4, '2026 AOP'!C$11, 'Monthly Detail'!171:171) | D37: =SUMIF('Monthly Detail'!$4:$4, '2026 AOP'!D$11, 'Monthly Detail'!171:171) | E37: =SUMIF('Monthly Detail'!$4:$4, '2026 AOP'!E$11, 'Monthly Detail'!171:171) | F37: =SUMIF('Monthly Detail'!$4:$4, '2026 AOP'!F$11, 'Monthly Detail'!171:171) | G37: =SUMIF('Monthly Detail'!$4:$4, '2026 AOP'!G$11, 'Monthly Detail'!171:171) | H37: =SUMIF('Monthly Detail'!$4:$4, '2026 AOP'!H$11, 'Monthly Detail'!171:171) | I37: =SUMIF('Monthly Detail'!$4:$4, '2026 AOP'!I$11, 'Monthly Detail'!171:171) | J37: =SUMIF('Monthly Detail'!$4:$4, '2026 AOP'!J$11, 'Monthly Detail'!171:171) | ... N37: =SUMIF('Monthly Detail'!$4:$4, '2026 AOP'!N$11, 'Monthly Detail'!171:171)

Sheet 2025 Overview (Rolling)
B8: 2025 Overview (Rolling Forecast)
C10: =TEXT('Monthly Detail'!D4,"mmmm") | D10: =TEXT('Monthly Detail'!E4,"mmmm") | E10: =TEXT('Monthly Detail'!F4,"mmmm") | F10: =TEXT('Monthly Detail'!G4,"mmmm") | G10: =TEXT('Monthly Detail'!H4,"mmmm") | H10: =TEXT('Monthly Detail'!I4,"mmmm") | I10: =TEXT('Monthly Detail'!J4,"mmmm") | J10: =TEXT('Monthly Detail'!K4,"mmmm") | ... N10: =TEXT('Monthly Detail'!O4,"mmmm") | P10: Total
C11: 45688 | D11: 45716 | E11: 45747 | F11: 45777 | G11: 45808 | H11: 45838 | I11: 45869 | J11: 45900 | K11: 45930 | L11: 45961 | M11: 45991 | N11: 46022 | O11: 45322
B12: Service Income | C12: =SUMIF('Monthly Detail'!$4:$4, '2025 Overview (Rolling)'!C$11, 'Monthly Detail'!12:12) | D12: =SUMIF('Monthly Detail'!$4:$4, '2025 Overview (Rolling)'!D$11, 'Monthly Detail'!12:12) | E12: =SUMIF('Monthly Detail'!$4:$4, '2025 Overview (Rolling)'!E$11, 'Monthly Detail'!12:12) | F12: =SUMIF('Monthly Detail'!$4:$4, '2025 Overview (Rolling)'!F$11, 'Monthly Detail'!12:12) | G12: =SUMIF('Monthly Detail'!$4:$4, '2025 Overview (Rolling)'!G$11, 'Monthly Detail'!12:12) | H12: =SUMIF('Monthly Detail'!$4:$4, '2025 Overview (Rolling)'!H$11, 'Monthly Detail'!12:12) | I12: =SUMIF('Monthly Detail'!$4:$4, '2025 Overview (Rolling)'!I$11, 'Monthly Detail'!12:12) | J12: =SUMIF('Monthly Detail'!$4:$4, '2025 Overview (Rolling)'!J$11, 'Monthly Detail'!12:12) | ... N12: =SUMIF('Monthly Detail'!$4:$4, '2025 Overview (Rolling)'!N$11, 'Monthly Detail'!12:12) | P12: =SUM(C12:O12)
B13: Tips | C13: =SUMIF('Monthly Detail'!$4:$4, '2025 Overview (Rolling)'!C$11, 'Monthly Detail'!13:13) | D13: =SUMIF('Monthly Detail'!$4:$4, '2025 Overview (Rolling)'!D$11, 'Monthly Detail'!13:13) | E13: =SUMIF('Monthly Detail'!$4:$4, '2025 Overview (Rolling)'!E$11, 'Monthly Detail'!13:13) | F13: =SUMIF('Monthly Detail'!$4:$4, '2025 Overview (Rolling)'!F$11, 'Monthly Detail'!13:13) | G13: =SUMIF('Monthly Detail'!$4:$4, '2025 Overview (Rolling)'!G$11, 'Monthly Detail'!13:13) | H13: =SUMIF('Monthly Detail'!$4:$4, '2025 Overview (Rolling)'!H$11, 'Monthly Detail'!13:13) | I13: =SUMIF('Monthly Detail'!$4:$4, '2025 Overview (Rolling)'!I$11, 'Monthly Detail'!13:13) | J13: =SUMIF('Monthly Detail'!$4:$4, '2025 Overview (Rolling)'!J$11, 'Monthly Detail'!13:13) | ... N13: =SUMIF('Monthly Detail'!$4:$4, '2025 Overview (Rolling)'!N$11, 'Monthly Detail'!13:13) | P13: =+SUM(C13:N13)
B14: Total Income | C14: =SUM(C12:C13) | D14: =SUM(D12:D13) | E14: =SUM(E12:E13) | F14: =SUM(F12:F13) | G14: =SUM(G12:G13) | H14: =SUM(H12:H13) | I14: =SUM(I12:I13) | J14: =SUM(J12:J13) | ... N14: =SUM(N12:N13) | P14: =SUM(P12:P13)
B15: # of Students | C15: =SUMIF('Monthly Detail'!$4:$4, '2025 Overview (Rolling)'!C$11, 'Monthly Detail'!17:17) | D15: =SUMIF('Monthly Detail'!$4:$4, '2025 Overview (Rolling)'!D$11, 'Monthly Detail'!17:17) | E15: =SUMIF('Monthly Detail'!$4:$4, '2025 Overview (Rolling)'!E$11, 'Monthly Detail'!17:17) | F15: =SUMIF('Monthly Detail'!$4:$4, '2025 Overview (Rolling)'!F$11, 'Monthly Detail'!17:17) | G15: =SUMIF('Monthly Detail'!$4:$4, '2025 Overview (Rolling)'!G$11, 'Monthly Detail'!17:17) | H15: =SUMIF('Monthly Detail'!$4:$4, '2025 Overview (Rolling)'!H$11, 'Monthly Detail'!17:17) | I15: =SUMIF('Monthly Detail'!$4:$4, '2025 Overview (Rolling)'!I$11, 'Monthly Detail'!17:17) | J15: =SUMIF('Monthly Detail'!$4:$4, '2025 Overview (Rolling)'!J$11, 'Monthly Detail'!17:17) | ... N15: =SUMIF('Monthly Detail'!$4:$4, '2025 Overview (Rolling)'!N$11, 'Monthly Detail'!17:17)
B16: # of Sessions | C16: =SUMIF('Monthly Detail'!$4:$4, '2025 Overview (Rolling)'!C$11, 'Monthly Detail'!22:22) | D16: =SUMIF('Monthly Detail'!$4:$4, '2025 Overview (Rolling)'!D$11, 'Monthly Detail'!22:22) | E16: =SUMIF('Monthly Detail'!$4:$4, '2025 Overview (Rolling)'!E$11, 'Monthly Detail'!22:22) | F16: =SUMIF('Monthly Detail'!$4:$4, '2025 Overview (Rolling)'!F$11, 'Monthly Detail'!22:22) | G16: =SUMIF('Monthly Detail'!$4:$4, '2025 Overview (Rolling)'!G$11, 'Monthly Detail'!22:22) | H16: =SUMIF('Monthly Detail'!$4:$4, '2025 Overview (Rolling)'!H$11, 'Monthly Detail'!22:22) | I16: =SUMIF('Monthly Detail'!$4:$4, '2025 Overview (Rolling)'!I$11, 'Monthly Detail'!22:22) | J16: =SUMIF('Monthly Detail'!$4:$4, '2025 Overview (Rolling)'!J$11, 'Monthly Detail'!22:22) | ... N16: =SUMIF('Monthly Detail'!$4:$4, '2025 Overview (Rolling)'!N$11, 'Monthly Detail'!22:22)
B18: Subcontractor Expenses | C18: =SUMIF('Monthly Detail'!$4:$4, '2025 Overview (Rolling)'!C$11, 'Monthly Detail'!65:65) | D18: =SUMIF('Monthly Detail'!$4:$4, '2025 Overview (Rolling)'!D$11, 'Monthly Detail'!65:65) | E18: =SUMIF('Monthly Detail'!$4:$4, '2025 Overview (Rolling)'!E$11, 'Monthly Detail'!65:65) | F18: =SUMIF('Monthly Detail'!$4:$4, '2025 Overview (Rolling)'!F$11, 'Monthly Detail'!65:65) | G18: =SUMIF('Monthly Detail'!$4:$4, '2025 Overview (Rolling)'!G$11, 'Monthly Detail'!65:65) | H18: =SUMIF('Monthly Detail'!$4:$4, '2025 Overview (Rolling)'!H$11, 'Monthly Detail'!65:65) | I18: =SUMIF('Monthly Detail'!$4:$4, '2025 Overview (Rolling)'!I$11, 'Monthly Detail'!65:65) | J18: =SUMIF('Monthly Detail'!$4:$4, '2025 Overview (Rolling)'!J$11, 'Monthly Detail'!65:65) | ... N18: =SUMIF('Monthly Detail'!$4:$4, '2025 Overview (Rolling)'!N$11, 'Monthly Detail'!65:65) | P18: =SUM(C18:O18)
B19: Gross Margin | C19: =C14-C18 | D19: =D14-D18 | E19: =E14-E18 | F19: =F14-F18 | G19: =G14-G18 | H19: =H14-H18 | I19: =I14-I18 | J19: =J14-J18 | ... N19: =N14-N18 | P19: =P14-P18
B20: GM % | C20: =C19/C14 | D20: =D19/D14 | E20: =E19/E14 | F20: =F19/F14 | G20: =G19/G14 | H20: =H19/H14 | I20: =I19/I14 | J20: =J19/J14 | ... N20: =N19/N14 | P20: =P19/P14
B22: Sales & Marketing Expenses | C22: =SUMIF('Monthly Detail'!$4:$4, '2025 Overview (Rolling)'!C$11, 'Monthly Detail'!$72:$72) | D22: =SUMIF('Monthly Detail'!$4:$4, '2025 Overview (Rolling)'!D$11, 'Monthly Detail'!$72:$72) | E22: =SUMIF('Monthly Detail'!$4:$4, '2025 Overview (Rolling)'!E$11, 'Monthly Detail'!$72:$72) | F22: =SUMIF('Monthly Detail'!$4:$4, '2025 Overview (Rolling)'!F$11, 'Monthly Detail'!$72:$72) | G22: =SUMIF('Monthly Detail'!$4:$4, '2025 Overview (Rolling)'!G$11, 'Monthly Detail'!$72:$72) | H22: =SUMIF('Monthly Detail'!$4:$4, '2025 Overview (Rolling)'!H$11, 'Monthly Detail'!$72:$72) | I22: =SUMIF('Monthly Detail'!$4:$4, '2025 Overview (Rolling)'!I$11, 'Monthly Detail'!$72:$72) | J22: =SUMIF('Monthly Detail'!$4:$4, '2025 Overview (Rolling)'!J$11, 'Monthly Detail'!$72:$72) | ... N22: =SUMIF('Monthly Detail'!$4:$4, '2025 Overview (Rolling)'!N$11, 'Monthly Detail'!$72:$72) | P22: =SUM(C22:O22)
B23: General & Admintrative Expenses | C23: =SUMIF('Monthly Detail'!$4:$4, '2025 Overview (Rolling)'!C$11, 'Monthly Detail'!$95:$95) | D23: =SUMIF('Monthly Detail'!$4:$4, '2025 Overview (Rolling)'!D$11, 'Monthly Detail'!$95:$95) | E23: =SUMIF('Monthly Detail'!$4:$4, '2025 Overview (Rolling)'!E$11, 'Monthly Detail'!$95:$95) | F23: =SUMIF('Monthly Detail'!$4:$4, '2025 Overview (Rolling)'!F$11, 'Monthly Detail'!$95:$95) | G23: =SUMIF('Monthly Detail'!$4:$4, '2025 Overview (Rolling)'!G$11, 'Monthly Detail'!$95:$95) | H23: =SUMIF('Monthly Detail'!$4:$4, '2025 Overview (Rolling)'!H$11, 'Monthly Detail'!$95:$95) | I23: =SUMIF('Monthly Detail'!$4:$4, '2025 Overview (Rolling)'!I$11, 'Monthly Detail'!$95:$95) | J23: =SUMIF('Monthly Detail'!$4:$4, '2025 Overview (Rolling)'!J$11, 'Monthly Detail'!$95:$95) | ... N23: =SUMIF('Monthly Detail'!$4:$4, '2025 Overview (Rolling)'!N$11, 'Monthly Detail'!$95:$95) | P23: =SUM(C23:O23)
B24: Operating Expenses | C24: =SUM(C23:C23) | D24: =SUM(D22:D23) | E24: =SUM(E22:E23) | F24: =SUM(F22:F23) | G24: =SUM(G22:G23) | H24: =SUM(H22:H23) | I24: =SUM(I22:I23) | J24: =SUM(J22:J23) | K24: =SUM(K22:K23) | ... N24: =SUM(N22:N23) | P24: =SUM(P22:P23)
B26: Net Operating Income (EBITDA) | C26: =C19-C24 | D26: =D19-D24 | E26: =E19-E24 | F26: =F19-F24 | G26: =G19-G24 | H26: =H19-H24 | I26: =I19-I24 | J26: =J19-J24 | ... N26: =N19-N24 | P26: =P19-P24
B27: EBITDA % | C27: =C26/C14 | D27: =D26/D14 | E27: =E26/E14 | F27: =F26/F14 | G27: =G26/G14 | H27: =H26/H14 | I27: =I26/I14 | J27: =J26/J14 | ... N27: =N26/N14 | P27: =P26/P14
B29: Other Income / (Expense) | C29: =SUMIF('Monthly Detail'!$4:$4, '2025 Overview (Rolling)'!C$11, 'Monthly Detail'!109:109) | D29: =SUMIF('Monthly Detail'!$4:$4, '2025 Overview (Rolling)'!D$11, 'Monthly Detail'!109:109) | E29: =SUMIF('Monthly Detail'!$4:$4, '2025 Overview (Rolling)'!E$11, 'Monthly Detail'!109:109) | F29: =SUMIF('Monthly Detail'!$4:$4, '2025 Overview (Rolling)'!F$11, 'Monthly Detail'!109:109) | G29: =SUMIF('Monthly Detail'!$4:$4, '2025 Overview (Rolling)'!G$11, 'Monthly Detail'!109:109) | H29: =SUMIF('Monthly Detail'!$4:$4, '2025 Overview (Rolling)'!H$11, 'Monthly Detail'!109:109) | I29: =SUMIF('Monthly Detail'!$4:$4, '2025 Overview (Rolling)'!I$11, 'Monthly Detail'!109:109) | J29: =SUMIF('Monthly Detail'!$4:$4, '2025 Overview (Rolling)'!J$11, 'Monthly Detail'!109:109) | ... N29: =SUMIF('Monthly Detail'!$4:$4, '2025 Overview (Rolling)'!N$11, 'Monthly Detail'!109:109) | P29: =SUM(C29:O29)
B30: Net Income | C30: =C26+SUM(C29:C29) | D30: =D26+SUM(D29:D29) | E30: =E26+SUM(E29:E29) | F30: =F26+SUM(F29:F29) | G30: =G26+SUM(G29:G29) | H30: =H26+SUM(H29:H29) | I30: =I26+SUM(I29:I29) | J30: =J26+SUM(J29:J29) | ... N30: =N26+SUM(N29:N29) | P30: =P26+SUM(P29:P29)
B31: NI % | C31: =C30/C14 | D31: =D30/D14 | E31: =E30/E14 | F31: =F30/F14 | G31: =G30/G14 | H31: =H30/H14 | I31: =I30/I14 | J31: =J30/J14 | ... N31: =N30/N14 | P31: =P30/P14
B32: Cash Contributions | C32: ='Monthly Detail'!AN149-'Monthly Detail'!AM149 | D32: ='Monthly Detail'!AO149-'Monthly Detail'!AN149 | E32: ='Monthly Detail'!AP149-'Monthly Detail'!AO149 | F32: ='Monthly Detail'!AQ149-'Monthly Detail'!AP149 | G32: ='Monthly Detail'!AR149-'Monthly Detail'!AQ149 | H32: ='Monthly Detail'!AS149-'Monthly Detail'!AR149 | I32: ='Monthly Detail'!AT149-'Monthly Detail'!AS149 | J32: ='Monthly Detail'!AU149-'Monthly Detail'!AT149 | ... N32: ='Monthly Detail'!AY149-'Monthly Detail'!AX149 | P32: =+SUM(C32:N32)
B33: Owner Cash Distributions/Taxes | C33: =+SUM('Monthly Detail'!AN150,'Monthly Detail'!AN152:AN153)-SUM('Monthly Detail'!AM150,'Monthly Detail'!AM152:AM153) | D33: =+SUM('Monthly Detail'!AO150,'Monthly Detail'!AO152:AO153)-SUM('Monthly Detail'!AN150,'Monthly Detail'!AN152:AN153) | E33: =+SUM('Monthly Detail'!AP150,'Monthly Detail'!AP152:AP153)-SUM('Monthly Detail'!AO150,'Monthly Detail'!AO152:AO153) | F33: =+SUM('Monthly Detail'!AQ150,'Monthly Detail'!AQ152:AQ153)-SUM('Monthly Detail'!AP150,'Monthly Detail'!AP152:AP153) | G33: =+SUM('Monthly Detail'!AR150,'Monthly Detail'!AR152:AR153)-SUM('Monthly Detail'!AQ150,'Monthly Detail'!AQ152:AQ153) | H33: =+SUM('Monthly Detail'!AS150,'Monthly Detail'!AS152:AS153)-SUM('Monthly Detail'!AR150,'Monthly Detail'!AR152:AR153) | I33: =+SUM('Monthly Detail'!AT150,'Monthly Detail'!AT152:AT153)-SUM('Monthly Detail'!AS150,'Monthly Detail'!AS152:AS153) | J33: =+SUM('Monthly Detail'!AU150,'Monthly Detail'!AU152:AU153)-SUM('Monthly Detail'!AT150,'Monthly Detail'!AT152:AT153) | ... N33: =+SUM('Monthly Detail'!AY150,'Monthly Detail'!AY152:AY153)-SUM('Monthly Detail'!AX150,'Monthly Detail'!AX152:AX153) | P33: =+SUM(C33:N33)
B34: Accrued Tax Burden | C34: =+C30*0.3 | D34: =+C34+(D26*0.3)-SUMIF('Monthly Detail'!$4:$4, '2025 Overview (Rolling)'!D$11, 'Monthly Detail'!77:77) | E34: =+D34+(E26*0.3)-SUMIF('Monthly Detail'!$4:$4, '2025 Overview (Rolling)'!E$11, 'Monthly Detail'!77:77) | F34: =+E34+(F26*0.3)-SUMIF('Monthly Detail'!$4:$4, '2025 Overview (Rolling)'!F$11, 'Monthly Detail'!77:77) | G34: =+F34+(G26*0.3)-SUMIF('Monthly Detail'!$4:$4, '2025 Overview (Rolling)'!G$11, 'Monthly Detail'!77:77) | H34: =+G34+(H26*0.3)-SUMIF('Monthly Detail'!$4:$4, '2025 Overview (Rolling)'!H$11, 'Monthly Detail'!77:77) | I34: =+H34+(I26*0.3)-SUMIF('Monthly Detail'!$4:$4, '2025 Overview (Rolling)'!I$11, 'Monthly Detail'!77:77) | J34: =+I34+(J26*0.3)-SUMIF('Monthly Detail'!$4:$4, '2025 Overview (Rolling)'!J$11, 'Monthly Detail'!77:77) | K34: =+J34+(K26*0.3)-SUMIF('Monthly Detail'!$4:$4, '2025 Overview (Rolling)'!K$11, 'Monthly Detail'!77:77) | ... N34: =+M34+(N26*0.3)-SUMIF('Monthly Detail'!$4:$4, '2025 Overview (Rolling)'!N$11, 'Monthly Detail'!77:77) | P34: =+N34
B36: Operating Cash | C36: =SUMIF('Monthly Detail'!$4:$4, '2025 Overview (Rolling)'!C$11, 'Monthly Detail'!174:174) | D36: =SUMIF('Monthly Detail'!$4:$4, '2025 Overview (Rolling)'!D$11, 'Monthly Detail'!174:174) | E36: =SUMIF('Monthly Detail'!$4:$4, '2025 Overview (Rolling)'!E$11, 'Monthly Detail'!174:174) | F36: =SUMIF('Monthly Detail'!$4:$4, '2025 Overview (Rolling)'!F$11, 'Monthly Detail'!174:174) | G36: =SUMIF('Monthly Detail'!$4:$4, '2025 Overview (Rolling)'!G$11, 'Monthly Detail'!174:174) | H36: =SUMIF('Monthly Detail'!$4:$4, '2025 Overview (Rolling)'!H$11, 'Monthly Detail'!174:174) | I36: =SUMIF('Monthly Detail'!$4:$4, '2025 Overview (Rolling)'!I$11, 'Monthly Detail'!174:174) | J36: =SUMIF('Monthly Detail'!$4:$4, '2025 Overview (Rolling)'!J$11, 'Monthly Detail'!174:174) | ... N36: =SUMIF('Monthly Detail'!$4:$4, '2025 Overview (Rolling)'!N$11, 'Monthly Detail'!174:174)
B37: Cash Inflow (Outflow) | C37: =SUMIF('Monthly Detail'!$4:$4, '2025 Overview (Rolling)'!C$11, 'Monthly Detail'!171:171) | D37: =SUMIF('Monthly Detail'!$4:$4, '2025 Overview (Rolling)'!D$11, 'Monthly Detail'!171:171) | E37: =SUMIF('Monthly Detail'!$4:$4, '2025 Overview (Rolling)'!E$11, 'Monthly Detail'!171:171) | F37: =SUMIF('Monthly Detail'!$4:$4, '2025 Overview (Rolling)'!F$11, 'Monthly Detail'!171:171) | G37: =SUMIF('Monthly Detail'!$4:$4, '2025 Overview (Rolling)'!G$11, 'Monthly Detail'!171:171) | H37: =SUMIF('Monthly Detail'!$4:$4, '2025 Overview (Rolling)'!H$11, 'Monthly Detail'!171:171) | I37: =SUMIF('Monthly Detail'!$4:$4, '2025 Overview (Rolling)'!I$11, 'Monthly Detail'!171:171) | J37: =SUMIF('Monthly Detail'!$4:$4, '2025 Overview (Rolling)'!J$11, 'Monthly Detail'!171:171) | ... N37: =SUMIF('Monthly Detail'!$4:$4, '2025 Overview (Rolling)'!N$11, 'Monthly Detail'!171:171)

Sheet 2025 Overview (Budget)
B8: 2025 Overview (Annual Operating Plan)
C10: =TEXT('Monthly Detail'!D4,"mmmm") | D10: =TEXT('Monthly Detail'!E4,"mmmm") | E10: =TEXT('Monthly Detail'!F4,"mmmm") | F10: =TEXT('Monthly Detail'!G4,"mmmm") | G10: =TEXT('Monthly Detail'!H4,"mmmm") | H10: =TEXT('Monthly Detail'!I4,"mmmm") | I10: =TEXT('Monthly Detail'!J4,"mmmm") | J10: =TEXT('Monthly Detail'!K4,"mmmm") | ... N10: =TEXT('Monthly Detail'!O4,"mmmm") | P10: Total
C11: 45688 | D11: 45716 | E11: 45747 | F11: 45777 | G11: 45808 | H11: 45838 | I11: 45869 | J11: 45900 | K11: 45930 | L11: 45961 | M11: 45991 | N11: 46022 | O11: 45322
B12: Service Income | C12: =+'2025 Overview (Rolling)'!C12 | D12: =+'2025 Overview (Rolling)'!D12 | E12: =+'2025 Overview (Rolling)'!E12 | F12: =+'2025 Overview (Rolling)'!F12 | G12: =+'2025 Overview (Rolling)'!G12 | H12: =+'2025 Overview (Rolling)'!H12 | I12: =+'2025 Overview (Rolling)'!I12 | J12: =+'2025 Overview (Rolling)'!J12 | ... L12: =+'2025 Overview (Rolling)'!L12 | M12: =+'2025 AOP'!M12 | N12: =+'2025 AOP'!N12 | P12: =SUM(C12:O12)
B13: Tips | C13: =+'2025 Overview (Rolling)'!C13 | D13: =+'2025 Overview (Rolling)'!D13 | E13: =+'2025 Overview (Rolling)'!E13 | F13: =+'2025 Overview (Rolling)'!F13 | G13: =+'2025 Overview (Rolling)'!G13 | H13: =+'2025 Overview (Rolling)'!H13 | I13: =+'2025 Overview (Rolling)'!I13 | J13: =+'2025 Overview (Rolling)'!J13 | ... L13: =+'2025 Overview (Rolling)'!L13 | M13: =+'2025 AOP'!M13 | N13: =+'2025 AOP'!N13 | P13: =+SUM(C13:N13)
B14: Total Income | C14: =+'2025 Overview (Rolling)'!C14 | D14: =+'2025 Overview (Rolling)'!D14 | E14: =+'2025 Overview (Rolling)'!E14 | F14: =+'2025 Overview (Rolling)'!F14 | G14: =+'2025 Overview (Rolling)'!G14 | H14: =+'2025 Overview (Rolling)'!H14 | I14: =+'2025 Overview (Rolling)'!I14 | J14: =+'2025 Overview (Rolling)'!J14 | ... L14: =+'2025 Overview (Rolling)'!L14 | M14: =SUM(M12:M13) | N14: =SUM(N12:N13) | P14: =SUM(P12:P13)
B15: # of Students | C15: =+'2025 Overview (Rolling)'!C15 | D15: =+'2025 Overview (Rolling)'!D15 | E15: =+'2025 Overview (Rolling)'!E15 | F15: =+'2025 Overview (Rolling)'!F15 | G15: =+'2025 Overview (Rolling)'!G15 | H15: =+'2025 Overview (Rolling)'!H15 | I15: =+'2025 Overview (Rolling)'!I15 | J15: =+'2025 Overview (Rolling)'!J15 | ... L15: =+'2025 Overview (Rolling)'!L15 | M15: =+'2025 AOP'!M15 | N15: =+'2025 AOP'!N15
B17: Subcontractor Expenses | C17: =+'2025 Overview (Rolling)'!C18 | D17: =+'2025 Overview (Rolling)'!D18 | E17: =+'2025 Overview (Rolling)'!E18 | F17: =+'2025 Overview (Rolling)'!F18 | G17: =+'2025 Overview (Rolling)'!G18 | H17: =+'2025 Overview (Rolling)'!H18 | I17: =+'2025 Overview (Rolling)'!I18 | J17: =+'2025 Overview (Rolling)'!J18 | ... L17: =+'2025 Overview (Rolling)'!L18 | M17: =+'2025 AOP'!M18 | N17: =+'2025 AOP'!N18 | P17: =SUM(C17:O17)
B18: Gross Margin | C18: =+'2025 Overview (Rolling)'!C19 | D18: =+'2025 Overview (Rolling)'!D19 | E18: =+'2025 Overview (Rolling)'!E19 | F18: =+'2025 Overview (Rolling)'!F19 | G18: =+'2025 Overview (Rolling)'!G19 | H18: =+'2025 Overview (Rolling)'!H19 | I18: =+'2025 Overview (Rolling)'!I19 | J18: =+'2025 Overview (Rolling)'!J19 | ... L18: =+'2025 Overview (Rolling)'!L19 | M18: =M14-M17 | N18: =N14-N17 | P18: =P14-P17
B19: GM % | C19: =+'2025 Overview (Rolling)'!C20 | D19: =+'2025 Overview (Rolling)'!D20 | E19: =+'2025 Overview (Rolling)'!E20 | F19: =+'2025 Overview (Rolling)'!F20 | G19: =+'2025 Overview (Rolling)'!G20 | H19: =+'2025 Overview (Rolling)'!H20 | I19: =+'2025 Overview (Rolling)'!I20 | J19: =+'2025 Overview (Rolling)'!J20 | ... L19: =+'2025 Overview (Rolling)'!L20 | M19: =M18/M14 | N19: =N18/N14 | P19: =P18/P14
B21: Sales & Marketing Expenses | C21: =+'2025 Overview (Rolling)'!C22 | D21: =+'2025 Overview (Rolling)'!D22 | E21: =+'2025 Overview (Rolling)'!E22 | F21: =+'2025 Overview (Rolling)'!F22 | G21: =+'2025 Overview (Rolling)'!G22 | H21: =+'2025 Overview (Rolling)'!H22 | I21: =+'2025 Overview (Rolling)'!I22 | J21: =+'2025 Overview (Rolling)'!J22 | ... L21: =+'2025 Overview (Rolling)'!L22 | M21: =+'2025 AOP'!M22 | N21: =+'2025 AOP'!N22 | P21: =SUM(C21:O21)
B22: General & Admintrative Expenses | C22: =+'2025 Overview (Rolling)'!C23 | D22: =+'2025 Overview (Rolling)'!D23 | E22: =+'2025 Overview (Rolling)'!E23 | F22: =+'2025 Overview (Rolling)'!F23 | G22: =+'2025 Overview (Rolling)'!G23 | H22: =+'2025 Overview (Rolling)'!H23 | I22: =+'2025 Overview (Rolling)'!I23 | J22: =+'2025 Overview (Rolling)'!J23 | ... L22: =+'2025 Overview (Rolling)'!L23 | M22: =+'2025 AOP'!M23 | N22: =+'2025 AOP'!N23 | P22: =SUM(C22:O22)
B23: Operating Expenses | C23: =+'2025 Overview (Rolling)'!C24 | D23: =+'2025 Overview (Rolling)'!D24 | E23: =+'2025 Overview (Rolling)'!E24 | F23: =+'2025 Overview (Rolling)'!F24 | G23: =+'2025 Overview (Rolling)'!G24 | H23: =+'2025 Overview (Rolling)'!H24 | I23: =+'2025 Overview (Rolling)'!I24 | J23: =+'2025 Overview (Rolling)'!J24 | ... L23: =+'2025 Overview (Rolling)'!L24 | M23: =SUM(M21:M22) | N23: =SUM(N21:N22) | P23: =SUM(P21:P22)
B25: Net Operating Income (EBITDA) | C25: =+'2025 Overview (Rolling)'!C26 | D25: =+'2025 Overview (Rolling)'!D26 | E25: =+'2025 Overview (Rolling)'!E26 | F25: =+'2025 Overview (Rolling)'!F26 | G25: =+'2025 Overview (Rolling)'!G26 | H25: =+'2025 Overview (Rolling)'!H26 | I25: =+'2025 Overview (Rolling)'!I26 | J25: =+'2025 Overview (Rolling)'!J26 | ... L25: =+'2025 Overview (Rolling)'!L26 | M25: =M18-M23 | N25: =N18-N23 | P25: =P18-P23
B26: EBITDA % | C26: =+'2025 Overview (Rolling)'!C27 | D26: =+'2025 Overview (Rolling)'!D27 | E26: =+'2025 Overview (Rolling)'!E27 | F26: =+'2025 Overview (Rolling)'!F27 | G26: =+'2025 Overview (Rolling)'!G27 | H26: =+'2025 Overview (Rolling)'!H27 | I26: =+'2025 Overview (Rolling)'!I27 | J26: =+'2025 Overview (Rolling)'!J27 | ... L26: =+'2025 Overview (Rolling)'!L27 | M26: =M25/M14 | N26: =N25/N14 | P26: =P25/P14
B28: Other Income / (Expense) | C28: =+'2025 Overview (Rolling)'!C29 | D28: =+'2025 Overview (Rolling)'!D29 | E28: =+'2025 Overview (Rolling)'!E29 | F28: =+'2025 Overview (Rolling)'!F29 | G28: =+'2025 Overview (Rolling)'!G29 | H28: =+'2025 Overview (Rolling)'!H29 | I28: =+'2025 Overview (Rolling)'!I29 | J28: =+'2025 Overview (Rolling)'!J29 | ... L28: =+'2025 Overview (Rolling)'!L29 | M28: =+'2025 AOP'!M29 | N28: =+'2025 AOP'!N29 | P28: =SUM(C28:O28)
B29: Net Income | C29: =+'2025 Overview (Rolling)'!C30 | D29: =+'2025 Overview (Rolling)'!D30 | E29: =+'2025 Overview (Rolling)'!E30 | F29: =+'2025 Overview (Rolling)'!F30 | G29: =+'2025 Overview (Rolling)'!G30 | H29: =+'2025 Overview (Rolling)'!H30 | I29: =+'2025 Overview (Rolling)'!I30 | J29: =+'2025 Overview (Rolling)'!J30 | ... L29: =+'2025 Overview (Rolling)'!L30 | M29: =M25+SUM(M28:M28) | N29: =N25+SUM(N28:N28) | P29: =P25+SUM(P28:P28)
B30: NI % | C30: =+'2025 Overview (Rolling)'!C31 | D30: =+'2025 Overview (Rolling)'!D31 | E30: =+'2025 Overview (Rolling)'!E31 | F30: =+'2025 Overview (Rolling)'!F31 | G30: =+'2025 Overview (Rolling)'!G31 | H30: =+'2025 Overview (Rolling)'!H31 | I30: =+'2025 Overview (Rolling)'!I31 | J30: =+'2025 Overview (Rolling)'!J31 | ... L30: =+'2025 Overview (Rolling)'!L31 | M30: =M29/M14 | N30: =N29/N14 | P30: =P29/P14
B32: Operating Cash | C32: =+'2025 Overview (Rolling)'!C36 | D32: =+'2025 Overview (Rolling)'!D36 | E32: =+'2025 Overview (Rolling)'!E36 | F32: =+'2025 Overview (Rolling)'!F36 | G32: =+'2025 Overview (Rolling)'!G36 | H32: =+'2025 Overview (Rolling)'!H36 | I32: =+'2025 Overview (Rolling)'!I36 | J32: =+'2025 Overview (Rolling)'!J36 | ... L32: =+'2025 Overview (Rolling)'!L36 | M32: =+'2024 AOP'!M31 | N32: =+'2024 AOP'!N31
B33: Cash Inflow (Outflow) | C33: =+'2025 Overview (Rolling)'!C37 | D33: =+'2025 Overview (Rolling)'!D37 | E33: =+'2025 Overview (Rolling)'!E37 | F33: =+'2025 Overview (Rolling)'!F37 | G33: =+'2025 Overview (Rolling)'!G37 | H33: =+'2025 Overview (Rolling)'!H37 | I33: =+'2025 Overview (Rolling)'!I37 | J33: =+'2025 Overview (Rolling)'!J37 | ... L33: =+'2025 Overview (Rolling)'!L37 | M33: =+'2024 AOP'!M32 | N33: =+'2024 AOP'!N32

Sheet 2024 Overview (Rolling)
B8: 2024 Overview (Rolling Forecast)
C10: =TEXT('Monthly Detail'!D4,"mmmm") | D10: =TEXT('Monthly Detail'!E4,"mmmm") | E10: =TEXT('Monthly Detail'!F4,"mmmm") | F10: =TEXT('Monthly Detail'!G4,"mmmm") | G10: =TEXT('Monthly Detail'!H4,"mmmm") | H10: =TEXT('Monthly Detail'!I4,"mmmm") | I10: =TEXT('Monthly Detail'!J4,"mmmm") | J10: =TEXT('Monthly Detail'!K4,"mmmm") | ... N10: =TEXT('Monthly Detail'!O4,"mmmm") | P10: Total
C11: 45322 | D11: 45351 | E11: 45382 | F11: 45412 | G11: 45443 | H11: 45473 | I11: 45504 | J11: 45535 | K11: 45565 | L11: 45596 | M11: 45626 | N11: 45657 | O11: 45322
B12: Service Income | C12: =SUMIF('Monthly Detail'!$4:$4, '2024 Overview (Rolling)'!C$11, 'Monthly Detail'!12:12) | D12: =SUMIF('Monthly Detail'!$4:$4, '2024 Overview (Rolling)'!D$11, 'Monthly Detail'!12:12) | E12: =SUMIF('Monthly Detail'!$4:$4, '2024 Overview (Rolling)'!E$11, 'Monthly Detail'!12:12) | F12: =SUMIF('Monthly Detail'!$4:$4, '2024 Overview (Rolling)'!F$11, 'Monthly Detail'!12:12) | G12: =SUMIF('Monthly Detail'!$4:$4, '2024 Overview (Rolling)'!G$11, 'Monthly Detail'!12:12) | H12: =SUMIF('Monthly Detail'!$4:$4, '2024 Overview (Rolling)'!H$11, 'Monthly Detail'!12:12) | I12: =SUMIF('Monthly Detail'!$4:$4, '2024 Overview (Rolling)'!I$11, 'Monthly Detail'!12:12) | J12: =SUMIF('Monthly Detail'!$4:$4, '2024 Overview (Rolling)'!J$11, 'Monthly Detail'!12:12) | ... N12: =SUMIF('Monthly Detail'!$4:$4, '2024 Overview (Rolling)'!N$11, 'Monthly Detail'!12:12) | P12: =SUM(C12:O12)
B13: Tips | C13: =SUMIF('Monthly Detail'!$4:$4, '2024 Overview (Rolling)'!C$11, 'Monthly Detail'!13:13) | D13: =SUMIF('Monthly Detail'!$4:$4, '2024 Overview (Rolling)'!D$11, 'Monthly Detail'!13:13) | E13: =SUMIF('Monthly Detail'!$4:$4, '2024 Overview (Rolling)'!E$11, 'Monthly Detail'!13:13) | F13: =SUMIF('Monthly Detail'!$4:$4, '2024 Overview (Rolling)'!F$11, 'Monthly Detail'!13:13) | G13: =SUMIF('Monthly Detail'!$4:$4, '2024 Overview (Rolling)'!G$11, 'Monthly Detail'!13:13) | H13: =SUMIF('Monthly Detail'!$4:$4, '2024 Overview (Rolling)'!H$11, 'Monthly Detail'!13:13) | I13: =SUMIF('Monthly Detail'!$4:$4, '2024 Overview (Rolling)'!I$11, 'Monthly Detail'!13:13) | J13: =SUMIF('Monthly Detail'!$4:$4, '2024 Overview (Rolling)'!J$11, 'Monthly Detail'!13:13) | ... N13: =SUMIF('Monthly Detail'!$4:$4, '2024 Overview (Rolling)'!N$11, 'Monthly Detail'!13:13) | P13: =+SUM(C13:N13)
B14: Total Income | C14: =SUM(C12:C13) | D14: =SUM(D12:D13) | E14: =SUM(E12:E13) | F14: =SUM(F12:F13) | G14: =SUM(G12:G13) | H14: =SUM(H12:H13) | I14: =SUM(I12:I13) | J14: =SUM(J12:J13) | ... N14: =SUM(N12:N13) | P14: =SUM(P12:P13)
B15: # of Students | C15: =+'Monthly Detail'!AB17 | D15: =+'Monthly Detail'!AC17 | E15: =+'Monthly Detail'!AD17 | F15: =+'Monthly Detail'!AE17 | G15: =+'Monthly Detail'!AF17 | H15: =+'Monthly Detail'!AG17 | I15: =+'Monthly Detail'!AH17 | J15: =+'Monthly Detail'!AI17 | ... N15: =+'Monthly Detail'!AM17
B16: # of Sessions | C16: =+'Monthly Detail'!AB22 | D16: =+'Monthly Detail'!AC22 | E16: =+'Monthly Detail'!AD22 | F16: =+'Monthly Detail'!AE22 | G16: =+'Monthly Detail'!AF22 | H16: =+'Monthly Detail'!AG22 | I16: =+'Monthly Detail'!AH22 | J16: =+'Monthly Detail'!AI22 | ... N16: =+'Monthly Detail'!AM22
