Workbook

Sheet 1

Sheet Annual Summary
D11: 2022 | E11: =+D11+1 -> 2023 | F11: Variance | G11: =+E11+1 -> 2024 | H11: Variance | I11: =+G11+1 -> 2025 | J11: =+I11+1 -> 2026 | K11: =+J11+1 -> 2027 | L11: =+K11+1 -> 2028 | M11: =+L11+1 -> 2029 | N11: =+M11+1 -> 2030
C13: Service Income | D13: =SUMIF('Monthly Detail'!$1:$1,'Annual Summary'!D$11, 'Monthly Detail'!12:12) -> 9212.5 | E13: =SUMIF('Monthly Detail'!$1:$1,'Annual Summary'!E$11, 'Monthly Detail'!12:12) -> 43837.41 | F13: =+E13-D13 -> 34624.91 | G13: =SUMIF('Monthly Detail'!$1:$1,'Annual Summary'!G$11, 'Monthly Detail'!12:12) -> 89488.79 | H13: =+G13-E13 -> 45651.38 | I13: =SUMIF('Monthly Detail'!$1:$1,'Annual Summary'!I$11, 'Monthly Detail'!12:12) -> 172325.82 | J13: =SUMIF('Monthly Detail'!$1:$1,'Annual Summary'!J$11, 'Monthly Detail'!12:12) -> 245759.64 | K13: =SUMIF('Monthly Detail'!$1:$1,'Annual Summary'!K$11, 'Monthly Detail'!12:12) -> 329658.57 | L13: =SUMIF('Monthly Detail'!$1:$1,'Annual Summary'!L$11, 'Monthly Detail'!12:12) -> 460399.19 | M13: =SUMIF('Monthly Detail'!$1:$1,'Annual Summary'!M$11, 'Monthly Detail'!12:12) -> 652731 | N13: =SUMIF('Monthly Detail'!$1:$1,'Annual Summary'!N$11, 'Monthly Detail'!12:12) -> 921050.81
C14: Tips | D14: =SUMIF('Monthly Detail'!$1:$1,'Annual Summary'!D$11, 'Monthly Detail'!13:13) -> 125 | E14: =SUMIF('Monthly Detail'!$1:$1,'Annual Summary'!E$11, 'Monthly Detail'!13:13) -> 608.09 | F14: =+E14-D14 -> 483.09 | G14: =SUMIF('Monthly Detail'!$1:$1,'Annual Summary'!G$11, 'Monthly Detail'!13:13) -> 339.45 | H14: =+G14-E14 -> -268.64 | I14: =SUMIF('Monthly Detail'!$1:$1,'Annual Summary'!I$11, 'Monthly Detail'!13:13) -> 654.50436 | J14: =SUMIF('Monthly Detail'!$1:$1,'Annual Summary'!J$11, 'Monthly Detail'!13:13) -> 1041.9737 | K14: =SUMIF('Monthly Detail'!$1:$1,'Annual Summary'!K$11, 'Monthly Detail'!13:13) -> 1397.6891 | L14: =SUMIF('Monthly Detail'!$1:$1,'Annual Summary'!L$11, 'Monthly Detail'!13:13) -> 1952.0042 | M14: =SUMIF('Monthly Detail'!$1:$1,'Annual Summary'!M$11, 'Monthly Detail'!13:13) -> 2767.4543 | N14: =SUMIF('Monthly Detail'!$1:$1,'Annual Summary'!N$11, 'Monthly Detail'!13:13) -> 3905.0788
C15: Total Income | D15: =SUM(D13:D14) -> 9337.5 | E15: =SUM(E13:E14) -> 44445.5 | F15: =+E15-D15 -> 35108 | G15: =SUM(G13:G14) -> 89828.24 | H15: =+G15-E15 -> 45382.74 | I15: =SUM(I13:I14) -> 172980.33 | J15: =SUM(J13:J14) -> 246801.61 | K15: =SUM(K13:K14) -> 331056.26 | L15: =SUM(L13:L14) -> 462351.19 | M15: =SUM(M13:M14) -> 655498.46 | N15: =SUM(N13:N14) -> 924955.89
C16: EOY # of Students | D16: =+SUMIFS('Monthly Detail'!17:17,'Monthly Detail'!4:4,DATE(D11,12,31)) -> 7 | E16: =+SUMIFS('Monthly Detail'!17:17,'Monthly Detail'!4:4,DATE(E11,12,31)) -> 19 | F16: =+E16-D16 -> 12 | G16: =+SUMIFS('Monthly Detail'!17:17,'Monthly Detail'!4:4,DATE(G11,12,31)) -> 23 | H16: =+G16-E16 -> 4 | I16: =+SUMIFS('Monthly Detail'!17:17,'Monthly Detail'!4:4,DATE(I11,12,31)) -> 57.6 | J16: =+SUMIFS('Monthly Detail'!17:17,'Monthly Detail'!4:4,DATE(J11,12,31)) -> 63.88 | K16: =+SUMIFS('Monthly Detail'!17:17,'Monthly Detail'!4:4,DATE(K11,12,31)) -> 89.072 | L16: =+SUMIFS('Monthly Detail'!17:17,'Monthly Detail'!4:4,DATE(L11,12,31)) -> 124.3408 | M16: =+SUMIFS('Monthly Detail'!17:17,'Monthly Detail'!4:4,DATE(M11,12,31)) -> 177.51712 | N16: =+SUMIFS('Monthly Detail'!17:17,'Monthly Detail'!4:4,DATE(N11,12,31)) -> 248.76397
C17: YOY Compounded Growth % | E17: =(E15/D15)-1 -> 3.7598929 | F17: =+E17-D17 -> 3.7598929 | G17: =(G15/E15)-1 -> 1.0210874 | H17: =+G17-E17 -> -2.7388055 | I17: =(I15/G15)-1 -> 0.9256787 | J17: =(J15/I15)-1 -> 0.42676114 | K17: =(K15/J15)-1 -> 0.34138614 | L17: =(L15/K15)-1 -> 0.39659401 | M17: =(M15/L15)-1 -> 0.41775012 | N17: =(N15/M15)-1 -> 0.41107256
C19: Subcontractor Expenses | D19: =SUMIF('Monthly Detail'!$1:$1,'Annual Summary'!D$11, 'Monthly Detail'!$63:$63) -> 0 | E19: =SUMIF('Monthly Detail'!$1:$1,'Annual Summary'!E$11, 'Monthly Detail'!$63:$63) -> 0 | F19: =+E19-D19 -> 0 | G19: =SUMIF('Monthly Detail'!$1:$1,'Annual Summary'!G$11, 'Monthly Detail'!$63:$63) -> 4014 | H19: =+G19-E19 -> 4014 | I19: =SUMIF('Monthly Detail'!$1:$1,'Annual Summary'!I$11, 'Monthly Detail'!$63:$63) -> 14278.194 | J19: =SUMIF('Monthly Detail'!$1:$1,'Annual Summary'!J$11, 'Monthly Detail'!$63:$63) -> 35654.857 | K19: =SUMIF('Monthly Detail'!$1:$1,'Annual Summary'!K$11, 'Monthly Detail'!$63:$63) -> 57005.125 | L19: =SUMIF('Monthly Detail'!$1:$1,'Annual Summary'!L$11, 'Monthly Detail'!$63:$63) -> 91695.815 | M19: =SUMIF('Monthly Detail'!$1:$1,'Annual Summary'!M$11, 'Monthly Detail'!$63:$63) -> 141680.31 | N19: =SUMIF('Monthly Detail'!$1:$1,'Annual Summary'!N$11, 'Monthly Detail'!$63:$63) -> 214895.34
C20: Gross Margin | D20: =D15-D19 -> 9337.5 | E20: =E15-E19 -> 44445.5 | F20: =+E20-D20 -> 35108 | G20: =G15-G19 -> 85814.24 | H20: =+G20-E20 -> 41368.74 | I20: =I15-I19 -> 158702.13 | J20: =J15-J19 -> 211146.75 | K20: =K15-K19 -> 274051.14 | L20: =L15-L19 -> 370655.38 | M20: =M15-M19 -> 513818.15 | N20: =N15-N19 -> 710060.55
C21: GM % | D21: =+D20/D15 -> 1 | E21: =+E20/E15 -> 1 | F21: =+E21-D21 -> 0 | G21: =+G20/G15 -> 0.95531472 | H21: =+G21-E21 -> -0.044685279 | I21: =+I20/I15 -> 0.9174577 | J21: =+J20/J15 -> 0.85553232 | K21: =+K20/K15 -> 0.82780835 | L21: =+L20/L15 -> 0.80167497 | M21: =+M20/M15 -> 0.78385867 | N21: =+N20/N15 -> 0.76766964
C23: Sales & Marketing Expenses | D23: =SUMIF('Monthly Detail'!$1:$1,'Annual Summary'!D$11, 'Monthly Detail'!$70:$70) -> 0 | E23: =SUMIF('Monthly Detail'!$1:$1,'Annual Summary'!E$11, 'Monthly Detail'!$70:$70) -> 0 | F23: =+E23-D23 -> 0 | G23: =SUMIF('Monthly Detail'!$1:$1,'Annual Summary'!G$11, 'Monthly Detail'!$70:$70) -> 4245 | H23: =+G23-E23 -> 4245 | I23: =SUMIF('Monthly Detail'!$1:$1,'Annual Summary'!I$11, 'Monthly Detail'!$70:$70) -> 0 | J23: =SUMIF('Monthly Detail'!$1:$1,'Annual Summary'!J$11, 'Monthly Detail'!$70:$70) -> 0 | K23: =SUMIF('Monthly Detail'!$1:$1,'Annual Summary'!K$11, 'Monthly Detail'!$70:$70) -> 0 | L23: =SUMIF('Monthly Detail'!$1:$1,'Annual Summary'!L$11, 'Monthly Detail'!$70:$70) -> 0 | M23: =SUMIF('Monthly Detail'!$1:$1,'Annual Summary'!M$11, 'Monthly Detail'!$70:$70) -> 0 | N23: =SUMIF('Monthly Detail'!$1:$1,'Annual Summary'!N$11, 'Monthly Detail'!$70:$70) -> 0
C24: General & Admintrative Expenses | D24: =SUMIF('Monthly Detail'!$1:$1,'Annual Summary'!D$11, 'Monthly Detail'!$93:$93) -> 2457.99 | E24: =SUMIF('Monthly Detail'!$1:$1,'Annual Summary'!E$11, 'Monthly Detail'!$93:$93) -> 7947.79 | F24: =+E24-D24 -> 5489.8 | G24: =SUMIF('Monthly Detail'!$1:$1,'Annual Summary'!G$11, 'Monthly Detail'!$93:$93) -> 12495.71 | H24: =+G24-E24 -> 4547.92 | I24: =SUMIF('Monthly Detail'!$1:$1,'Annual Summary'!I$11, 'Monthly Detail'!$93:$93) -> 118763.02 | J24: =SUMIF('Monthly Detail'!$1:$1,'Annual Summary'!J$11, 'Monthly Detail'!$93:$93) -> 180740.57 | K24: =SUMIF('Monthly Detail'!$1:$1,'Annual Summary'!K$11, 'Monthly Detail'!$93:$93) -> 184109.16 | L24: =SUMIF('Monthly Detail'!$1:$1,'Annual Summary'!L$11, 'Monthly Detail'!$93:$93) -> 210365.98 | M24: =SUMIF('Monthly Detail'!$1:$1,'Annual Summary'!M$11, 'Monthly Detail'!$93:$93) -> 224246.92 | N24: =SUMIF('Monthly Detail'!$1:$1,'Annual Summary'!N$11, 'Monthly Detail'!$93:$93) -> 233327.72
C25: Owner Guarenteed Payments | D25: =SUMIF('Monthly Detail'!$1:$1,'Annual Summary'!D$11, 'Monthly Detail'!94:94) -> 0 | E25: =SUMIF('Monthly Detail'!$1:$1,'Annual Summary'!E$11, 'Monthly Detail'!94:94) -> 0 | F25: =+E25-D25 -> 0 | G25: =SUMIF('Monthly Detail'!$1:$1,'Annual Summary'!G$11, 'Monthly Detail'!94:94) -> 0 | H25: =+G25-E25 -> 0 | I25: =SUMIF('Monthly Detail'!$1:$1,'Annual Summary'!I$11, 'Monthly Detail'!94:94) -> 0 | J25: =SUMIF('Monthly Detail'!$1:$1,'Annual Summary'!J$11, 'Monthly Detail'!94:94) -> 0 | K25: =SUMIF('Monthly Detail'!$1:$1,'Annual Summary'!K$11, 'Monthly Detail'!94:94) -> 0 | L25: =SUMIF('Monthly Detail'!$1:$1,'Annual Summary'!L$11, 'Monthly Detail'!94:94) -> 0 | M25: =SUMIF('Monthly Detail'!$1:$1,'Annual Summary'!M$11, 'Monthly Detail'!94:94) -> 0 | N25: =SUMIF('Monthly Detail'!$1:$1,'Annual Summary'!N$11, 'Monthly Detail'!94:94) -> 0
C26: Operating Expense | D26: =SUM(D23:D25) -> 2457.99 | E26: =SUM(E23:E25) -> 7947.79 | F26: =+E26-D26 -> 5489.8 | G26: =SUM(G23:G25) -> 16740.71 | H26: =+G26-E26 -> 8792.92 | I26: =SUM(I23:I25) -> 118763.02 | J26: =SUM(J23:J25) -> 180740.57 | K26: =SUM(K23:K25) -> 184109.16 | L26: =SUM(L23:L25) -> 210365.98 | M26: =SUM(M23:M25) -> 224246.92 | N26: =SUM(N23:N25) -> 233327.72
C28: Net Operating Income (EBITDA) | D28: =D20-D26 -> 6879.51 | E28: =E20-E26 -> 36497.71 | F28: =+E28-D28 -> 29618.2 | G28: =G20-G26 -> 69073.53 | H28: =+G28-E28 -> 32575.82 | I28: =I20-I26 -> 39939.114 | J28: =J20-J26 -> 30406.183 | K28: =K20-K26 -> 89941.979 | L28: =L20-L26 -> 160289.39 | M28: =M20-M26 -> 289571.23 | N28: =N20-N26 -> 476732.83
C29: EBITDA % | D29: =D28/D15 -> 0.73676145 | E29: =E28/E15 -> 0.82117897 | F29: =+E29-D29 -> 0.084417526 | G29: =G28/G15 -> 0.76895117 | H29: =+G29-E29 -> -0.052227805 | I29: =I28/I15 -> 0.23088818 | J29: =J28/J15 -> 0.12320091 | K29: =K28/K15 -> 0.27168185 | L29: =L28/L15 -> 0.34668321 | M29: =M28/M15 -> 0.4417573 | N29: =N28/N15 -> 0.51541142
C31: Other Income / (Expense) | D31: 0 | E31: 0 | F31: =+E31-D31 -> 0 | G31: =SUMIF('Monthly Detail'!$1:$1,'Annual Summary'!G$11, 'Monthly Detail'!107:107) -> -5018.23 | H31: =+G31-E31 -> -5018.23 | I31: =SUMIF('Monthly Detail'!$1:$1,'Annual Summary'!I$11, 'Monthly Detail'!107:107) -> -9246.3 | J31: =SUMIF('Monthly Detail'!$1:$1,'Annual Summary'!J$11, 'Monthly Detail'!107:107) -> -9600 | K31: =SUMIF('Monthly Detail'!$1:$1,'Annual Summary'!K$11, 'Monthly Detail'!107:107) -> -9600 | L31: =SUMIF('Monthly Detail'!$1:$1,'Annual Summary'!L$11, 'Monthly Detail'!107:107) -> -9600 | M31: =SUMIF('Monthly Detail'!$1:$1,'Annual Summary'!M$11, 'Monthly Detail'!107:107) -> -9600 | N31: =SUMIF('Monthly Detail'!$1:$1,'Annual Summary'!N$11, 'Monthly Detail'!107:107) -> -9600
C32: Net Income | D32: =D28+D31 -> 6879.51 | E32: =E28+E31 -> 36497.71 | F32: =+E32-D32 -> 29618.2 | G32: =G28+G31 -> 64055.3 | H32: =+G32-E32 -> 27557.59 | I32: =I28+I31 -> 30692.814 | J32: =J28+J31 -> 20806.183 | K32: =K28+K31 -> 80341.979 | L32: =L28+L31 -> 150689.39 | M32: =M28+M31 -> 279971.23 | N32: =N28+N31 -> 467132.83
C33: NI % | D33: =D32/D15 -> 0.73676145 | E33: =E32/E15 -> 0.82117897 | F33: =+E33-D33 -> 0.084417526 | G33: =G32/G15 -> 0.71308644 | H33: =+G33-E33 -> -0.10809253 | I33: =I32/I15 -> 0.17743528 | J33: =J32/J15 -> 0.084303271 | K33: =K32/K15 -> 0.24268376 | L33: =L32/L15 -> 0.32591977 | M33: =M32/M15 -> 0.42711196 | N33: =N32/N15 -> 0.50503255

Sheet 2025 AOP
B8: 2025 Annual Operating Plan
C10: January | D10: February | E10: March | F10: April | G10: May | H10: June | I10: July | J10: August | K10: September | L10: October | M10: November | N10: December | P10: Total
C11: 45688 | D11: 45716 | E11: 45747 | F11: 45777 | G11: 45808 | H11: 45838 | I11: 45869 | J11: 45900 | K11: 45930 | L11: 45961 | M11: 45991 | N11: 46022 | O11: 46053
B12: Service Income | C12: 7677.1321 | D12: 12691.952 | E12: 7473.9 | F12: 9831.9706 | G12: 10732.473 | H12: 5809.4312 | I12: 10858.9 | J12: 15862.285 | K12: 12122.449 | L12: 15626.953 | M12: 8797.317 | N12: 6287.4785 | P12: 123772.24
B13: Tips | C13: 13.919186 | D13: 23.011412 | E13: 13.550712 | F13: 17.826062 | G13: 19.458736 | H13: 10.532912 | I13: 19.687958 | J13: 28.75945 | K13: 21.978862 | L13: 28.332777 | M13: 15.950161 | N13: 11.399646 | P13: 224.40787
B14: Total Income | C14: 7691.0513 | D14: 12714.964 | E14: 7487.4507 | F14: 9849.7967 | G14: 10751.932 | H14: 5819.9642 | I14: 10878.588 | J14: 15891.044 | K14: 12144.428 | L14: 15655.286 | M14: 8813.2671 | N14: 6298.8782 | P14: 123996.65
B15: # of Students | C15: 34.8 | D15: 35.8 | E15: 33.6 | F15: 32.4 | G15: 33.4 | H15: 29.2 | I15: 31.2 | J15: 37.2 | K15: 43.2 | L15: 45 | M15: 43.6 | N15: 42.2
B16: # of Sessions | C16: 34 | D16: 56 | E16: 36 | F16: 49 | G16: 76 | H16: 45 | I16: 118 | J16: 169 | K16: 125 | L16: 173 | M16: 90 | N16: 129.33333
B18: Subcontractor Expenses | C18: 0 | D18: 919.6069 | E18: 450 | F18: 1073.0882 | G18: 2850.0435 | H18: 1050 | I18: 1894.25 | J18: 4130.1794 | K18: 1256.4172 | L18: 1439.8958 | M18: 524 | N18: 0 | P18: 15587.481
B19: Gross Margin | C19: 7691.0513 | D19: 11795.357 | E19: 7037.4507 | F19: 8776.7084 | G19: 7901.8881 | H19: 4769.9642 | I19: 8984.338 | J19: 11760.865 | K19: 10888.011 | L19: 14215.39 | M19: 8289.2671 | N19: 6298.8782 | P19: 108409.17
B20: GM % | C20: 1 | D20: 0.92767522 | E20: 0.93989944 | F20: 0.89105478 | G20: 0.7349273 | H20: 0.81958652 | I20: 0.82587354 | J20: 0.74009389 | K20: 0.89654373 | L20: 0.90802494 | M20: 0.94054418 | N20: 1 | P20: 0.87429111
B22: Sales & Marketing Expenses | C22: 0 | D22: 0 | E22: 0 | F22: 0 | G22: 0 | H22: 0 | I22: 0 | J22: 0 | K22: 0 | L22: 0 | M22: 0 | N22: 0 | P22: 0
B23: General & Admintrative Expenses | C23: 1454.0336 | D23: 1416.0203 | E23: 1647.4689 | F23: 1523.6384 | G23: 1352.726 | H23: 1193.7039 | I23: 1556.8098 | J23: 2008.4271 | K23: 1397.6245 | L23: 1973.3255 | M23: 1340.2174 | N23: 1635.3956 | P23: 18499.391
B24: Operating Expenses | C24: 1454.0336 | D24: 1416.0203 | E24: 1647.4689 | F24: 1523.6384 | G24: 1352.726 | H24: 1193.7039 | I24: 1556.8098 | J24: 2008.4271 | K24: 1397.6245 | L24: 1973.3255 | M24: 1340.2174 | N24: 1635.3956 | P24: 18499.391
B26: Net Operating Income (EBITDA) | C26: 6237.0177 | D26: 10379.337 | E26: 5389.9818 | F26: 7253.0701 | G26: 6549.1621 | H26: 3576.2603 | I26: 7427.5281 | J26: 9752.4376 | K26: 9490.3861 | L26: 12242.065 | M26: 6949.0498 | N26: 4663.4826 | P26: 89909.777
B27: EBITDA % | C27: 0.81094475 | D27: 0.81630878 | E27: 0.71986875 | F27: 0.73636749 | G27: 0.60911493 | H27: 0.61448149 | I27: 0.68276583 | J27: 0.61370653 | K27: 0.78146013 | L27: 0.78197643 | M27: 0.78847601 | N27: 0.74036716 | P27: 0.72509844
B29: Other Income / (Expense) | C29: -800 | D29: -800 | E29: -800 | F29: -800 | G29: -800 | H29: -800 | I29: -800 | J29: -800 | K29: -800 | L29: -800 | M29: -800 | N29: -800 | P29: -9600
B30: Net Income | C30: 5437.0177 | D30: 9579.3366 | E30: 4589.9818 | F30: 6453.0701 | G30: 5749.1621 | H30: 2776.2603 | I30: 6627.5281 | J30: 8952.4376 | K30: 8690.3861 | L30: 11442.065 | M30: 6149.0498 | N30: 3863.4826 | P30: 80309.777
B31: NI % | C31: 0.70692776 | D31: 0.75339079 | E31: 0.61302331 | F31: 0.65514754 | G31: 0.5347097 | H31: 0.4770236 | I31: 0.60922687 | J31: 0.56336371 | K31: 0.7155863 | L31: 0.73087548 | M31: 0.69770377 | N31: 0.61336042 | P31: 0.64767699
B32: Cash Contributions | C32: 0 | D32: 0 | E32: 0 | F32: 2400 | G32: 0 | H32: 0 | I32: 0 | J32: 0 | K32: 0 | L32: 0 | M32: 0 | N32: 0 | P32: 2400
... B34: Accrued Tax Burden | C34: 1631.1053 | D34: 4744.9063 | E34: 6361.9008 | F34: 8537.8218 | G34: 10502.57 | H34: 11575.449 | I34: 13803.707 | J34: 16729.438 | K34: 19576.554 | L34: 23249.173 | M34: 25333.888 | N34: 26732.933 | P34: 26732.933
B36: Operating Cash | C36: 5910.492 | D36: 11084.272 | E36: 13626.641 | F36: 16286.345 | G36: 18578.006 | H36: 19238.674 | I36: 21452.662 | J36: 26002.178 | K36: 32304.328 | L36: 39688.856 | M36: 44161.647 | N36: 45353.467
B37: Cash Inflow (Outflow) | C37: 1691.5453 | D37: 5173.7804 | E37: 2542.3684 | F37: 2659.704 | G37: 2291.6609 | H37: 660.66802 | I37: 2213.988 | J37: 4549.5165 | K37: 6302.1499 | L37: 7384.5278 | M37: 4472.7907 | N37: 1191.8202

Sheet 2023 Overview
C10: =TEXT('Monthly Detail'!D4,"mmmm") -> January | D10: =TEXT('Monthly Detail'!E4,"mmmm") -> February | E10: =TEXT('Monthly Detail'!F4,"mmmm") -> March | F10: =TEXT('Monthly Detail'!G4,"mmmm") -> April | G10: =TEXT('Monthly Detail'!H4,"mmmm") -> May | H10: =TEXT('Monthly Detail'!I4,"mmmm") -> June | I10: =TEXT('Monthly Detail'!J4,"mmmm") -> July | J10: =TEXT('Monthly Detail'!K4,"mmmm") -> August | ... N10: =TEXT('Monthly Detail'!O4,"mmmm") -> December | P10: Total
C11: 44957 | D11: 44985 | E11: 45016 | F11: 45046 | G11: 45077 | H11: 45107 | I11: 45138 | J11: 45169 | K11: 45199 | L11: 45230 | M11: 45260 | N11: 45291 | O11: 45322
B12: Service Income | C12: =SUMIF('Monthly Detail'!$4:$4, '2023 Overview'!C$11, 'Monthly Detail'!12:12) -> 1510 | D12: =SUMIF('Monthly Detail'!$4:$4, '2023 Overview'!D$11, 'Monthly Detail'!12:12) -> 1225 | E12: =SUMIF('Monthly Detail'!$4:$4, '2023 Overview'!E$11, 'Monthly Detail'!12:12) -> 1177.5 | F12: =SUMIF('Monthly Detail'!$4:$4, '2023 Overview'!F$11, 'Monthly Detail'!12:12) -> 1919.91 | G12: =SUMIF('Monthly Detail'!$4:$4, '2023 Overview'!G$11, 'Monthly Detail'!12:12) -> 2446.25 | H12: =SUMIF('Monthly Detail'!$4:$4, '2023 Overview'!H$11, 'Monthly Detail'!12:12) -> 2038.75 | I12: =SUMIF('Monthly Detail'!$4:$4, '2023 Overview'!I$11, 'Monthly Detail'!12:12) -> 2785 | J12: =SUMIF('Monthly Detail'!$4:$4, '2023 Overview'!J$11, 'Monthly Detail'!12:12) -> 7051.66 | ... N12: =SUMIF('Monthly Detail'!$4:$4, '2023 Overview'!N$11, 'Monthly Detail'!12:12) -> 2095 | P12: =SUM(C12:O12) -> 43837.41
B13: Misc. | C13: =SUMIF('Monthly Detail'!$4:$4, '2023 Overview'!C$11, 'Monthly Detail'!13:13) -> 35.99 | D13: =SUMIF('Monthly Detail'!$4:$4, '2023 Overview'!D$11, 'Monthly Detail'!13:13) -> 30.75 | E13: =SUMIF('Monthly Detail'!$4:$4, '2023 Overview'!E$11, 'Monthly Detail'!13:13) -> 29.25 | F13: =SUMIF('Monthly Detail'!$4:$4, '2023 Overview'!F$11, 'Monthly Detail'!13:13) -> 37.5 | G13: =SUMIF('Monthly Detail'!$4:$4, '2023 Overview'!G$11, 'Monthly Detail'!13:13) -> 40.68 | H13: =SUMIF('Monthly Detail'!$4:$4, '2023 Overview'!H$11, 'Monthly Detail'!13:13) -> 4.68 | I13: =SUMIF('Monthly Detail'!$4:$4, '2023 Overview'!I$11, 'Monthly Detail'!13:13) -> 50.5 | J13: =SUMIF('Monthly Detail'!$4:$4, '2023 Overview'!J$11, 'Monthly Detail'!13:13) -> 27 | ... N13: =SUMIF('Monthly Detail'!$4:$4, '2023 Overview'!N$11, 'Monthly Detail'!13:13) -> 49.5
B14: Total Income | C14: =SUM(C12:C13) -> 1545.99 | D14: =SUM(D12:D13) -> 1255.75 | E14: =SUM(E12:E13) -> 1206.75 | F14: =SUM(F12:F13) -> 1957.41 | G14: =SUM(G12:G13) -> 2486.93 | H14: =SUM(H12:H13) -> 2043.43 | I14: =SUM(I12:I13) -> 2835.5 | J14: =SUM(J12:J13) -> 7078.66 | ... N14: =SUM(N12:N13) -> 2144.5 | P14: =SUM(P12:P12) -> 43837.41
B16: Gross Margin | C16: =C14 -> 1545.99 | D16: =D14 -> 1255.75 | E16: =E14 -> 1206.75 | F16: =F14 -> 1957.41 | G16: =G14 -> 2486.93 | H16: =H14 -> 2043.43 | I16: =I14 -> 2835.5 | J16: =J14 -> 7078.66 | ... N16: =N14 -> 2144.5 | P16: =P14 -> 43837.41
B17: GM % | C17: =C16/C14 -> 1 | D17: =D16/D14 -> 1 | E17: =E16/E14 -> 1 | F17: =F16/F14 -> 1 | G17: =G16/G14 -> 1 | H17: =H16/H14 -> 1 | I17: =I16/I14 -> 1 | J17: =J16/J14 -> 1 | ... N17: =N16/N14 -> 1 | P17: =P16/P14 -> 1
B19: General & Admintrative Expenses | C19: =SUMIF('Monthly Detail'!$4:$4, '2023 Overview'!C$11, 'Monthly Detail'!$93:$93) -> 235.13 | D19: =SUMIF('Monthly Detail'!$4:$4, '2023 Overview'!D$11, 'Monthly Detail'!$93:$93) -> 153.76 | E19: =SUMIF('Monthly Detail'!$4:$4, '2023 Overview'!E$11, 'Monthly Detail'!$93:$93) -> 105.36 | F19: =SUMIF('Monthly Detail'!$4:$4, '2023 Overview'!F$11, 'Monthly Detail'!$93:$93) -> 272.84 | G19: =SUMIF('Monthly Detail'!$4:$4, '2023 Overview'!G$11, 'Monthly Detail'!$93:$93) -> 551 | H19: =SUMIF('Monthly Detail'!$4:$4, '2023 Overview'!H$11, 'Monthly Detail'!$93:$93) -> 647.26 | I19: =SUMIF('Monthly Detail'!$4:$4, '2023 Overview'!I$11, 'Monthly Detail'!$93:$93) -> 432.76 | J19: =SUMIF('Monthly Detail'!$4:$4, '2023 Overview'!J$11, 'Monthly Detail'!$93:$93) -> 851.95 | ... N19: =SUMIF('Monthly Detail'!$4:$4, '2023 Overview'!N$11, 'Monthly Detail'!$93:$93) -> 797.47 | P19: =SUM(C19:O19) -> 7947.79
B20: Operating Expenses | C20: =SUM(C19:C19) -> 235.13 | D20: =SUM(D19:D19) -> 153.76 | E20: =SUM(E19:E19) -> 105.36 | F20: =SUM(F19:F19) -> 272.84 | G20: =SUM(G19:G19) -> 551 | H20: =SUM(H19:H19) -> 647.26 | I20: =SUM(I19:I19) -> 432.76 | J20: =SUM(J19:J19) -> 851.95 | ... N20: =SUM(N19:N19) -> 797.47 | P20: =SUM(P19:P19) -> 7947.79
B22: Net Operating Income (EBITDA) | C22: =C16-C20 -> 1310.86 | D22: =D16-D20 -> 1101.99 | E22: =E16-E20 -> 1101.39 | F22: =F16-F20 -> 1684.57 | G22: =G16-G20 -> 1935.93 | H22: =H16-H20 -> 1396.17 | I22: =I16-I20 -> 2402.74 | J22: =J16-J20 -> 6226.71 | ... N22: =N16-N20 -> 1347.03 | P22: =P16-P20 -> 35889.62
B23: EBITDA % | C23: =C22/C14 -> 0.84790975 | D23: =D22/D14 -> 0.87755525 | E23: =E22/E14 -> 0.91269111 | F23: =F22/F14 -> 0.86061173 | G23: =G22/G14 -> 0.77844169 | H23: =H22/H14 -> 0.68324826 | I23: =I22/I14 -> 0.84737789 | J23: =J22/J14 -> 0.8796453 | ... N23: =N22/N14 -> 0.62813243 | P23: =P22/P14 -> 0.81869846
B25: Other Income / (Expense) | C25: =SUMIF('Monthly Detail'!$4:$4, '2023 Overview'!C$11, 'Monthly Detail'!102:102) -> 0 | D25: =SUMIF('Monthly Detail'!$4:$4, '2023 Overview'!D$11, 'Monthly Detail'!102:102) -> 0 | E25: =SUMIF('Monthly Detail'!$4:$4, '2023 Overview'!E$11, 'Monthly Detail'!102:102) -> 0 | F25: =SUMIF('Monthly Detail'!$4:$4, '2023 Overview'!F$11, 'Monthly Detail'!102:102) -> 0.01 | G25: =SUMIF('Monthly Detail'!$4:$4, '2023 Overview'!G$11, 'Monthly Detail'!102:102) -> 0.01 | H25: =SUMIF('Monthly Detail'!$4:$4, '2023 Overview'!H$11, 'Monthly Detail'!102:102) -> 0.01 | I25: =SUMIF('Monthly Detail'!$4:$4, '2023 Overview'!I$11, 'Monthly Detail'!102:102) -> 0.03 | J25: =SUMIF('Monthly Detail'!$4:$4, '2023 Overview'!J$11, 'Monthly Detail'!102:102) -> 0.01 | ... N25: =SUMIF('Monthly Detail'!$4:$4, '2023 Overview'!N$11, 'Monthly Detail'!102:102) -> 0 | P25: =SUM(C25:O25) -> 0.07
B26: Net Income | C26: =C22+SUM(C25:C25) -> 1310.86 | D26: =D22+SUM(D25:D25) -> 1101.99 | E26: =E22+SUM(E25:E25) -> 1101.39 | F26: =F22+SUM(F25:F25) -> 1684.58 | G26: =G22+SUM(G25:G25) -> 1935.94 | H26: =H22+SUM(H25:H25) -> 1396.18 | I26: =I22+SUM(I25:I25) -> 2402.77 | J26: =J22+SUM(J25:J25) -> 6226.72 | ... N26: =N22+SUM(N25:N25) -> 1347.03 | P26: =P22+SUM(P25:P25) -> 35889.69
B27: NI % | C27: =C26/C14 -> 0.84790975 | D27: =D26/D14 -> 0.87755525 | E27: =E26/E14 -> 0.91269111 | F27: =F26/F14 -> 0.86061684 | G27: =G26/G14 -> 0.77844571 | H27: =H26/H14 -> 0.68325316 | I27: =I26/I14 -> 0.84738847 | J27: =J26/J14 -> 0.87964671 | ... N27: =N26/N14 -> 0.62813243 | P27: =P26/P14 -> 0.81870006
B29: Operating Cash | C29: =SUMIF('Monthly Detail'!$4:$4, '2023 Overview'!C$11, 'Monthly Detail'!172:172) -> 169.96 | D29: =SUMIF('Monthly Detail'!$4:$4, '2023 Overview'!D$11, 'Monthly Detail'!172:172) -> 212.95 | E29: =SUMIF('Monthly Detail'!$4:$4, '2023 Overview'!E$11, 'Monthly Detail'!172:172) -> 127.39 | F29: =SUMIF('Monthly Detail'!$4:$4, '2023 Overview'!F$11, 'Monthly Detail'!172:172) -> 395.42 | G29: =SUMIF('Monthly Detail'!$4:$4, '2023 Overview'!G$11, 'Monthly Detail'!172:172) -> 300.21 | H29: =SUMIF('Monthly Detail'!$4:$4, '2023 Overview'!H$11, 'Monthly Detail'!172:172) -> 433.57 | I29: =SUMIF('Monthly Detail'!$4:$4, '2023 Overview'!I$11, 'Monthly Detail'!172:172) -> 566.73 | J29: =SUMIF('Monthly Detail'!$4:$4, '2023 Overview'!J$11, 'Monthly Detail'!172:172) -> 503.45 | ... N29: =SUMIF('Monthly Detail'!$4:$4, '2023 Overview'!N$11, 'Monthly Detail'!172:172) -> 997.02
B30: Cash Inflow (Outflow) | C30: =SUMIF('Monthly Detail'!$4:$4, '2023 Overview'!C$11, 'Monthly Detail'!169:169) -> 225.86 | D30: =SUMIF('Monthly Detail'!$4:$4, '2023 Overview'!D$11, 'Monthly Detail'!169:169) -> 42.99 | E30: =SUMIF('Monthly Detail'!$4:$4, '2023 Overview'!E$11, 'Monthly Detail'!169:169) -> -85.56 | F30: =SUMIF('Monthly Detail'!$4:$4, '2023 Overview'!F$11, 'Monthly Detail'!169:169) -> 268.03 | G30: =SUMIF('Monthly Detail'!$4:$4, '2023 Overview'!G$11, 'Monthly Detail'!169:169) -> -95.21 | H30: =SUMIF('Monthly Detail'!$4:$4, '2023 Overview'!H$11, 'Monthly Detail'!169:169) -> 133.36 | I30: =SUMIF('Monthly Detail'!$4:$4, '2023 Overview'!I$11, 'Monthly Detail'!169:169) -> 133.16 | J30: =SUMIF('Monthly Detail'!$4:$4, '2023 Overview'!J$11, 'Monthly Detail'!169:169) -> -63.28 | ... N30: =SUMIF('Monthly Detail'!$4:$4, '2023 Overview'!N$11, 'Monthly Detail'!169:169) -> 269.53

Sheet 2025 Overview (Rolling)
B8: 2025 Overview (Rolling Forecast)
C10: =TEXT('Monthly Detail'!D4,"mmmm") -> January | D10: =TEXT('Monthly Detail'!E4,"mmmm") -> February | E10: =TEXT('Monthly Detail'!F4,"mmmm") -> March | F10: =TEXT('Monthly Detail'!G4,"mmmm") -> April | G10: =TEXT('Monthly Detail'!H4,"mmmm") -> May | H10: =TEXT('Monthly Detail'!I4,"mmmm") -> June | I10: =TEXT('Monthly Detail'!J4,"mmmm") -> July | J10: =TEXT('Monthly Detail'!K4,"mmmm") -> August | ... N10: =TEXT('Monthly Detail'!O4,"mmmm") -> December | P10: Total
C11: 45688 | D11: 45716 | E11: 45747 | F11: 45777 | G11: 45808 | H11: 45838 | I11: 45869 | J11: 45900 | K11: 45930 | L11: 45961 | M11: 45991 | N11: 46022 | O11: 45322
B12: Service Income | C12: =SUMIF('Monthly Detail'!$4:$4, '2025 Overview (Rolling)'!C$11, 'Monthly Detail'!12:12) -> 6477.5 | D12: =SUMIF('Monthly Detail'!$4:$4, '2025 Overview (Rolling)'!D$11, 'Monthly Detail'!12:12) -> 8052.5 | E12: =SUMIF('Monthly Detail'!$4:$4, '2025 Overview (Rolling)'!E$11, 'Monthly Detail'!12:12) -> 7630 | F12: =SUMIF('Monthly Detail'!$4:$4, '2025 Overview (Rolling)'!F$11, 'Monthly Detail'!12:12) -> 3756.25 | G12: =SUMIF('Monthly Detail'!$4:$4, '2025 Overview (Rolling)'!G$11, 'Monthly Detail'!12:12) -> 6032.5 | H12: =SUMIF('Monthly Detail'!$4:$4, '2025 Overview (Rolling)'!H$11, 'Monthly Detail'!12:12) -> 6822.5 | I12: =SUMIF('Monthly Detail'!$4:$4, '2025 Overview (Rolling)'!I$11, 'Monthly Detail'!12:12) -> 14855 | J12: =SUMIF('Monthly Detail'!$4:$4, '2025 Overview (Rolling)'!J$11, 'Monthly Detail'!12:12) -> 20412.5 | ... N12: =SUMIF('Monthly Detail'!$4:$4, '2025 Overview (Rolling)'!N$11, 'Monthly Detail'!12:12) -> 17967.542 | P12: =SUM(C12:O12) -> 172325.82
B13: Tips | C13: =SUMIF('Monthly Detail'!$4:$4, '2025 Overview (Rolling)'!C$11, 'Monthly Detail'!13:13) -> 108 | D13: =SUMIF('Monthly Detail'!$4:$4, '2025 Overview (Rolling)'!D$11, 'Monthly Detail'!13:13) -> 59.62 | E13: =SUMIF('Monthly Detail'!$4:$4, '2025 Overview (Rolling)'!E$11, 'Monthly Detail'!13:13) -> 52.37 | F13: =SUMIF('Monthly Detail'!$4:$4, '2025 Overview (Rolling)'!F$11, 'Monthly Detail'!13:13) -> 0 | G13: =SUMIF('Monthly Detail'!$4:$4, '2025 Overview (Rolling)'!G$11, 'Monthly Detail'!13:13) -> 12 | H13: =SUMIF('Monthly Detail'!$4:$4, '2025 Overview (Rolling)'!H$11, 'Monthly Detail'!13:13) -> 93.5 | I13: =SUMIF('Monthly Detail'!$4:$4, '2025 Overview (Rolling)'!I$11, 'Monthly Detail'!13:13) -> 75 | J13: =SUMIF('Monthly Detail'!$4:$4, '2025 Overview (Rolling)'!J$11, 'Monthly Detail'!13:13) -> 44.5 | ... N13: =SUMIF('Monthly Detail'!$4:$4, '2025 Overview (Rolling)'!N$11, 'Monthly Detail'!13:13) -> 76.178933 | P13: =+SUM(C13:N13) -> 654.50436
B14: Total Income | C14: =SUM(C12:C13) -> 6585.5 | D14: =SUM(D12:D13) -> 8112.12 | E14: =SUM(E12:E13) -> 7682.37 | F14: =SUM(F12:F13) -> 3756.25 | G14: =SUM(G12:G13) -> 6044.5 | H14: =SUM(H12:H13) -> 6916 | I14: =SUM(I12:I13) -> 14930 | J14: =SUM(J12:J13) -> 20457 | ... N14: =SUM(N12:N13) -> 18043.721 | P14: =SUM(P12:P13) -> 172980.33
B15: # of Students | C15: =SUMIF('Monthly Detail'!$4:$4, '2025 Overview (Rolling)'!C$11, 'Monthly Detail'!17:17) -> 24 | D15: =SUMIF('Monthly Detail'!$4:$4, '2025 Overview (Rolling)'!D$11, 'Monthly Detail'!17:17) -> 28 | E15: =SUMIF('Monthly Detail'!$4:$4, '2025 Overview (Rolling)'!E$11, 'Monthly Detail'!17:17) -> 24 | F15: =SUMIF('Monthly Detail'!$4:$4, '2025 Overview (Rolling)'!F$11, 'Monthly Detail'!17:17) -> 23 | G15: =SUMIF('Monthly Detail'!$4:$4, '2025 Overview (Rolling)'!G$11, 'Monthly Detail'!17:17) -> 20 | H15: =SUMIF('Monthly Detail'!$4:$4, '2025 Overview (Rolling)'!H$11, 'Monthly Detail'!17:17) -> 25 | I15: =SUMIF('Monthly Detail'!$4:$4, '2025 Overview (Rolling)'!I$11, 'Monthly Detail'!17:17) -> 35 | J15: =SUMIF('Monthly Detail'!$4:$4, '2025 Overview (Rolling)'!J$11, 'Monthly Detail'!17:17) -> 48 | ... N15: =SUMIF('Monthly Detail'!$4:$4, '2025 Overview (Rolling)'!N$11, 'Monthly Detail'!17:17) -> 57.6
B16: # of Sessions | C16: =SUMIF('Monthly Detail'!$4:$4, '2025 Overview (Rolling)'!C$11, 'Monthly Detail'!22:22) -> 56 | D16: =SUMIF('Monthly Detail'!$4:$4, '2025 Overview (Rolling)'!D$11, 'Monthly Detail'!22:22) -> 66 | E16: =SUMIF('Monthly Detail'!$4:$4, '2025 Overview (Rolling)'!E$11, 'Monthly Detail'!22:22) -> 73 | F16: =SUMIF('Monthly Detail'!$4:$4, '2025 Overview (Rolling)'!F$11, 'Monthly Detail'!22:22) -> 37 | G16: =SUMIF('Monthly Detail'!$4:$4, '2025 Overview (Rolling)'!G$11, 'Monthly Detail'!22:22) -> 62 | H16: =SUMIF('Monthly Detail'!$4:$4, '2025 Overview (Rolling)'!H$11, 'Monthly Detail'!22:22) -> 51 | I16: =SUMIF('Monthly Detail'!$4:$4, '2025 Overview (Rolling)'!I$11, 'Monthly Detail'!22:22) -> 120 | J16: =SUMIF('Monthly Detail'!$4:$4, '2025 Overview (Rolling)'!J$11, 'Monthly Detail'!22:22) -> 163 | ... N16: =SUMIF('Monthly Detail'!$4:$4, '2025 Overview (Rolling)'!N$11, 'Monthly Detail'!22:22) -> 247.623
B18: Subcontractor Expenses | C18: =SUMIF('Monthly Detail'!$4:$4, '2025 Overview (Rolling)'!C$11, 'Monthly Detail'!63:63) -> 0 | D18: =SUMIF('Monthly Detail'!$4:$4, '2025 Overview (Rolling)'!D$11, 'Monthly Detail'!63:63) -> 450 | E18: =SUMIF('Monthly Detail'!$4:$4, '2025 Overview (Rolling)'!E$11, 'Monthly Detail'!63:63) -> 0 | F18: =SUMIF('Monthly Detail'!$4:$4, '2025 Overview (Rolling)'!F$11, 'Monthly Detail'!63:63) -> 0 | G18: =SUMIF('Monthly Detail'!$4:$4, '2025 Overview (Rolling)'!G$11, 'Monthly Detail'!63:63) -> 270 | H18: =SUMIF('Monthly Detail'!$4:$4, '2025 Overview (Rolling)'!H$11, 'Monthly Detail'!63:63) -> 0 | I18: =SUMIF('Monthly Detail'!$4:$4, '2025 Overview (Rolling)'!I$11, 'Monthly Detail'!63:63) -> 1582.5 | J18: =SUMIF('Monthly Detail'!$4:$4, '2025 Overview (Rolling)'!J$11, 'Monthly Detail'!63:63) -> 684 | ... N18: =SUMIF('Monthly Detail'!$4:$4, '2025 Overview (Rolling)'!N$11, 'Monthly Detail'!63:63) -> 959.95423 | P18: =SUM(C18:O18) -> 14278.194
B19: Gross Margin | C19: =C14-C18 -> 6585.5 | D19: =D14-D18 -> 7662.12 | E19: =E14-E18 -> 7682.37 | F19: =F14-F18 -> 3756.25 | G19: =G14-G18 -> 5774.5 | H19: =H14-H18 -> 6916 | I19: =I14-I18 -> 13347.5 | J19: =J14-J18 -> 19773 | ... N19: =N14-N18 -> 17083.767 | P19: =P14-P18 -> 158702.13
B20: GM % | C20: =C19/C14 -> 1 | D20: =D19/D14 -> 0.94452745 | E20: =E19/E14 -> 1 | F20: =F19/F14 -> 1 | G20: =G19/G14 -> 0.95533129 | H20: =H19/H14 -> 1 | I20: =I19/I14 -> 0.89400536 | J20: =J19/J14 -> 0.96656401 | ... N20: =N19/N14 -> 0.94679843 | P20: =P19/P14 -> 0.9174577
B22: Sales & Marketing Expenses | C22: =SUMIF('Monthly Detail'!$4:$4, '2025 Overview (Rolling)'!C$11, 'Monthly Detail'!$70:$70) -> 0 | D22: =SUMIF('Monthly Detail'!$4:$4, '2025 Overview (Rolling)'!D$11, 'Monthly Detail'!$70:$70) -> 0 | E22: =SUMIF('Monthly Detail'!$4:$4, '2025 Overview (Rolling)'!E$11, 'Monthly Detail'!$70:$70) -> 0 | F22: =SUMIF('Monthly Detail'!$4:$4, '2025 Overview (Rolling)'!F$11, 'Monthly Detail'!$70:$70) -> 0 | G22: =SUMIF('Monthly Detail'!$4:$4, '2025 Overview (Rolling)'!G$11, 'Monthly Detail'!$70:$70) -> 0 | H22: =SUMIF('Monthly Detail'!$4:$4, '2025 Overview (Rolling)'!H$11, 'Monthly Detail'!$70:$70) -> 0 | I22: =SUMIF('Monthly Detail'!$4:$4, '2025 Overview (Rolling)'!I$11, 'Monthly Detail'!$70:$70) -> 0 | J22: =SUMIF('Monthly Detail'!$4:$4, '2025 Overview (Rolling)'!J$11, 'Monthly Detail'!$70:$70) -> 0 | ... N22: =SUMIF('Monthly Detail'!$4:$4, '2025 Overview (Rolling)'!N$11, 'Monthly Detail'!$70:$70) -> 0 | P22: =SUM(C22:O22) -> 0
B23: General & Admintrative Expenses | C23: =SUMIF('Monthly Detail'!$4:$4, '2025 Overview (Rolling)'!C$11, 'Monthly Detail'!$93:$93) -> 4230.3 | D23: =SUMIF('Monthly Detail'!$4:$4, '2025 Overview (Rolling)'!D$11, 'Monthly Detail'!$93:$93) -> 6699.3 | E23: =SUMIF('Monthly Detail'!$4:$4, '2025 Overview (Rolling)'!E$11, 'Monthly Detail'!$93:$93) -> 7438.99 | F23: =SUMIF('Monthly Detail'!$4:$4, '2025 Overview (Rolling)'!F$11, 'Monthly Detail'!$93:$93) -> 3780.99 | G23: =SUMIF('Monthly Detail'!$4:$4, '2025 Overview (Rolling)'!G$11, 'Monthly Detail'!$93:$93) -> 3678.36 | H23: =SUMIF('Monthly Detail'!$4:$4, '2025 Overview (Rolling)'!H$11, 'Monthly Detail'!$93:$93) -> 4152.38 | I23: =SUMIF('Monthly Detail'!$4:$4, '2025 Overview (Rolling)'!I$11, 'Monthly Detail'!$93:$93) -> 9510.39 | J23: =SUMIF('Monthly Detail'!$4:$4, '2025 Overview (Rolling)'!J$11, 'Monthly Detail'!$93:$93) -> 17648.04 | ... N23: =SUMIF('Monthly Detail'!$4:$4, '2025 Overview (Rolling)'!N$11, 'Monthly Detail'!$93:$93) -> 14483.406 | P23: =SUM(C23:O23) -> 118763.02
B24: Operating Expenses | C24: =SUM(C23:C23) -> 4230.3 | D24: =SUM(D22:D23) -> 6699.3 | E24: =SUM(E22:E23) -> 7438.99 | F24: =SUM(F22:F23) -> 3780.99 | G24: =SUM(G22:G23) -> 3678.36 | H24: =SUM(H22:H23) -> 4152.38 | I24: =SUM(I22:I23) -> 9510.39 | J24: =SUM(J22:J23) -> 17648.04 | K24: =SUM(K22:K23) -> 13518.2 | ... N24: =SUM(N22:N23) -> 14483.406 | P24: =SUM(P22:P23) -> 118763.02
B26: Net Operating Income (EBITDA) | C26: =C19-C24 -> 2355.2 | D26: =D19-D24 -> 962.82 | E26: =E19-E24 -> 243.38 | F26: =F19-F24 -> -24.74 | G26: =G19-G24 -> 2096.14 | H26: =H19-H24 -> 2763.62 | I26: =I19-I24 -> 3837.11 | J26: =J19-J24 -> 2124.96 | ... N26: =N19-N24 -> 2600.3611 | P26: =P19-P24 -> 39939.114
B27: EBITDA % | C27: =C26/C14 -> 0.3576342 | D27: =D26/D14 -> 0.11868907 | E27: =E26/E14 -> 0.031680328 | F27: =F26/F14 -> -0.0065863561 | G27: =G26/G14 -> 0.34678468 | H27: =H26/H14 -> 0.39959803 | I27: =I26/I14 -> 0.2570067 | J27: =J26/J14 -> 0.10387447 | ... N27: =N26/N14 -> 0.14411446 | P27: =P26/P14 -> 0.23088818
B29: Other Income / (Expense) | C29: =SUMIF('Monthly Detail'!$4:$4, '2025 Overview (Rolling)'!C$11, 'Monthly Detail'!107:107) -> -821.84 | D29: =SUMIF('Monthly Detail'!$4:$4, '2025 Overview (Rolling)'!D$11, 'Monthly Detail'!107:107) -> -775.57 | E29: =SUMIF('Monthly Detail'!$4:$4, '2025 Overview (Rolling)'!E$11, 'Monthly Detail'!107:107) -> -757.92 | F29: =SUMIF('Monthly Detail'!$4:$4, '2025 Overview (Rolling)'!F$11, 'Monthly Detail'!107:107) -> -757.92 | G29: =SUMIF('Monthly Detail'!$4:$4, '2025 Overview (Rolling)'!G$11, 'Monthly Detail'!107:107) -> -692.87 | H29: =SUMIF('Monthly Detail'!$4:$4, '2025 Overview (Rolling)'!H$11, 'Monthly Detail'!107:107) -> -769.02 | I29: =SUMIF('Monthly Detail'!$4:$4, '2025 Overview (Rolling)'!I$11, 'Monthly Detail'!107:107) -> -775.25 | J29: =SUMIF('Monthly Detail'!$4:$4, '2025 Overview (Rolling)'!J$11, 'Monthly Detail'!107:107) -> -727.32 | ... N29: =SUMIF('Monthly Detail'!$4:$4, '2025 Overview (Rolling)'!N$11, 'Monthly Detail'!107:107) -> -800 | P29: =SUM(C29:O29) -> -9246.3
B30: Net Income | C30: =C26+SUM(C29:C29) -> 1533.36 | D30: =D26+SUM(D29:D29) -> 187.25 | E30: =E26+SUM(E29:E29) -> -514.54 | F30: =F26+SUM(F29:F29) -> -782.66 | G30: =G26+SUM(G29:G29) -> 1403.27 | H30: =H26+SUM(H29:H29) -> 1994.6 | I30: =I26+SUM(I29:I29) -> 3061.86 | J30: =J26+SUM(J29:J29) -> 1397.64 | ... N30: =N26+SUM(N29:N29) -> 1800.3611 | P30: =P26+SUM(P29:P29) -> 30692.814
B31: NI % | C31: =C30/C14 -> 0.23283881 | D31: =D30/D14 -> 0.023082745 | E31: =E30/E14 -> -0.066976727 | F31: =F30/F14 -> -0.20836206 | G31: =G30/G14 -> 0.23215651 | H31: =H30/H14 -> 0.2884037 | I31: =I30/I14 -> 0.20508104 | J31: =J30/J14 -> 0.068320868 | ... N31: =N30/N14 -> 0.099777707 | P31: =P30/P14 -> 0.17743528
B32: Cash Contributions | C32: ='Monthly Detail'!AN147-'Monthly Detail'!AM147 -> 0 | D32: ='Monthly Detail'!AO147-'Monthly Detail'!AN147 -> 0 | E32: ='Monthly Detail'!AP147-'Monthly Detail'!AO147 -> 0 | F32: ='Monthly Detail'!AQ147-'Monthly Detail'!AP147 -> 20675 | G32: ='Monthly Detail'!AR147-'Monthly Detail'!AQ147 -> 7721 | H32: ='Monthly Detail'!AS147-'Monthly Detail'!AR147 -> 0 | I32: ='Monthly Detail'!AT147-'Monthly Detail'!AS147 -> 250 | J32: ='Monthly Detail'!AU147-'Monthly Detail'!AT147 -> 0 | ... N32: ='Monthly Detail'!AY147-'Monthly Detail'!AX147 -> 0 | P32: =+SUM(C32:N32) -> 30646
B33: Owner Cash Distributions/Taxes | C33: =+SUM('Monthly Detail'!AN148,'Monthly Detail'!AN150:AN151)-SUM('Monthly Detail'!AM148,'Monthly Detail'!AM150:AM151) -> -2150 | D33: =+SUM('Monthly Detail'!AO148,'Monthly Detail'!AO150:AO151)-SUM('Monthly Detail'!AN148,'Monthly Detail'!AN150:AN151) -> 0 | E33: =+SUM('Monthly Detail'!AP148,'Monthly Detail'!AP150:AP151)-SUM('Monthly Detail'!AO148,'Monthly Detail'!AO150:AO151) -> 0 | F33: =+SUM('Monthly Detail'!AQ148,'Monthly Detail'!AQ150:AQ151)-SUM('Monthly Detail'!AP148,'Monthly Detail'!AP150:AP151) -> -20674 | G33: =+SUM('Monthly Detail'!AR148,'Monthly Detail'!AR150:AR151)-SUM('Monthly Detail'!AQ148,'Monthly Detail'!AQ150:AQ151) -> -8467.49 | H33: =+SUM('Monthly Detail'!AS148,'Monthly Detail'!AS150:AS151)-SUM('Monthly Detail'!AR148,'Monthly Detail'!AR150:AR151) -> 655.25 | I33: =+SUM('Monthly Detail'!AT148,'Monthly Detail'!AT150:AT151)-SUM('Monthly Detail'!AS148,'Monthly Detail'!AS150:AS151) -> -1057.78 | J33: =+SUM('Monthly Detail'!AU148,'Monthly Detail'!AU150:AU151)-SUM('Monthly Detail'!AT148,'Monthly Detail'!AT150:AT151) -> 0 | ... N33: =+SUM('Monthly Detail'!AY148,'Monthly Detail'!AY150:AY151)-SUM('Monthly Detail'!AX148,'Monthly Detail'!AX150:AX151) -> 0 | P33: =+SUM(C33:N33) -> -34268.24
B34: Accrued Tax Burden | C34: =+C30*0.3 -> 460.008 | D34: =+C34+(D26*0.3)-SUMIF('Monthly Detail'!$4:$4, '2025 Overview (Rolling)'!D$11, 'Monthly Detail'!75:75) -> 313.034 | E34: =+D34+(E26*0.3)-SUMIF('Monthly Detail'!$4:$4, '2025 Overview (Rolling)'!E$11, 'Monthly Detail'!75:75) -> -30.252 | F34: =+E34+(F26*0.3)-SUMIF('Monthly Detail'!$4:$4, '2025 Overview (Rolling)'!F$11, 'Monthly Detail'!75:75) -> -225.104 | G34: =+F34+(G26*0.3)-SUMIF('Monthly Detail'!$4:$4, '2025 Overview (Rolling)'!G$11, 'Monthly Detail'!75:75) -> 253.798 | H34: =+G34+(H26*0.3)-SUMIF('Monthly Detail'!$4:$4, '2025 Overview (Rolling)'!H$11, 'Monthly Detail'!75:75) -> 895.464 | I34: =+H34+(I26*0.3)-SUMIF('Monthly Detail'!$4:$4, '2025 Overview (Rolling)'!I$11, 'Monthly Detail'!75:75) -> 1895.827 | J34: =+I34+(J26*0.3)-SUMIF('Monthly Detail'!$4:$4, '2025 Overview (Rolling)'!J$11, 'Monthly Detail'!75:75) -> 1699.875 | K34: =+J34+(K26*0.3)-SUMIF('Monthly Detail'!$4:$4, '2025 Overview (Rolling)'!K$11, 'Monthly Detail'!75:75) -> 4163.943 | ... N34: =+M34+(N26*0.3)-SUMIF('Monthly Detail'!$4:$4, '2025 Overview (Rolling)'!N$11, 'Monthly Detail'!75:75) -> 5705.8921 | P34: =+N34 -> 5705.8921
B36: Operating Cash | C36: =SUMIF('Monthly Detail'!$4:$4, '2025 Overview (Rolling)'!C$11, 'Monthly Detail'!172:172) -> 3823.59 | D36: =SUMIF('Monthly Detail'!$4:$4, '2025 Overview (Rolling)'!D$11, 'Monthly Detail'!172:172) -> 494.25 | E36: =SUMIF('Monthly Detail'!$4:$4, '2025 Overview (Rolling)'!E$11, 'Monthly Detail'!172:172) -> 985.19 | F36: =SUMIF('Monthly Detail'!$4:$4, '2025 Overview (Rolling)'!F$11, 'Monthly Detail'!172:172) -> 1331.53 | G36: =SUMIF('Monthly Detail'!$4:$4, '2025 Overview (Rolling)'!G$11, 'Monthly Detail'!172:172) -> 557.08 | H36: =SUMIF('Monthly Detail'!$4:$4, '2025 Overview (Rolling)'!H$11, 'Monthly Detail'!172:172) -> 1059.5 | I36: =SUMIF('Monthly Detail'!$4:$4, '2025 Overview (Rolling)'!I$11, 'Monthly Detail'!172:172) -> 3158.83 | J36: =SUMIF('Monthly Detail'!$4:$4, '2025 Overview (Rolling)'!J$11, 'Monthly Detail'!172:172) -> 3999.47 | ... N36: =SUMIF('Monthly Detail'!$4:$4, '2025 Overview (Rolling)'!N$11, 'Monthly Detail'!172:172) -> 26701.564
B37: Cash Inflow (Outflow) | C37: =SUMIF('Monthly Detail'!$4:$4, '2025 Overview (Rolling)'!C$11, 'Monthly Detail'!169:169) -> 3530.76 | D37: =SUMIF('Monthly Detail'!$4:$4, '2025 Overview (Rolling)'!D$11, 'Monthly Detail'!169:169) -> -3329.34 | E37: =SUMIF('Monthly Detail'!$4:$4, '2025 Overview (Rolling)'!E$11, 'Monthly Detail'!169:169) -> 490.94 | F37: =SUMIF('Monthly Detail'!$4:$4, '2025 Overview (Rolling)'!F$11, 'Monthly Detail'!169:169) -> 346.34 | G37: =SUMIF('Monthly Detail'!$4:$4, '2025 Overview (Rolling)'!G$11, 'Monthly Detail'!169:169) -> -774.45 | H37: =SUMIF('Monthly Detail'!$4:$4, '2025 Overview (Rolling)'!H$11, 'Monthly Detail'!169:169) -> 502.42 | I37: =SUMIF('Monthly Detail'!$4:$4, '2025 Overview (Rolling)'!I$11, 'Monthly Detail'!169:169) -> 2099.33 | J37: =SUMIF('Monthly Detail'!$4:$4, '2025 Overview (Rolling)'!J$11, 'Monthly Detail'!169:169) -> 840.64 | ... N37: =SUMIF('Monthly Detail'!$4:$4, '2025 Overview (Rolling)'!N$11, 'Monthly Detail'!169:169) -> 935.93232

Sheet 2025 Overview (Budget)
B8: 2025 Overview (Annual Operating Plan)
C10: =TEXT('Monthly Detail'!D4,"mmmm") -> January | D10: =TEXT('Monthly Detail'!E4,"mmmm") -> February | E10: =TEXT('Monthly Detail'!F4,"mmmm") -> March | F10: =TEXT('Monthly Detail'!G4,"mmmm") -> April | G10: =TEXT('Monthly Detail'!H4,"mmmm") -> May | H10: =TEXT('Monthly Detail'!I4,"mmmm") -> June | I10: =TEXT('Monthly Detail'!J4,"mmmm") -> July | J10: =TEXT('Monthly Detail'!K4,"mmmm") -> August | ... N10: =TEXT('Monthly Detail'!O4,"mmmm") -> December | P10: Total
C11: 45688 | D11: 45716 | E11: 45747 | F11: 45777 | G11: 45808 | H11: 45838 | I11: 45869 | J11: 45900 | K11: 45930 | L11: 45961 | M11: 45991 | N11: 46022 | O11: 45322
B12: Service Income | C12: =+'2025 Overview (Rolling)'!C12 -> 6477.5 | D12: =+'2025 Overview (Rolling)'!D12 -> 8052.5 | E12: =+'2025 Overview (Rolling)'!E12 -> 7630 | F12: =+'2025 Overview (Rolling)'!F12 -> 3756.25 | G12: =+'2025 Overview (Rolling)'!G12 -> 6032.5 | H12: =+'2025 Overview (Rolling)'!H12 -> 6822.5 | I12: =+'2025 Overview (Rolling)'!I12 -> 14855 | J12: =+'2025 Overview (Rolling)'!J12 -> 20412.5 | ... L12: =+'2025 Overview (Rolling)'!L12 -> 39333.76 | M12: =+'2025 AOP'!M12 -> 8797.317 | N12: =+'2025 AOP'!N12 -> 6287.4785 | P12: =SUM(C12:O12) -> 156714.81
B13: Tips | C13: =+'2025 Overview (Rolling)'!C13 -> 108 | D13: =+'2025 Overview (Rolling)'!D13 -> 59.62 | E13: =+'2025 Overview (Rolling)'!E13 -> 52.37 | F13: =+'2025 Overview (Rolling)'!F13 -> 0 | G13: =+'2025 Overview (Rolling)'!G13 -> 12 | H13: =+'2025 Overview (Rolling)'!H13 -> 93.5 | I13: =+'2025 Overview (Rolling)'!I13 -> 75 | J13: =+'2025 Overview (Rolling)'!J13 -> 44.5 | ... L13: =+'2025 Overview (Rolling)'!L13 -> 29.37 | M13: =+'2025 AOP'!M13 -> 15.950161 | N13: =+'2025 AOP'!N13 -> 11.399646 | P13: =+SUM(C13:N13) -> 551.70981
B14: Total Income | C14: =+'2025 Overview (Rolling)'!C14 -> 6585.5 | D14: =+'2025 Overview (Rolling)'!D14 -> 8112.12 | E14: =+'2025 Overview (Rolling)'!E14 -> 7682.37 | F14: =+'2025 Overview (Rolling)'!F14 -> 3756.25 | G14: =+'2025 Overview (Rolling)'!G14 -> 6044.5 | H14: =+'2025 Overview (Rolling)'!H14 -> 6916 | I14: =+'2025 Overview (Rolling)'!I14 -> 14930 | J14: =+'2025 Overview (Rolling)'!J14 -> 20457 | ... L14: =+'2025 Overview (Rolling)'!L14 -> 39363.13 | M14: =SUM(M12:M13) -> 8813.2671 | N14: =SUM(N12:N13) -> 6298.8782 | P14: =SUM(P12:P13) -> 157266.52
B15: # of Students | C15: =+'2025 Overview (Rolling)'!C15 -> 24 | D15: =+'2025 Overview (Rolling)'!D15 -> 28 | E15: =+'2025 Overview (Rolling)'!E15 -> 24 | F15: =+'2025 Overview (Rolling)'!F15 -> 23 | G15: =+'2025 Overview (Rolling)'!G15 -> 20 | H15: =+'2025 Overview (Rolling)'!H15 -> 25 | I15: =+'2025 Overview (Rolling)'!I15 -> 35 | J15: =+'2025 Overview (Rolling)'!J15 -> 48 | ... L15: =+'2025 Overview (Rolling)'!L15 -> 67 | M15: =+'2025 AOP'!M15 -> 43.6 | N15: =+'2025 AOP'!N15 -> 42.2
B17: Subcontractor Expenses | C17: =+'2025 Overview (Rolling)'!C18 -> 0 | D17: =+'2025 Overview (Rolling)'!D18 -> 450 | E17: =+'2025 Overview (Rolling)'!E18 -> 0 | F17: =+'2025 Overview (Rolling)'!F18 -> 0 | G17: =+'2025 Overview (Rolling)'!G18 -> 270 | H17: =+'2025 Overview (Rolling)'!H18 -> 0 | I17: =+'2025 Overview (Rolling)'!I18 -> 1582.5 | J17: =+'2025 Overview (Rolling)'!J18 -> 684 | ... L17: =+'2025 Overview (Rolling)'!L18 -> 6255 | M17: =+'2025 AOP'!M18 -> 524 | N17: =+'2025 AOP'!N18 -> 0 | P17: =SUM(C17:O17) -> 13842.24
B18: Gross Margin | C18: =+'2025 Overview (Rolling)'!C19 -> 6585.5 | D18: =+'2025 Overview (Rolling)'!D19 -> 7662.12 | E18: =+'2025 Overview (Rolling)'!E19 -> 7682.37 | F18: =+'2025 Overview (Rolling)'!F19 -> 3756.25 | G18: =+'2025 Overview (Rolling)'!G19 -> 5774.5 | H18: =+'2025 Overview (Rolling)'!H19 -> 6916 | I18: =+'2025 Overview (Rolling)'!I19 -> 13347.5 | J18: =+'2025 Overview (Rolling)'!J19 -> 19773 | ... L18: =+'2025 Overview (Rolling)'!L19 -> 33108.13 | M18: =M14-M17 -> 8289.2671 | N18: =N14-N17 -> 6298.8782 | P18: =P14-P17 -> 143424.28
B19: GM % | C19: =+'2025 Overview (Rolling)'!C20 -> 1 | D19: =+'2025 Overview (Rolling)'!D20 -> 0.94452745 | E19: =+'2025 Overview (Rolling)'!E20 -> 1 | F19: =+'2025 Overview (Rolling)'!F20 -> 1 | G19: =+'2025 Overview (Rolling)'!G20 -> 0.95533129 | H19: =+'2025 Overview (Rolling)'!H20 -> 1 | I19: =+'2025 Overview (Rolling)'!I20 -> 0.89400536 | J19: =+'2025 Overview (Rolling)'!J20 -> 0.96656401 | ... L19: =+'2025 Overview (Rolling)'!L20 -> 0.84109495 | M19: =M18/M14 -> 0.94054418 | N19: =N18/N14 -> 1 | P19: =P18/P14 -> 0.91198228
B21: Sales & Marketing Expenses | C21: =+'2025 Overview (Rolling)'!C22 -> 0 | D21: =+'2025 Overview (Rolling)'!D22 -> 0 | E21: =+'2025 Overview (Rolling)'!E22 -> 0 | F21: =+'2025 Overview (Rolling)'!F22 -> 0 | G21: =+'2025 Overview (Rolling)'!G22 -> 0 | H21: =+'2025 Overview (Rolling)'!H22 -> 0 | I21: =+'2025 Overview (Rolling)'!I22 -> 0 | J21: =+'2025 Overview (Rolling)'!J22 -> 0 | ... L21: =+'2025 Overview (Rolling)'!L22 -> 0 | M21: =+'2025 AOP'!M22 -> 0 | N21: =+'2025 AOP'!N22 -> 0 | P21: =SUM(C21:O21) -> 0
B22: General & Admintrative Expenses | C22: =+'2025 Overview (Rolling)'!C23 -> 4230.3 | D22: =+'2025 Overview (Rolling)'!D23 -> 6699.3 | E22: =+'2025 Overview (Rolling)'!E23 -> 7438.99 | F22: =+'2025 Overview (Rolling)'!F23 -> 3780.99 | G22: =+'2025 Overview (Rolling)'!G23 -> 3678.36 | H22: =+'2025 Overview (Rolling)'!H23 -> 4152.38 | I22: =+'2025 Overview (Rolling)'!I23 -> 9510.39 | J22: =+'2025 Overview (Rolling)'!J23 -> 17648.04 | ... L22: =+'2025 Overview (Rolling)'!L23 -> 18946.23 | M22: =+'2025 AOP'!M23 -> 1340.2174 | N22: =+'2025 AOP'!N23 -> 1635.3956 | P22: =SUM(C22:O22) -> 92578.793
B23: Operating Expenses | C23: =+'2025 Overview (Rolling)'!C24 -> 4230.3 | D23: =+'2025 Overview (Rolling)'!D24 -> 6699.3 | E23: =+'2025 Overview (Rolling)'!E24 -> 7438.99 | F23: =+'2025 Overview (Rolling)'!F24 -> 3780.99 | G23: =+'2025 Overview (Rolling)'!G24 -> 3678.36 | H23: =+'2025 Overview (Rolling)'!H24 -> 4152.38 | I23: =+'2025 Overview (Rolling)'!I24 -> 9510.39 | J23: =+'2025 Overview (Rolling)'!J24 -> 17648.04 | ... L23: =+'2025 Overview (Rolling)'!L24 -> 18946.23 | M23: =SUM(M21:M22) -> 1340.2174 | N23: =SUM(N21:N22) -> 1635.3956 | P23: =SUM(P21:P22) -> 92578.793
B25: Net Operating Income (EBITDA) | C25: =+'2025 Overview (Rolling)'!C26 -> 2355.2 | D25: =+'2025 Overview (Rolling)'!D26 -> 962.82 | E25: =+'2025 Overview (Rolling)'!E26 -> 243.38 | F25: =+'2025 Overview (Rolling)'!F26 -> -24.74 | G25: =+'2025 Overview (Rolling)'!G26 -> 2096.14 | H25: =+'2025 Overview (Rolling)'!H26 -> 2763.62 | I25: =+'2025 Overview (Rolling)'!I26 -> 3837.11 | J25: =+'2025 Overview (Rolling)'!J26 -> 2124.96 | ... L25: =+'2025 Overview (Rolling)'!L26 -> 14161.9 | M25: =M18-M23 -> 6949.0498 | N25: =N18-N23 -> 4663.4826 | P25: =P18-P23 -> 50845.482
B26: EBITDA % | C26: =+'2025 Overview (Rolling)'!C27 -> 0.3576342 | D26: =+'2025 Overview (Rolling)'!D27 -> 0.11868907 | E26: =+'2025 Overview (Rolling)'!E27 -> 0.031680328 | F26: =+'2025 Overview (Rolling)'!F27 -> -0.0065863561 | G26: =+'2025 Overview (Rolling)'!G27 -> 0.34678468 | H26: =+'2025 Overview (Rolling)'!H27 -> 0.39959803 | I26: =+'2025 Overview (Rolling)'!I27 -> 0.2570067 | J26: =+'2025 Overview (Rolling)'!J27 -> 0.10387447 | ... L26: =+'2025 Overview (Rolling)'!L27 -> 0.35977576 | M26: =M25/M14 -> 0.78847601 | N26: =N25/N14 -> 0.74036716 | P26: =P25/P14 -> 0.32330774
B28: Other Income / (Expense) | C28: =+'2025 Overview (Rolling)'!C29 -> -821.84 | D28: =+'2025 Overview (Rolling)'!D29 -> -775.57 | E28: =+'2025 Overview (Rolling)'!E29 -> -757.92 | F28: =+'2025 Overview (Rolling)'!F29 -> -757.92 | G28: =+'2025 Overview (Rolling)'!G29 -> -692.87 | H28: =+'2025 Overview (Rolling)'!H29 -> -769.02 | I28: =+'2025 Overview (Rolling)'!I29 -> -775.25 | J28: =+'2025 Overview (Rolling)'!J29 -> -727.32 | ... L28: =+'2025 Overview (Rolling)'!L29 -> -842.23 | M28: =+'2025 AOP'!M29 -> -800 | N28: =+'2025 AOP'!N29 -> -800 | P28: =SUM(C28:O28) -> -9246.3
B29: Net Income | C29: =+'2025 Overview (Rolling)'!C30 -> 1533.36 | D29: =+'2025 Overview (Rolling)'!D30 -> 187.25 | E29: =+'2025 Overview (Rolling)'!E30 -> -514.54 | F29: =+'2025 Overview (Rolling)'!F30 -> -782.66 | G29: =+'2025 Overview (Rolling)'!G30 -> 1403.27 | H29: =+'2025 Overview (Rolling)'!H30 -> 1994.6 | I29: =+'2025 Overview (Rolling)'!I30 -> 3061.86 | J29: =+'2025 Overview (Rolling)'!J30 -> 1397.64 | ... L29: =+'2025 Overview (Rolling)'!L30 -> 13319.67 | M29: =M25+SUM(M28:M28) -> 6149.0498 | N29: =N25+SUM(N28:N28) -> 3863.4826 | P29: =P25+SUM(P28:P28) -> 41599.182
B30: NI % | C30: =+'2025 Overview (Rolling)'!C31 -> 0.23283881 | D30: =+'2025 Overview (Rolling)'!D31 -> 0.023082745 | E30: =+'2025 Overview (Rolling)'!E31 -> -0.066976727 | F30: =+'2025 Overview (Rolling)'!F31 -> -0.20836206 | G30: =+'2025 Overview (Rolling)'!G31 -> 0.23215651 | H30: =+'2025 Overview (Rolling)'!H31 -> 0.2884037 | I30: =+'2025 Overview (Rolling)'!I31 -> 0.20508104 | J30: =+'2025 Overview (Rolling)'!J31 -> 0.068320868 | ... L30: =+'2025 Overview (Rolling)'!L31 -> 0.33837934 | M30: =M29/M14 -> 0.69770377 | N30: =N29/N14 -> 0.61336042 | P30: =P29/P14 -> 0.26451392
B32: Operating Cash | C32: =+'2025 Overview (Rolling)'!C36 -> 3823.59 | D32: =+'2025 Overview (Rolling)'!D36 -> 494.25 | E32: =+'2025 Overview (Rolling)'!E36 -> 985.19 | F32: =+'2025 Overview (Rolling)'!F36 -> 1331.53 | G32: =+'2025 Overview (Rolling)'!G36 -> 557.08 | H32: =+'2025 Overview (Rolling)'!H36 -> 1059.5 | I32: =+'2025 Overview (Rolling)'!I36 -> 3158.83 | J32: =+'2025 Overview (Rolling)'!J36 -> 3999.47 | ... L32: =+'2025 Overview (Rolling)'!L36 -> 10262.87 | M32: =+'2024 AOP'!M31 -> 36536.59 | N32: =+'2024 AOP'!N31 -> 38730.025
B33: Cash Inflow (Outflow) | C33: =+'2025 Overview (Rolling)'!C37 -> 3530.76 | D33: =+'2025 Overview (Rolling)'!D37 -> -3329.34 | E33: =+'2025 Overview (Rolling)'!E37 -> 490.94 | F33: =+'2025 Overview (Rolling)'!F37 -> 346.34 | G33: =+'2025 Overview (Rolling)'!G37 -> -774.45 | H33: =+'2025 Overview (Rolling)'!H37 -> 502.42 | I33: =+'2025 Overview (Rolling)'!I37 -> 2099.33 | J33: =+'2025 Overview (Rolling)'!J37 -> 840.64 | ... L33: =+'2025 Overview (Rolling)'!L37 -> 4129.67 | M33: =+'2024 AOP'!M32 -> 1814.0563 | N33: =+'2024 AOP'!N32 -> 2193.4353

Sheet 2024 Overview (Rolling)
B8: 2024 Overview (Rolling Forecast)
C10: =TEXT('Monthly Detail'!D4,"mmmm") -> January | D10: =TEXT('Monthly Detail'!E4,"mmmm") -> February | E10: =TEXT('Monthly Detail'!F4,"mmmm") -> March | F10: =TEXT('Monthly Detail'!G4,"mmmm") -> April | G10: =TEXT('Monthly Detail'!H4,"mmmm") -> May | H10: =TEXT('Monthly Detail'!I4,"mmmm") -> June | I10: =TEXT('Monthly Detail'!J4,"mmmm") -> July | J10: =TEXT('Monthly Detail'!K4,"mmmm") -> August | ... N10: =TEXT('Monthly Detail'!O4,"mmmm") -> December | P10: Total
C11: 45322 | D11: 45351 | E11: 45382 | F11: 45412 | G11: 45443 | H11: 45473 | I11: 45504 | J11: 45535 | K11: 45565 | L11: 45596 | M11: 45626 | N11: 45657 | O11: 45322
B12: Service Income | C12: =SUMIF('Monthly Detail'!$4:$4, '2024 Overview (Rolling)'!C$11, 'Monthly Detail'!12:12) -> 2885 | D12: =SUMIF('Monthly Detail'!$4:$4, '2024 Overview (Rolling)'!D$11, 'Monthly Detail'!12:12) -> 4357.5 | E12: =SUMIF('Monthly Detail'!$4:$4, '2024 Overview (Rolling)'!E$11, 'Monthly Detail'!12:12) -> 3467.5 | F12: =SUMIF('Monthly Detail'!$4:$4, '2024 Overview (Rolling)'!F$11, 'Monthly Detail'!12:12) -> 4000 | G12: =SUMIF('Monthly Detail'!$4:$4, '2024 Overview (Rolling)'!G$11, 'Monthly Detail'!12:12) -> 5370 | H12: =SUMIF('Monthly Detail'!$4:$4, '2024 Overview (Rolling)'!H$11, 'Monthly Detail'!12:12) -> 4296.26 | I12: =SUMIF('Monthly Detail'!$4:$4, '2024 Overview (Rolling)'!I$11, 'Monthly Detail'!12:12) -> 9031.27 | J12: =SUMIF('Monthly Detail'!$4:$4, '2024 Overview (Rolling)'!J$11, 'Monthly Detail'!12:12) -> 14073.76 | ... N12: =SUMIF('Monthly Detail'!$4:$4, '2024 Overview (Rolling)'!N$11, 'Monthly Detail'!12:12) -> 5160 | P12: =SUM(C12:O12) -> 89488.79
B13: Tips | C13: =SUMIF('Monthly Detail'!$4:$4, '2024 Overview (Rolling)'!C$11, 'Monthly Detail'!13:13) -> 117 | D13: =SUMIF('Monthly Detail'!$4:$4, '2024 Overview (Rolling)'!D$11, 'Monthly Detail'!13:13) -> 0 | E13: =SUMIF('Monthly Detail'!$4:$4, '2024 Overview (Rolling)'!E$11, 'Monthly Detail'!13:13) -> 12 | F13: =SUMIF('Monthly Detail'!$4:$4, '2024 Overview (Rolling)'!F$11, 'Monthly Detail'!13:13) -> 18 | G13: =SUMIF('Monthly Detail'!$4:$4, '2024 Overview (Rolling)'!G$11, 'Monthly Detail'!13:13) -> 50.08 | H13: =SUMIF('Monthly Detail'!$4:$4, '2024 Overview (Rolling)'!H$11, 'Monthly Detail'!13:13) -> 12 | I13: =SUMIF('Monthly Detail'!$4:$4, '2024 Overview (Rolling)'!I$11, 'Monthly Detail'!13:13) -> 29.62 | J13: =SUMIF('Monthly Detail'!$4:$4, '2024 Overview (Rolling)'!J$11, 'Monthly Detail'!13:13) -> 37.5 | ... N13: =SUMIF('Monthly Detail'!$4:$4, '2024 Overview (Rolling)'!N$11, 'Monthly Detail'!13:13) -> 34 | P13: =+SUM(C13:N13) -> 339.45
B14: Total Income | C14: =SUM(C12:C13) -> 3002 | D14: =SUM(D12:D13) -> 4357.5 | E14: =SUM(E12:E13) -> 3479.5 | F14: =SUM(F12:F13) -> 4018 | G14: =SUM(G12:G13) -> 5420.08 | H14: =SUM(H12:H13) -> 4308.26 | I14: =SUM(I12:I13) -> 9060.89 | J14: =SUM(J12:J13) -> 14111.26 | ... N14: =SUM(N12:N13) -> 5194 | P14: =SUM(P12:P13) -> 89828.24
B15: # of Students | C15: =+'Monthly Detail'!AB17 -> 16 | D15: =+'Monthly Detail'!AC17 -> 15 | E15: =+'Monthly Detail'!AD17 -> 20 | F15: =+'Monthly Detail'!AE17 -> 17 | G15: =+'Monthly Detail'!AF17 -> 20 | H15: =+'Monthly Detail'!AG17 -> 24 | I15: =+'Monthly Detail'!AH17 -> 30 | J15: =+'Monthly Detail'!AI17 -> 38 | ... N15: =+'Monthly Detail'!AM17 -> 23
B16: # of Sessions | C16: =+'Monthly Detail'!AB22 -> 34 | D16: =+'Monthly Detail'!AC22 -> 56 | E16: =+'Monthly Detail'!AD22 -> 36 | F16: =+'Monthly Detail'!AE22 -> 49 | G16: =+'Monthly Detail'!AF22 -> 76 | H16: =+'Monthly Detail'!AG22 -> 45 | I16: =+'Monthly Detail'!AH22 -> 118 | J16: =+'Monthly Detail'!AI22 -> 169 | ... N16: =+'Monthly Detail'!AM22 -> 50
B18: Subcontractor Expenses | C18: =SUMIF('Monthly Detail'!$4:$4, '2025 Overview (Budget)'!C$11, 'Monthly Detail'!63:63) -> 0 | D18: =SUMIF('Monthly Detail'!$4:$4, '2025 Overview (Budget)'!D$11, 'Monthly Detail'!63:63) -> 450 | E18: =SUMIF('Monthly Detail'!$4:$4, '2025 Overview (Budget)'!E$11, 'Monthly Detail'!63:63) -> 0 | F18: =SUMIF('Monthly Detail'!$4:$4, '2025 Overview (Budget)'!F$11, 'Monthly Detail'!63:63) -> 0 | G18: =SUMIF('Monthly Detail'!$4:$4, '2025 Overview (Budget)'!G$11, 'Monthly Detail'!63:63) -> 270 | H18: =SUMIF('Monthly Detail'!$4:$4, '2025 Overview (Budget)'!H$11, 'Monthly Detail'!63:63) -> 0 | I18: =SUMIF('Monthly Detail'!$4:$4, '2025 Overview (Budget)'!I$11, 'Monthly Detail'!63:63) -> 1582.5 | J18: =SUMIF('Monthly Detail'!$4:$4, '2025 Overview (Budget)'!J$11, 'Monthly Detail'!63:63) -> 684 | ... N18: =SUMIF('Monthly Detail'!$4:$4, '2025 Overview (Budget)'!N$11, 'Monthly Detail'!63:63) -> 959.95423 | P18: =SUM(C18:O18) -> 14278.194
B19: Gross Margin | C19: =C14-C18 -> 3002 | D19: =D14-D18 -> 3907.5 | E19: =E14-E18 -> 3479.5 | F19: =F14-F18 -> 4018 | G19: =G14-G18 -> 5150.08 | H19: =H14-H18 -> 4308.26 | I19: =I14-I18 -> 7478.39 | J19: =J14-J18 -> 13427.26 | ... N19: =N14-N18 -> 4234.0458 | P19: =P14-P18 -> 75550.046
B20: GM % | C20: =C19/C14 -> 1 | D20: =D19/D14 -> 0.89672978 | E20: =E19/E14 -> 1 | F20: =F19/F14 -> 1 | G20: =G19/G14 -> 0.95018524 | H20: =H19/H14 -> 1 | I20: =I19/I14 -> 0.82534828 | J20: =J19/J14 -> 0.95152807 | ... N20: =N19/N14 -> 0.81518016 | P20: =P19/P14 -> 0.84105005
B22: Sales & Marketing Expenses | C22: =SUMIF('Monthly Detail'!$4:$4, '2024 Overview (Rolling)'!C$11, 'Monthly Detail'!$70:$70) -> 0 | D22: =SUMIF('Monthly Detail'!$4:$4, '2024 Overview (Rolling)'!D$11, 'Monthly Detail'!$70:$70) -> 1179.44 | E22: =SUMIF('Monthly Detail'!$4:$4, '2024 Overview (Rolling)'!E$11, 'Monthly Detail'!$70:$70) -> 0 | F22: =SUMIF('Monthly Detail'!$4:$4, '2024 Overview (Rolling)'!F$11, 'Monthly Detail'!$70:$70) -> 2400 | G22: =SUMIF('Monthly Detail'!$4:$4, '2024 Overview (Rolling)'!G$11, 'Monthly Detail'!$70:$70) -> 0 | H22: =SUMIF('Monthly Detail'!$4:$4, '2024 Overview (Rolling)'!H$11, 'Monthly Detail'!$70:$70) -> 665.56 | I22: =SUMIF('Monthly Detail'!$4:$4, '2024 Overview (Rolling)'!I$11, 'Monthly Detail'!$70:$70) -> 0 | J22: =SUMIF('Monthly Detail'!$4:$4, '2024 Overview (Rolling)'!J$11, 'Monthly Detail'!$70:$70) -> 0 | ... N22: =SUMIF('Monthly Detail'!$4:$4, '2024 Overview (Rolling)'!N$11, 'Monthly Detail'!$70:$70) -> 0 | P22: =SUM(C22:O22) -> 4245
B23: General & Admintrative Expenses | C23: =SUMIF('Monthly Detail'!$4:$4, '2024 Overview (Rolling)'!C$11, 'Monthly Detail'!$93:$93) -> 417.24 | D23: =SUMIF('Monthly Detail'!$4:$4, '2024 Overview (Rolling)'!D$11, 'Monthly Detail'!$93:$93) -> 436.02 | E23: =SUMIF('Monthly Detail'!$4:$4, '2024 Overview (Rolling)'!E$11, 'Monthly Detail'!$93:$93) -> 943.03 | F23: =SUMIF('Monthly Detail'!$4:$4, '2024 Overview (Rolling)'!F$11, 'Monthly Detail'!$93:$93) -> 382.8 | G23: =SUMIF('Monthly Detail'!$4:$4, '2024 Overview (Rolling)'!G$11, 'Monthly Detail'!$93:$93) -> 689.95 | H23: =SUMIF('Monthly Detail'!$4:$4, '2024 Overview (Rolling)'!H$11, 'Monthly Detail'!$93:$93) -> 913.86 | I23: =SUMIF('Monthly Detail'!$4:$4, '2024 Overview (Rolling)'!I$11, 'Monthly Detail'!$93:$93) -> 2146.76 | J23: =SUMIF('Monthly Detail'!$4:$4, '2024 Overview (Rolling)'!J$11, 'Monthly Detail'!$93:$93) -> 1446.32 | ... N23: =SUMIF('Monthly Detail'!$4:$4, '2024 Overview (Rolling)'!N$11, 'Monthly Detail'!$93:$93) -> 620.21 | P23: =SUM(C23:O23) -> 12495.71
B24: Operating Expenses | C24: =SUM(C23:C23) -> 417.24 | D24: =SUM(D22:D23) -> 1615.46 | E24: =SUM(E22:E23) -> 943.03 | F24: =SUM(F22:F23) -> 2782.8 | G24: =SUM(G22:G23) -> 689.95 | H24: =SUM(H22:H23) -> 1579.42 | I24: =SUM(I22:I23) -> 2146.76 | J24: =SUM(J22:J23) -> 1446.32 | K24: =SUM(K22:K23) -> 878.64 | ... N24: =SUM(N22:N23) -> 620.21 | P24: =SUM(P22:P23) -> 16740.71
B26: Net Operating Income (EBITDA) | C26: =C19-C24 -> 2584.76 | D26: =D19-D24 -> 2292.04 | E26: =E19-E24 -> 2536.47 | F26: =F19-F24 -> 1235.2 | G26: =G19-G24 -> 4460.13 | H26: =H19-H24 -> 2728.84 | I26: =I19-I24 -> 5331.63 | J26: =J19-J24 -> 11980.94 | ... N26: =N19-N24 -> 3613.8358 | P26: =P19-P24 -> 58809.336
B27: EBITDA % | C27: =C26/C14 -> 0.86101266 | D27: =D26/D14 -> 0.52599885 | E27: =E26/E14 -> 0.72897543 | F27: =F26/F14 -> 0.30741663 | G27: =G26/G14 -> 0.82289007 | H27: =H26/H14 -> 0.63339724 | I27: =I26/I14 -> 0.58842233 | J27: =J26/J14 -> 0.84903403 | ... N27: =N26/N14 -> 0.69577123 | P27: =P26/P14 -> 0.6546865
B29: Other Income / (Expense) | C29: =SUMIF('Monthly Detail'!$4:$4, '2024 Overview (Rolling)'!C$11, 'Monthly Detail'!107:107) -> 0 | D29: =SUMIF('Monthly Detail'!$4:$4, '2024 Overview (Rolling)'!D$11, 'Monthly Detail'!107:107) -> 0 | E29: =SUMIF('Monthly Detail'!$4:$4, '2024 Overview (Rolling)'!E$11, 'Monthly Detail'!107:107) -> 0 | F29: =SUMIF('Monthly Detail'!$4:$4, '2024 Overview (Rolling)'!F$11, 'Monthly Detail'!107:107) -> 0 | G29: =SUMIF('Monthly Detail'!$4:$4, '2024 Overview (Rolling)'!G$11, 'Monthly Detail'!107:107) -> 0 | H29: =SUMIF('Monthly Detail'!$4:$4, '2024 Overview (Rolling)'!H$11, 'Monthly Detail'!107:107) -> -690.26 | I29: =SUMIF('Monthly Detail'!$4:$4, '2024 Overview (Rolling)'!I$11, 'Monthly Detail'!107:107) -> -715.26 | J29: =SUMIF('Monthly Detail'!$4:$4, '2024 Overview (Rolling)'!J$11, 'Monthly Detail'!107:107) -> -639.19 | ... N29: =SUMIF('Monthly Detail'!$4:$4, '2024 Overview (Rolling)'!N$11, 'Monthly Detail'!107:107) -> -790.04 | P29: =SUM(C29:O29) -> -5018.23
B30: Net Income | C30: =C26+SUM(C29:C29) -> 2584.76 | D30: =D26+SUM(D29:D29) -> 2292.04 | E30: =E26+SUM(E29:E29) -> 2536.47 | F30: =F26+SUM(F29:F29) -> 1235.2 | G30: =G26+SUM(G29:G29) -> 4460.13 | H30: =H26+SUM(H29:H29) -> 2038.58 | I30: =I26+SUM(I29:I29) -> 4616.37 | J30: =J26+SUM(J29:J29) -> 11341.75 | ... N30: =N26+SUM(N29:N29) -> 2823.7958 | P30: =P26+SUM(P29:P29) -> 53791.106
