Workbook

Sheet 1

Sheet Annual Summary
D17: 2023 | E17: =+D17+1 | F17: =+E17+1 | G17: =+F17+1 | H17: =+G17+1 | I17: =+H17+1 | J17: =+I17+1 | K17: =+J17+1
C19: Service Income | D19: =SUMIF('Monthly Detail'!$1:$1,'Annual Summary'!D$17, 'Monthly Detail'!9:9) | E19: =SUMIF('Monthly Detail'!$1:$1,'Annual Summary'!E$17, 'Monthly Detail'!9:9) | F19: =SUMIF('Monthly Detail'!$1:$1,'Annual Summary'!F$17, 'Monthly Detail'!9:9) | G19: =SUMIF('Monthly Detail'!$1:$1,'Annual Summary'!G$17, 'Monthly Detail'!9:9) | H19: =SUMIF('Monthly Detail'!$1:$1,'Annual Summary'!H$17, 'Monthly Detail'!9:9) | I19: =SUMIF('Monthly Detail'!$1:$1,'Annual Summary'!I$17, 'Monthly Detail'!9:9) | J19: =SUMIF('Monthly Detail'!$1:$1,'Annual Summary'!J$17, 'Monthly Detail'!9:9) | K19: =SUMIF('Monthly Detail'!$1:$1,'Annual Summary'!K$17, 'Monthly Detail'!9:9)
C20: Misc | D20: =SUMIF('Monthly Detail'!$1:$1,'Annual Summary'!D$17, 'Monthly Detail'!12:12) | E20: =SUMIF('Monthly Detail'!$1:$1,'Annual Summary'!E$17, 'Monthly Detail'!12:12) | F20: =SUMIF('Monthly Detail'!$1:$1,'Annual Summary'!F$17, 'Monthly Detail'!12:12) | G20: =SUMIF('Monthly Detail'!$1:$1,'Annual Summary'!G$17, 'Monthly Detail'!12:12) | H20: =SUMIF('Monthly Detail'!$1:$1,'Annual Summary'!H$17, 'Monthly Detail'!12:12) | I20: =SUMIF('Monthly Detail'!$1:$1,'Annual Summary'!I$17, 'Monthly Detail'!12:12) | J20: =SUMIF('Monthly Detail'!$1:$1,'Annual Summary'!J$17, 'Monthly Detail'!12:12) | K20: =SUMIF('Monthly Detail'!$1:$1,'Annual Summary'!K$17, 'Monthly Detail'!12:12)
C21: Total Income | D21: =SUM(D19:D20) | E21: =SUM(E19:E20) | F21: =SUM(F19:F20) | G21: =SUM(G19:G20) | H21: =SUM(H19:H20) | I21: =SUM(I19:I20) | J21: =SUM(J19:J20) | K21: =SUM(K19:K20)
C22: # of Appointments | D22: =SUMIF('Monthly Detail'!$1:$1,'Annual Summary'!D$17, 'Monthly Detail'!15:15) | E22: =SUMIF('Monthly Detail'!$1:$1,'Annual Summary'!E$17, 'Monthly Detail'!15:15) | F22: =SUMIF('Monthly Detail'!$1:$1,'Annual Summary'!F$17, 'Monthly Detail'!15:15) | G22: =SUMIF('Monthly Detail'!$1:$1,'Annual Summary'!G$17, 'Monthly Detail'!15:15) | H22: =SUMIF('Monthly Detail'!$1:$1,'Annual Summary'!H$17, 'Monthly Detail'!15:15) | I22: =SUMIF('Monthly Detail'!$1:$1,'Annual Summary'!I$17, 'Monthly Detail'!15:15) | J22: =SUMIF('Monthly Detail'!$1:$1,'Annual Summary'!J$17, 'Monthly Detail'!15:15) | K22: =SUMIF('Monthly Detail'!$1:$1,'Annual Summary'!K$17, 'Monthly Detail'!15:15)
C23: MRR | D23: =AVERAGEIF('Monthly Detail'!$1:$1,'Annual Summary'!D$17, 'Monthly Detail'!41:41) | E23: =AVERAGEIF('Monthly Detail'!$1:$1,'Annual Summary'!E$17, 'Monthly Detail'!41:41) | F23: =AVERAGEIF('Monthly Detail'!$1:$1,'Annual Summary'!F$17, 'Monthly Detail'!41:41) | G23: =AVERAGEIF('Monthly Detail'!$1:$1,'Annual Summary'!G$17, 'Monthly Detail'!41:41) | H23: =AVERAGEIF('Monthly Detail'!$1:$1,'Annual Summary'!H$17, 'Monthly Detail'!41:41) | I23: =AVERAGEIF('Monthly Detail'!$1:$1,'Annual Summary'!I$17, 'Monthly Detail'!41:41) | J23: =AVERAGEIF('Monthly Detail'!$1:$1,'Annual Summary'!J$17, 'Monthly Detail'!41:41) | K23: =AVERAGEIF('Monthly Detail'!$1:$1,'Annual Summary'!K$17, 'Monthly Detail'!41:41)
C24: Recurring Client Base | D24: =AVERAGEIF('Monthly Detail'!$1:$1,'Annual Summary'!D$17, 'Monthly Detail'!17:17) | E24: =AVERAGEIF('Monthly Detail'!$1:$1,'Annual Summary'!E$17, 'Monthly Detail'!17:17) | F24: =AVERAGEIF('Monthly Detail'!$1:$1,'Annual Summary'!F$17, 'Monthly Detail'!17:17) | G24: =AVERAGEIF('Monthly Detail'!$1:$1,'Annual Summary'!G$17, 'Monthly Detail'!17:17) | H24: =AVERAGEIF('Monthly Detail'!$1:$1,'Annual Summary'!H$17, 'Monthly Detail'!17:17) | I24: =AVERAGEIF('Monthly Detail'!$1:$1,'Annual Summary'!I$17, 'Monthly Detail'!17:17) | J24: =AVERAGEIF('Monthly Detail'!$1:$1,'Annual Summary'!J$17, 'Monthly Detail'!17:17) | K24: =AVERAGEIF('Monthly Detail'!$1:$1,'Annual Summary'!K$17, 'Monthly Detail'!17:17)
C25: YOY Compounded Growth % | E25: - | F25: =(F21/E21)-1 | G25: =(G21/F21)-1 | H25: =(H21/G21)-1 | I25: =(I21/H21)-1 | J25: =(J21/I21)-1 | K25: =(K21/J21)-1
C27: Materials - COGS | D27: =SUMIF('Monthly Detail'!$1:$1,'Annual Summary'!D$17, 'Monthly Detail'!58:58) | E27: =SUMIF('Monthly Detail'!$1:$1,'Annual Summary'!E$17, 'Monthly Detail'!58:58) | F27: =SUMIF('Monthly Detail'!$1:$1,'Annual Summary'!F$17, 'Monthly Detail'!58:58) | G27: =SUMIF('Monthly Detail'!$1:$1,'Annual Summary'!G$17, 'Monthly Detail'!58:58) | H27: =SUMIF('Monthly Detail'!$1:$1,'Annual Summary'!H$17, 'Monthly Detail'!58:58) | I27: =SUMIF('Monthly Detail'!$1:$1,'Annual Summary'!I$17, 'Monthly Detail'!58:58) | J27: =SUMIF('Monthly Detail'!$1:$1,'Annual Summary'!J$17, 'Monthly Detail'!58:58) | K27: =SUMIF('Monthly Detail'!$1:$1,'Annual Summary'!K$17, 'Monthly Detail'!58:58)
C28: Software - COS | D28: =SUMIF('Monthly Detail'!$1:$1,'Annual Summary'!D$17, 'Monthly Detail'!59:59) | E28: =SUMIF('Monthly Detail'!$1:$1,'Annual Summary'!E$17, 'Monthly Detail'!59:59) | F28: =SUMIF('Monthly Detail'!$1:$1,'Annual Summary'!F$17, 'Monthly Detail'!59:59) | G28: =SUMIF('Monthly Detail'!$1:$1,'Annual Summary'!G$17, 'Monthly Detail'!59:59) | H28: =SUMIF('Monthly Detail'!$1:$1,'Annual Summary'!H$17, 'Monthly Detail'!59:59) | I28: =SUMIF('Monthly Detail'!$1:$1,'Annual Summary'!I$17, 'Monthly Detail'!59:59) | J28: =SUMIF('Monthly Detail'!$1:$1,'Annual Summary'!J$17, 'Monthly Detail'!59:59) | K28: =SUMIF('Monthly Detail'!$1:$1,'Annual Summary'!K$17, 'Monthly Detail'!59:59)
C29: Contractors - COS | D29: =SUMIF('Monthly Detail'!$1:$1,'Annual Summary'!D$17, 'Monthly Detail'!60:60) | E29: =SUMIF('Monthly Detail'!$1:$1,'Annual Summary'!E$17, 'Monthly Detail'!60:60) | F29: =SUMIF('Monthly Detail'!$1:$1,'Annual Summary'!F$17, 'Monthly Detail'!60:60) | G29: =SUMIF('Monthly Detail'!$1:$1,'Annual Summary'!G$17, 'Monthly Detail'!60:60) | H29: =SUMIF('Monthly Detail'!$1:$1,'Annual Summary'!H$17, 'Monthly Detail'!60:60) | I29: =SUMIF('Monthly Detail'!$1:$1,'Annual Summary'!I$17, 'Monthly Detail'!60:60) | J29: =SUMIF('Monthly Detail'!$1:$1,'Annual Summary'!J$17, 'Monthly Detail'!60:60) | K29: =SUMIF('Monthly Detail'!$1:$1,'Annual Summary'!K$17, 'Monthly Detail'!60:60)
C30: Total Cost of Goods Sold (COGS) | D30: =SUM(D27:D29) | E30: =SUM(E27:E29) | F30: =SUM(F27:F29) | G30: =SUM(G27:G29) | H30: =SUM(H27:H29) | I30: =SUM(I27:I29) | J30: =SUM(J27:J29) | K30: =SUM(K27:K29)
C32: Gross Margin | D32: =D21-D30 | E32: =E21-E30 | F32: =F21-F30 | G32: =G21-G30 | H32: =H21-H30 | I32: =I21-I30 | J32: =J21-J30 | K32: =K21-K30
C33: GM % | D33: =+D32/D21 | E33: =+E32/E21 | F33: =+F32/F21 | G33: =+G32/G21 | H33: =+H32/H21 | I33: =+I32/I21 | J33: =+J32/J21 | K33: =+K32/K21
C35: General & Admintrative Expenses | D35: =SUMIF('Monthly Detail'!$1:$1,'Annual Summary'!D$17, 'Monthly Detail'!$89:$89) | E35: =SUMIF('Monthly Detail'!$1:$1,'Annual Summary'!E$17, 'Monthly Detail'!$89:$89)+SUMIF('Monthly Detail'!$1:$1,'Annual Summary'!E$17, 'Monthly Detail'!$90:$90) | F35: =SUMIF('Monthly Detail'!$1:$1,'Annual Summary'!F$17, 'Monthly Detail'!$89:$89)+SUMIF('Monthly Detail'!$1:$1,'Annual Summary'!F$17, 'Monthly Detail'!$90:$90) | G35: =SUMIF('Monthly Detail'!$1:$1,'Annual Summary'!G$17, 'Monthly Detail'!$89:$89)+SUMIF('Monthly Detail'!$1:$1,'Annual Summary'!G$17, 'Monthly Detail'!$90:$90) | H35: =SUMIF('Monthly Detail'!$1:$1,'Annual Summary'!H$17, 'Monthly Detail'!$89:$89)+SUMIF('Monthly Detail'!$1:$1,'Annual Summary'!H$17, 'Monthly Detail'!$90:$90) | I35: =SUMIF('Monthly Detail'!$1:$1,'Annual Summary'!I$17, 'Monthly Detail'!$89:$89)+SUMIF('Monthly Detail'!$1:$1,'Annual Summary'!I$17, 'Monthly Detail'!$90:$90) | J35: =SUMIF('Monthly Detail'!$1:$1,'Annual Summary'!J$17, 'Monthly Detail'!$89:$89) | K35: =SUMIF('Monthly Detail'!$1:$1,'Annual Summary'!K$17, 'Monthly Detail'!$89:$89)
C36: Operating Expense | D36: =SUM(D35:D35) | E36: =SUM(E35:E35) | F36: =SUM(F35:F35) | G36: =SUM(G35:G35) | H36: =SUM(H35:H35) | I36: =SUM(I35:I35) | J36: =SUM(J35:J35) | K36: =SUM(K35:K35)
C38: Net Operating Income (EBITDA) | D38: =D32-D36 | E38: =E32-E36 | F38: =F32-F36 | G38: =G32-G36 | H38: =H32-H36 | I38: =I32-I36 | J38: =J32-J36 | K38: =K32-K36
C39: EBITDA % | D39: =D38/D21 | E39: =E38/E21 | F39: =F38/F21 | G39: =G38/G21 | H39: =H38/H21 | I39: =I38/I21 | J39: =J38/J21 | K39: =K38/K21
C41: Other Income / (Expense) | D41: =SUMIF('Monthly Detail'!$1:$1,'Annual Summary'!D$17, 'Monthly Detail'!95:95) | E41: =SUMIF('Monthly Detail'!$1:$1,'Annual Summary'!E$17, 'Monthly Detail'!95:95) | F41: =SUMIF('Monthly Detail'!$1:$1,'Annual Summary'!F$17, 'Monthly Detail'!95:95) | G41: =SUMIF('Monthly Detail'!$1:$1,'Annual Summary'!G$17, 'Monthly Detail'!95:95) | H41: =SUMIF('Monthly Detail'!$1:$1,'Annual Summary'!H$17, 'Monthly Detail'!95:95) | I41: =SUMIF('Monthly Detail'!$1:$1,'Annual Summary'!I$17, 'Monthly Detail'!95:95) | J41: =SUMIF('Monthly Detail'!$1:$1,'Annual Summary'!J$17, 'Monthly Detail'!95:95) | K41: =SUMIF('Monthly Detail'!$1:$1,'Annual Summary'!K$17, 'Monthly Detail'!95:95)
C42: Net Income | D42: =D38+D41 | E42: =E38+E41 | F42: =F38+F41 | G42: =G38+G41 | H42: =H38+H41 | I42: =I38+I41 | J42: =J38+J41 | K42: =K38+K41
C43: NI % | D43: =D42/D21 | E43: =E42/E21 | F43: =F42/F21 | G43: =G42/G21 | H43: =H42/H21 | I43: =I42/I21 | J43: =J42/J21 | K43: =K42/K21
C44: Estimated Tax Burden | D44: =+IF(D42>0, D42*0.25, 0) | E44: =+IF(E42>0, E42*0.25, 0) | F44: =+IF(F42>0, F42*0.25, 0) | G44: =+IF(G42>0, G42*0.25, 0) | H44: =+IF(H42>0, H42*0.25, 0) | I44: =+IF(I42>0, I42*0.25, 0) | J44: =+IF(J42>0, J42*0.25, 0) | K44: =+IF(K42>0, K42*0.25, 0)
C45: Cash Balance | D45: #VALUE! | E45: =+SUMIF('Monthly Detail'!$4:$4, DATE(E17, 12, 31),'Monthly Detail'!$173:$173) | F45: =+SUMIF('Monthly Detail'!$4:$4, DATE(F17, 12, 31),'Monthly Detail'!$173:$173) | G45: =+SUMIF('Monthly Detail'!$4:$4, DATE(G17, 12, 31),'Monthly Detail'!$173:$173) | H45: =+SUMIF('Monthly Detail'!$4:$4, DATE(H17, 12, 31),'Monthly Detail'!$173:$173) | I45: =+SUMIF('Monthly Detail'!$4:$4, DATE(I17, 12, 31),'Monthly Detail'!$173:$173) | J45: =+SUMIF('Monthly Detail'!$4:$4, DATE(J17, 12, 31),'Monthly Detail'!$173:$173) | K45: =+SUMIF('Monthly Detail'!$4:$4, DATE(K17, 12, 31),'Monthly Detail'!$173:$173)

Sheet 2023 Overview
C10: =TEXT('Monthly Detail'!D4,"mmmm") | D10: =TEXT('Monthly Detail'!E4,"mmmm") | E10: =TEXT('Monthly Detail'!F4,"mmmm") | F10: =TEXT('Monthly Detail'!G4,"mmmm") | G10: =TEXT('Monthly Detail'!H4,"mmmm") | H10: =TEXT('Monthly Detail'!I4,"mmmm") | I10: =TEXT('Monthly Detail'!J4,"mmmm") | J10: =TEXT('Monthly Detail'!K4,"mmmm") | ... N10: =TEXT('Monthly Detail'!O4,"mmmm") | P10: Total
C11: 44957 | D11: 44985 | E11: 45016 | F11: 45046 | G11: 45077 | H11: 45107 | I11: 45138 | J11: 45169 | K11: 45199 | L11: 45230 | M11: 45260 | N11: 45291 | O11: 45322
B12: Service Income | C12: =SUMIF('Monthly Detail'!$4:$4, '2023 Overview'!C$11, 'Monthly Detail'!9:9) | D12: =SUMIF('Monthly Detail'!$4:$4, '2023 Overview'!D$11, 'Monthly Detail'!9:9) | E12: =SUMIF('Monthly Detail'!$4:$4, '2023 Overview'!E$11, 'Monthly Detail'!9:9) | F12: =SUMIF('Monthly Detail'!$4:$4, '2023 Overview'!F$11, 'Monthly Detail'!9:9) | G12: =SUMIF('Monthly Detail'!$4:$4, '2023 Overview'!G$11, 'Monthly Detail'!9:9) | H12: =SUMIF('Monthly Detail'!$4:$4, '2023 Overview'!H$11, 'Monthly Detail'!9:9) | I12: =SUMIF('Monthly Detail'!$4:$4, '2023 Overview'!I$11, 'Monthly Detail'!9:9) | J12: =SUMIF('Monthly Detail'!$4:$4, '2023 Overview'!J$11, 'Monthly Detail'!9:9) | ... N12: =SUMIF('Monthly Detail'!$4:$4, '2023 Overview'!N$11, 'Monthly Detail'!9:9) | P12: =SUM(C12:O12)
B13: Misc. | C13: =SUMIF('Monthly Detail'!$4:$4, '2023 Overview'!C$11, 'Monthly Detail'!12:12) | D13: =SUMIF('Monthly Detail'!$4:$4, '2023 Overview'!D$11, 'Monthly Detail'!12:12) | E13: =SUMIF('Monthly Detail'!$4:$4, '2023 Overview'!E$11, 'Monthly Detail'!12:12) | F13: =SUMIF('Monthly Detail'!$4:$4, '2023 Overview'!F$11, 'Monthly Detail'!12:12) | G13: =SUMIF('Monthly Detail'!$4:$4, '2023 Overview'!G$11, 'Monthly Detail'!12:12) | H13: =SUMIF('Monthly Detail'!$4:$4, '2023 Overview'!H$11, 'Monthly Detail'!12:12) | I13: =SUMIF('Monthly Detail'!$4:$4, '2023 Overview'!I$11, 'Monthly Detail'!12:12) | J13: =SUMIF('Monthly Detail'!$4:$4, '2023 Overview'!J$11, 'Monthly Detail'!12:12) | ... N13: =SUMIF('Monthly Detail'!$4:$4, '2023 Overview'!N$11, 'Monthly Detail'!12:12)
B14: Total Income | C14: =SUM(C12:C13) | D14: =SUM(D12:D13) | E14: =SUM(E12:E13) | F14: =SUM(F12:F13) | G14: =SUM(G12:G13) | H14: =SUM(H12:H13) | I14: =SUM(I12:I13) | J14: =SUM(J12:J13) | ... N14: =SUM(N12:N13) | P14: =SUM(P12:P12)
B16: Gross Margin | C16: =C14 | D16: =D14 | E16: =E14 | F16: =F14 | G16: =G14 | H16: =H14 | I16: =I14 | J16: =J14 | ... N16: =N14 | P16: =P14
B17: GM % | C17: =C16/C14 | D17: =D16/D14 | E17: =E16/E14 | F17: =F16/F14 | G17: =G16/G14 | H17: =H16/H14 | I17: =I16/I14 | J17: =J16/J14 | ... N17: =N16/N14 | P17: =P16/P14
B19: General & Admintrative Expenses | C19: =SUMIF('Monthly Detail'!$4:$4, '2023 Overview'!C$11, 'Monthly Detail'!$89:$89) | D19: =SUMIF('Monthly Detail'!$4:$4, '2023 Overview'!D$11, 'Monthly Detail'!$89:$89) | E19: =SUMIF('Monthly Detail'!$4:$4, '2023 Overview'!E$11, 'Monthly Detail'!$89:$89) | F19: =SUMIF('Monthly Detail'!$4:$4, '2023 Overview'!F$11, 'Monthly Detail'!$89:$89) | G19: =SUMIF('Monthly Detail'!$4:$4, '2023 Overview'!G$11, 'Monthly Detail'!$89:$89) | H19: =SUMIF('Monthly Detail'!$4:$4, '2023 Overview'!H$11, 'Monthly Detail'!$89:$89) | I19: =SUMIF('Monthly Detail'!$4:$4, '2023 Overview'!I$11, 'Monthly Detail'!$89:$89) | J19: =SUMIF('Monthly Detail'!$4:$4, '2023 Overview'!J$11, 'Monthly Detail'!$89:$89) | ... N19: =SUMIF('Monthly Detail'!$4:$4, '2023 Overview'!N$11, 'Monthly Detail'!$89:$89) | P19: =SUM(C19:O19)
B20: Operating Expenses | C20: =SUM(C19:C19) | D20: =SUM(D19:D19) | E20: =SUM(E19:E19) | F20: =SUM(F19:F19) | G20: =SUM(G19:G19) | H20: =SUM(H19:H19) | I20: =SUM(I19:I19) | J20: =SUM(J19:J19) | ... N20: =SUM(N19:N19) | P20: =SUM(P19:P19)
B22: Net Operating Income (EBITDA) | C22: =C16-C20 | D22: =D16-D20 | E22: =E16-E20 | F22: =F16-F20 | G22: =G16-G20 | H22: =H16-H20 | I22: =I16-I20 | J22: =J16-J20 | ... N22: =N16-N20 | P22: =P16-P20
B23: EBITDA % | C23: =C22/C14 | D23: =D22/D14 | E23: =E22/E14 | F23: =F22/F14 | G23: =G22/G14 | H23: =H22/H14 | I23: =I22/I14 | J23: =J22/J14 | ... N23: =N22/N14 | P23: =P22/P14
B25: Other Income / (Expense) | C25: =SUMIF('Monthly Detail'!$4:$4, '2023 Overview'!C$11, 'Monthly Detail'!95:95) | D25: =SUMIF('Monthly Detail'!$4:$4, '2023 Overview'!D$11, 'Monthly Detail'!95:95) | E25: =SUMIF('Monthly Detail'!$4:$4, '2023 Overview'!E$11, 'Monthly Detail'!95:95) | F25: =SUMIF('Monthly Detail'!$4:$4, '2023 Overview'!F$11, 'Monthly Detail'!95:95) | G25: =SUMIF('Monthly Detail'!$4:$4, '2023 Overview'!G$11, 'Monthly Detail'!95:95) | H25: =SUMIF('Monthly Detail'!$4:$4, '2023 Overview'!H$11, 'Monthly Detail'!95:95) | I25: =SUMIF('Monthly Detail'!$4:$4, '2023 Overview'!I$11, 'Monthly Detail'!95:95) | J25: =SUMIF('Monthly Detail'!$4:$4, '2023 Overview'!J$11, 'Monthly Detail'!95:95) | ... N25: =SUMIF('Monthly Detail'!$4:$4, '2023 Overview'!N$11, 'Monthly Detail'!95:95) | P25: =SUM(C25:O25)
B26: Net Income | C26: =C22+SUM(C25:C25) | D26: =D22+SUM(D25:D25) | E26: =E22+SUM(E25:E25) | F26: =F22+SUM(F25:F25) | G26: =G22+SUM(G25:G25) | H26: =H22+SUM(H25:H25) | I26: =I22+SUM(I25:I25) | J26: =J22+SUM(J25:J25) | ... N26: =N22+SUM(N25:N25) | P26: =P22+SUM(P25:P25)
B27: NI % | C27: =C26/C14 | D27: =D26/D14 | E27: =E26/E14 | F27: =F26/F14 | G27: =G26/G14 | H27: =H26/H14 | I27: =I26/I14 | J27: =J26/J14 | ... N27: =N26/N14 | P27: =P26/P14
B29: Operating Cash | C29: =SUMIF('Monthly Detail'!$4:$4, '2023 Overview'!C$11, 'Monthly Detail'!173:173) | D29: =SUMIF('Monthly Detail'!$4:$4, '2023 Overview'!D$11, 'Monthly Detail'!173:173) | E29: =SUMIF('Monthly Detail'!$4:$4, '2023 Overview'!E$11, 'Monthly Detail'!173:173) | F29: =SUMIF('Monthly Detail'!$4:$4, '2023 Overview'!F$11, 'Monthly Detail'!173:173) | G29: =SUMIF('Monthly Detail'!$4:$4, '2023 Overview'!G$11, 'Monthly Detail'!173:173) | H29: =SUMIF('Monthly Detail'!$4:$4, '2023 Overview'!H$11, 'Monthly Detail'!173:173) | I29: =SUMIF('Monthly Detail'!$4:$4, '2023 Overview'!I$11, 'Monthly Detail'!173:173) | J29: =SUMIF('Monthly Detail'!$4:$4, '2023 Overview'!J$11, 'Monthly Detail'!173:173) | ... N29: =SUMIF('Monthly Detail'!$4:$4, '2023 Overview'!N$11, 'Monthly Detail'!173:173)
B30: Cash Inflow (Outflow) | C30: =SUMIF('Monthly Detail'!$4:$4, '2023 Overview'!C$11, 'Monthly Detail'!170:170) | D30: =SUMIF('Monthly Detail'!$4:$4, '2023 Overview'!D$11, 'Monthly Detail'!170:170) | E30: =SUMIF('Monthly Detail'!$4:$4, '2023 Overview'!E$11, 'Monthly Detail'!170:170) | F30: =SUMIF('Monthly Detail'!$4:$4, '2023 Overview'!F$11, 'Monthly Detail'!170:170) | G30: =SUMIF('Monthly Detail'!$4:$4, '2023 Overview'!G$11, 'Monthly Detail'!170:170) | H30: =SUMIF('Monthly Detail'!$4:$4, '2023 Overview'!H$11, 'Monthly Detail'!170:170) | I30: =SUMIF('Monthly Detail'!$4:$4, '2023 Overview'!I$11, 'Monthly Detail'!170:170) | J30: =SUMIF('Monthly Detail'!$4:$4, '2023 Overview'!J$11, 'Monthly Detail'!170:170) | ... N30: =SUMIF('Monthly Detail'!$4:$4, '2023 Overview'!N$11, 'Monthly Detail'!170:170)

Sheet 2025 Overview (Budget)
B15: 2025 Overview (Annual Operating Plan)
C18: January | D18: February | E18: March | F18: April | G18: May | H18: June | I18: July | J18: August | K18: September | L18: October | M18: November | N18: December | P18: Total
C19: 45688 | D19: 45716 | E19: 45747 | F19: 45777 | G19: 45808 | H19: 45838 | I19: 45869 | J19: 45900 | K19: 45930 | L19: 45961 | M19: 45991 | N19: 46022 | O19: 45322
B20: Service Income | C20: =SUMIF('Monthly Detail'!$4:$4, '2025 Overview (Budget)'!C$19, 'Monthly Detail'!13:13) | D20: =SUMIF('Monthly Detail'!$4:$4, '2025 Overview (Budget)'!D$19, 'Monthly Detail'!13:13) | E20: =SUMIF('Monthly Detail'!$4:$4, '2025 Overview (Budget)'!E$19, 'Monthly Detail'!13:13) | F20: =SUMIF('Monthly Detail'!$4:$4, '2025 Overview (Budget)'!F$19, 'Monthly Detail'!13:13) | G20: =SUMIF('Monthly Detail'!$4:$4, '2025 Overview (Budget)'!G$19, 'Monthly Detail'!13:13) | H20: =SUMIF('Monthly Detail'!$4:$4, '2025 Overview (Budget)'!H$19, 'Monthly Detail'!13:13) | I20: =SUMIF('Monthly Detail'!$4:$4, '2025 Overview (Budget)'!I$19, 'Monthly Detail'!13:13) | J20: =SUMIF('Monthly Detail'!$4:$4, '2025 Overview (Budget)'!J$19, 'Monthly Detail'!13:13) | ... L20: =SUMIF('Monthly Detail'!$4:$4, '2025 Overview (Budget)'!L$19, 'Monthly Detail'!13:13) | M20: =+'2025 AOP'!M20 | N20: =+'2025 AOP'!N20 | P20: =SUM(C20:O20)
B21: Misc. | C21: =SUMIF('Monthly Detail'!$4:$4, '2025 Overview (Budget)'!C$19, 'Monthly Detail'!12:12) | D21: =SUMIF('Monthly Detail'!$4:$4, '2025 Overview (Budget)'!D$19, 'Monthly Detail'!12:12) | E21: =SUMIF('Monthly Detail'!$4:$4, '2025 Overview (Budget)'!E$19, 'Monthly Detail'!12:12) | F21: =SUMIF('Monthly Detail'!$4:$4, '2025 Overview (Budget)'!F$19, 'Monthly Detail'!12:12) | G21: =SUMIF('Monthly Detail'!$4:$4, '2025 Overview (Budget)'!G$19, 'Monthly Detail'!12:12) | H21: =SUMIF('Monthly Detail'!$4:$4, '2025 Overview (Budget)'!H$19, 'Monthly Detail'!12:12) | I21: =SUMIF('Monthly Detail'!$4:$4, '2025 Overview (Budget)'!I$19, 'Monthly Detail'!12:12) | J21: =SUMIF('Monthly Detail'!$4:$4, '2025 Overview (Budget)'!J$19, 'Monthly Detail'!12:12) | ... L21: =SUMIF('Monthly Detail'!$4:$4, '2025 Overview (Budget)'!L$19, 'Monthly Detail'!12:12) | M21: =+'2025 AOP'!M21 | N21: =+'2025 AOP'!N21 | P21: =SUM(C21:O21)
B22: Total Income | C22: =SUM(C20:C21) | D22: =SUM(D20:D21) | E22: =SUM(E20:E21) | F22: =SUM(F20:F21) | G22: =SUM(G20:G21) | H22: =SUM(H20:H21) | I22: =SUM(I20:I21) | J22: =SUM(J20:J21) | ... L22: =SUM(L20:L21) | M22: =+'2025 AOP'!M22 | N22: =+'2025 AOP'!N22 | P22: =SUM(P20:P20)
B23: # of Appointments | C23: =SUMIF('Monthly Detail'!$4:$4, '2025 Overview (Budget)'!C$19, 'Monthly Detail'!15:15) | D23: =SUMIF('Monthly Detail'!$4:$4, '2025 Overview (Budget)'!D$19, 'Monthly Detail'!15:15) | E23: =SUMIF('Monthly Detail'!$4:$4, '2025 Overview (Budget)'!E$19, 'Monthly Detail'!15:15) | F23: =SUMIF('Monthly Detail'!$4:$4, '2025 Overview (Budget)'!F$19, 'Monthly Detail'!15:15) | G23: =SUMIF('Monthly Detail'!$4:$4, '2025 Overview (Budget)'!G$19, 'Monthly Detail'!15:15) | H23: =SUMIF('Monthly Detail'!$4:$4, '2025 Overview (Budget)'!H$19, 'Monthly Detail'!15:15) | I23: =SUMIF('Monthly Detail'!$4:$4, '2025 Overview (Budget)'!I$19, 'Monthly Detail'!15:15) | J23: =SUMIF('Monthly Detail'!$4:$4, '2025 Overview (Budget)'!J$19, 'Monthly Detail'!15:15) | ... L23: =SUMIF('Monthly Detail'!$4:$4, '2025 Overview (Budget)'!L$19, 'Monthly Detail'!15:15) | M23: =+'2025 AOP'!M23 | N23: =+'2025 AOP'!N23 | P23: =+SUM(C23:N23)
B24: MRR | C24: =SUMIF('Monthly Detail'!$4:$4, '2025 Overview (Budget)'!C$19, 'Monthly Detail'!41:41) | D24: =SUMIF('Monthly Detail'!$4:$4, '2025 Overview (Budget)'!D$19, 'Monthly Detail'!41:41) | E24: =SUMIF('Monthly Detail'!$4:$4, '2025 Overview (Budget)'!E$19, 'Monthly Detail'!41:41) | F24: =SUMIF('Monthly Detail'!$4:$4, '2025 Overview (Budget)'!F$19, 'Monthly Detail'!41:41) | G24: =SUMIF('Monthly Detail'!$4:$4, '2025 Overview (Budget)'!G$19, 'Monthly Detail'!41:41) | H24: =SUMIF('Monthly Detail'!$4:$4, '2025 Overview (Budget)'!H$19, 'Monthly Detail'!41:41) | I24: =SUMIF('Monthly Detail'!$4:$4, '2025 Overview (Budget)'!I$19, 'Monthly Detail'!41:41) | J24: =SUMIF('Monthly Detail'!$4:$4, '2025 Overview (Budget)'!J$19, 'Monthly Detail'!41:41) | ... L24: =SUMIF('Monthly Detail'!$4:$4, '2025 Overview (Budget)'!L$19, 'Monthly Detail'!41:41) | M24: =+'2025 AOP'!M24 | N24: =+'2025 AOP'!N24 | P24: =+AVERAGE(C24:N24)
B25: Recurring Client Base | C25: =SUMIF('Monthly Detail'!$4:$4, '2025 Overview (Budget)'!C$19, 'Monthly Detail'!17:17) | D25: =SUMIF('Monthly Detail'!$4:$4, '2025 Overview (Budget)'!D$19, 'Monthly Detail'!17:17) | E25: =SUMIF('Monthly Detail'!$4:$4, '2025 Overview (Budget)'!E$19, 'Monthly Detail'!17:17) | F25: =SUMIF('Monthly Detail'!$4:$4, '2025 Overview (Budget)'!F$19, 'Monthly Detail'!17:17) | G25: =SUMIF('Monthly Detail'!$4:$4, '2025 Overview (Budget)'!G$19, 'Monthly Detail'!17:17) | H25: =SUMIF('Monthly Detail'!$4:$4, '2025 Overview (Budget)'!H$19, 'Monthly Detail'!17:17) | I25: =SUMIF('Monthly Detail'!$4:$4, '2025 Overview (Budget)'!I$19, 'Monthly Detail'!17:17) | J25: =SUMIF('Monthly Detail'!$4:$4, '2025 Overview (Budget)'!J$19, 'Monthly Detail'!17:17) | ... L25: =SUMIF('Monthly Detail'!$4:$4, '2025 Overview (Budget)'!L$19, 'Monthly Detail'!17:17) | M25: =+'2025 AOP'!M25 | N25: =+'2025 AOP'!N25
B28: Software - COS | C28: =SUMIF('Monthly Detail'!$4:$4, '2025 Overview (Budget)'!C$19, 'Monthly Detail'!58:58) | D28: =SUMIF('Monthly Detail'!$4:$4, '2025 Overview (Budget)'!D$19, 'Monthly Detail'!58:58) | E28: =SUMIF('Monthly Detail'!$4:$4, '2025 Overview (Budget)'!E$19, 'Monthly Detail'!58:58) | F28: =SUMIF('Monthly Detail'!$4:$4, '2025 Overview (Budget)'!F$19, 'Monthly Detail'!58:58) | G28: =SUMIF('Monthly Detail'!$4:$4, '2025 Overview (Budget)'!G$19, 'Monthly Detail'!58:58) | H28: =SUMIF('Monthly Detail'!$4:$4, '2025 Overview (Budget)'!H$19, 'Monthly Detail'!58:58) | I28: =SUMIF('Monthly Detail'!$4:$4, '2025 Overview (Budget)'!I$19, 'Monthly Detail'!58:58) | J28: =SUMIF('Monthly Detail'!$4:$4, '2025 Overview (Budget)'!J$19, 'Monthly Detail'!58:58) | ... L28: =SUMIF('Monthly Detail'!$4:$4, '2025 Overview (Budget)'!L$19, 'Monthly Detail'!58:58) | M28: =+'2025 AOP'!M28 | N28: =+'2025 AOP'!N28 | P28: =+SUM(C28:N28)
B29: Materials - COGS | C29: =SUMIF('Monthly Detail'!$4:$4, '2025 Overview (Budget)'!C$19, 'Monthly Detail'!59:59) | D29: =SUMIF('Monthly Detail'!$4:$4, '2025 Overview (Budget)'!D$19, 'Monthly Detail'!59:59) | E29: =SUMIF('Monthly Detail'!$4:$4, '2025 Overview (Budget)'!E$19, 'Monthly Detail'!59:59) | F29: =SUMIF('Monthly Detail'!$4:$4, '2025 Overview (Budget)'!F$19, 'Monthly Detail'!59:59) | G29: =SUMIF('Monthly Detail'!$4:$4, '2025 Overview (Budget)'!G$19, 'Monthly Detail'!59:59) | H29: =SUMIF('Monthly Detail'!$4:$4, '2025 Overview (Budget)'!H$19, 'Monthly Detail'!59:59) | I29: =SUMIF('Monthly Detail'!$4:$4, '2025 Overview (Budget)'!I$19, 'Monthly Detail'!59:59) | J29: =SUMIF('Monthly Detail'!$4:$4, '2025 Overview (Budget)'!J$19, 'Monthly Detail'!59:59) | ... L29: =SUMIF('Monthly Detail'!$4:$4, '2025 Overview (Budget)'!L$19, 'Monthly Detail'!59:59) | M29: =+'2025 AOP'!M29 | N29: =+'2025 AOP'!N29 | P29: =+SUM(C29:N29)
B30: Contractors - COS | C30: =SUMIF('Monthly Detail'!$4:$4, '2025 Overview (Budget)'!C$19, 'Monthly Detail'!60:60) | D30: =SUMIF('Monthly Detail'!$4:$4, '2025 Overview (Budget)'!D$19, 'Monthly Detail'!60:60) | E30: =SUMIF('Monthly Detail'!$4:$4, '2025 Overview (Budget)'!E$19, 'Monthly Detail'!60:60) | F30: =SUMIF('Monthly Detail'!$4:$4, '2025 Overview (Budget)'!F$19, 'Monthly Detail'!60:60) | G30: =SUMIF('Monthly Detail'!$4:$4, '2025 Overview (Budget)'!G$19, 'Monthly Detail'!60:60) | H30: =SUMIF('Monthly Detail'!$4:$4, '2025 Overview (Budget)'!H$19, 'Monthly Detail'!60:60) | I30: =SUMIF('Monthly Detail'!$4:$4, '2025 Overview (Budget)'!I$19, 'Monthly Detail'!60:60) | J30: =SUMIF('Monthly Detail'!$4:$4, '2025 Overview (Budget)'!J$19, 'Monthly Detail'!60:60) | ... L30: =SUMIF('Monthly Detail'!$4:$4, '2025 Overview (Budget)'!L$19, 'Monthly Detail'!60:60) | M30: =+'2025 AOP'!M30 | N30: =+'2025 AOP'!N30 | P30: =+SUM(C30:N30)
B31: Total Cost of Goods Sold (COGS) | C31: =SUM(C28:C30) | D31: =SUM(D28:D30) | E31: =SUM(E28:E30) | F31: =SUM(F28:F30) | G31: =SUM(G28:G30) | H31: =SUM(H28:H30) | I31: =SUM(I28:I30) | J31: =SUM(J28:J30) | ... N31: =SUM(N28:N30) | P31: =SUM(P28:P30)
B33: Gross Margin | C33: =+C22-C31 | D33: =+D22-D31 | E33: =+E22-E31 | F33: =+F22-F31 | G33: =+G22-G31 | H33: =+H22-H31 | I33: =+I22-I31 | J33: =+J22-J31 | ... N33: =+N22-N31 | P33: =+SUM(C33:N33)
B34: GM % | C34: =IFERROR(C33/C22, 0) | D34: =IFERROR(D33/D22, 0) | E34: =IFERROR(E33/E22, 0) | F34: =IFERROR(F33/F22, 0) | G34: =IFERROR(G33/G22, 0) | H34: =IFERROR(H33/H22, 0) | I34: =IFERROR(I33/I22, 0) | J34: =IFERROR(J33/J22, 0) | ... N34: =IFERROR(N33/N22, 0) | P34: =P33/P22
B36: General & Admintrative Expenses | C36: =SUMIF('Monthly Detail'!$4:$4, '2025 Overview (Budget)'!C$19, 'Monthly Detail'!$89:$89) | D36: =SUMIF('Monthly Detail'!$4:$4, '2025 Overview (Budget)'!D$19, 'Monthly Detail'!$89:$89) | E36: =SUMIF('Monthly Detail'!$4:$4, '2025 Overview (Budget)'!E$19, 'Monthly Detail'!$89:$89) | F36: =SUMIF('Monthly Detail'!$4:$4, '2025 Overview (Budget)'!F$19, 'Monthly Detail'!$89:$89) | G36: =SUMIF('Monthly Detail'!$4:$4, '2025 Overview (Budget)'!G$19, 'Monthly Detail'!$89:$89) | H36: =SUMIF('Monthly Detail'!$4:$4, '2025 Overview (Budget)'!H$19, 'Monthly Detail'!$89:$89) | I36: =SUMIF('Monthly Detail'!$4:$4, '2025 Overview (Budget)'!I$19, 'Monthly Detail'!$89:$89) | J36: =SUMIF('Monthly Detail'!$4:$4, '2025 Overview (Budget)'!J$19, 'Monthly Detail'!$89:$89) | K36: =SUMIF('Monthly Detail'!$4:$4, '2025 Overview (Budget)'!K$19, 'Monthly Detail'!$89:$89) | L36: =SUMIF('Monthly Detail'!$4:$4, '2025 Overview'!L$19, 'Monthly Detail'!$89:$89)+SUMIF('Monthly Detail'!$4:$4, '2025 Overview'!L$19, 'Monthly Detail'!$90:$90) | M36: =+'2025 AOP'!M36 | N36: =+'2025 AOP'!N36 | P36: =SUM(C36:O36)
B37: Operating Expenses | C37: =SUM(C36:C36) | D37: =SUM(D36:D36) | E37: =SUM(E36:E36) | F37: =SUM(F36:F36) | G37: =SUM(G36:G36) | H37: =SUM(H36:H36) | I37: =SUM(I36:I36) | J37: =SUM(J36:J36) | ... N37: =SUM(N36:N36) | P37: =SUM(P36:P36)
B39: Net Operating Income (EBITDA) | C39: =C33-C37 | D39: =D33-D37 | E39: =E33-E37 | F39: =F33-F37 | G39: =G33-G37 | H39: =H33-H37 | I39: =I33-I37 | J39: =J33-J37 | ... N39: =N33-N37 | P39: =P33-P37
B40: EBITDA % | C40: =IFERROR(C39/C22, 0) | D40: =IFERROR(D39/D22, 0) | E40: =IFERROR(E39/E22, 0) | F40: =IFERROR(F39/F22, 0) | G40: =IFERROR(G39/G22, 0) | H40: =IFERROR(H39/H22, 0) | I40: =IFERROR(I39/I22, 0) | J40: =IFERROR(J39/J22, 0) | ... N40: =IFERROR(N39/N22, 0) | P40: =P39/P22
B42: Other Income / (Expense) | C42: =SUMIF('Monthly Detail'!$4:$4, '2025 Overview (Budget)'!C$19, 'Monthly Detail'!95:95) | D42: =SUMIF('Monthly Detail'!$4:$4, '2025 Overview (Budget)'!D$19, 'Monthly Detail'!95:95) | E42: =SUMIF('Monthly Detail'!$4:$4, '2025 Overview (Budget)'!E$19, 'Monthly Detail'!95:95) | F42: =SUMIF('Monthly Detail'!$4:$4, '2025 Overview (Budget)'!F$19, 'Monthly Detail'!95:95) | G42: =SUMIF('Monthly Detail'!$4:$4, '2025 Overview (Budget)'!G$19, 'Monthly Detail'!95:95) | H42: =SUMIF('Monthly Detail'!$4:$4, '2025 Overview (Budget)'!H$19, 'Monthly Detail'!95:95) | I42: =SUMIF('Monthly Detail'!$4:$4, '2025 Overview (Budget)'!I$19, 'Monthly Detail'!95:95) | J42: =SUMIF('Monthly Detail'!$4:$4, '2025 Overview (Budget)'!J$19, 'Monthly Detail'!95:95) | ... L42: =SUMIF('Monthly Detail'!$4:$4, '2025 Overview (Budget)'!L$19, 'Monthly Detail'!95:95) | M42: =SUMIF('Monthly Detail'!$4:$4, '2025 Overview (Budget)'!M$19, 'Monthly Detail'!130:130) | N42: =SUMIF('Monthly Detail'!$4:$4, '2025 Overview (Budget)'!N$19, 'Monthly Detail'!130:130) | P42: =SUM(C42:O42)
B43: Net Income | C43: =C39+SUM(C42:C42) | D43: =D39+SUM(D42:D42) | E43: =E39+SUM(E42:E42) | F43: =F39+SUM(F42:F42) | G43: =G39+SUM(G42:G42) | H43: =H39+SUM(H42:H42) | I43: =I39+SUM(I42:I42) | J43: =J39+SUM(J42:J42) | ... N43: =N39+SUM(N42:N42) | P43: =P39+SUM(P42:P42)
B44: NI % | C44: =IFERROR(C43/C22, 0) | D44: =IFERROR(D43/D22, 0) | E44: =IFERROR(E43/E22, 0) | F44: =IFERROR(F43/F22, 0) | G44: =IFERROR(G43/G22, 0) | H44: =IFERROR(H43/H22, 0) | I44: =IFERROR(I43/I22, 0) | J44: =IFERROR(J43/J22, 0) | ... N44: =IFERROR(N43/N22, 0) | P44: =P43/P22
B46: Operating (Business) Cash | C46: =SUMIF('Monthly Detail'!$4:$4, '2025 Overview (Budget)'!C$19, 'Monthly Detail'!112:112) | D46: =SUMIF('Monthly Detail'!$4:$4, '2025 Overview (Budget)'!D$19, 'Monthly Detail'!112:112) | E46: =SUMIF('Monthly Detail'!$4:$4, '2025 Overview (Budget)'!E$19, 'Monthly Detail'!112:112) | F46: =SUMIF('Monthly Detail'!$4:$4, '2025 Overview (Budget)'!F$19, 'Monthly Detail'!112:112) | G46: =SUMIF('Monthly Detail'!$4:$4, '2025 Overview (Budget)'!G$19, 'Monthly Detail'!112:112) | H46: =SUMIF('Monthly Detail'!$4:$4, '2025 Overview (Budget)'!H$19, 'Monthly Detail'!112:112) | I46: =SUMIF('Monthly Detail'!$4:$4, '2025 Overview (Budget)'!I$19, 'Monthly Detail'!112:112) | J46: =SUMIF('Monthly Detail'!$4:$4, '2025 Overview (Budget)'!J$19, 'Monthly Detail'!112:112) | ... L46: =SUMIF('Monthly Detail'!$4:$4, '2025 Overview (Budget)'!L$19, 'Monthly Detail'!112:112) | M46: =+'2025 AOP'!M46 | N46: =+'2025 AOP'!N46
B47: Savings Cash | C47: =SUMIF('Monthly Detail'!$4:$4, '2025 Overview (Budget)'!C$19, 'Monthly Detail'!106:106) | D47: =SUMIF('Monthly Detail'!$4:$4, '2025 Overview (Budget)'!D$19, 'Monthly Detail'!106:106) | E47: =SUMIF('Monthly Detail'!$4:$4, '2025 Overview (Budget)'!E$19, 'Monthly Detail'!106:106) | F47: =SUMIF('Monthly Detail'!$4:$4, '2025 Overview (Budget)'!F$19, 'Monthly Detail'!106:106) | G47: =SUMIF('Monthly Detail'!$4:$4, '2025 Overview (Budget)'!G$19, 'Monthly Detail'!106:106) | H47: =SUMIF('Monthly Detail'!$4:$4, '2025 Overview (Budget)'!H$19, 'Monthly Detail'!106:106) | I47: =SUMIF('Monthly Detail'!$4:$4, '2025 Overview (Budget)'!I$19, 'Monthly Detail'!106:106) | J47: =SUMIF('Monthly Detail'!$4:$4, '2025 Overview (Budget)'!J$19, 'Monthly Detail'!106:106) | ... L47: =SUMIF('Monthly Detail'!$4:$4, '2025 Overview (Budget)'!L$19, 'Monthly Detail'!106:106) | M47: =+'2025 AOP'!M47 | N47: =+'2025 AOP'!N47
B48: Total Cash Balance | C48: =SUMIF('Monthly Detail'!$4:$4, '2025 Overview (Budget)'!C$19, 'Monthly Detail'!173:173) | D48: =SUMIF('Monthly Detail'!$4:$4, '2025 Overview (Budget)'!D$19, 'Monthly Detail'!173:173) | E48: =SUMIF('Monthly Detail'!$4:$4, '2025 Overview (Budget)'!E$19, 'Monthly Detail'!173:173) | F48: =SUMIF('Monthly Detail'!$4:$4, '2025 Overview (Budget)'!F$19, 'Monthly Detail'!173:173) | G48: =SUMIF('Monthly Detail'!$4:$4, '2025 Overview (Budget)'!G$19, 'Monthly Detail'!173:173) | H48: =SUMIF('Monthly Detail'!$4:$4, '2025 Overview (Budget)'!H$19, 'Monthly Detail'!173:173) | I48: =SUMIF('Monthly Detail'!$4:$4, '2025 Overview (Budget)'!I$19, 'Monthly Detail'!173:173) | J48: =SUMIF('Monthly Detail'!$4:$4, '2025 Overview (Budget)'!J$19, 'Monthly Detail'!173:173) | ... L48: =SUMIF('Monthly Detail'!$4:$4, '2025 Overview (Budget)'!L$19, 'Monthly Detail'!173:173) | M48: =+'2025 AOP'!M48 | N48: =+'2025 AOP'!N48
B49: Total Cash Inflow (Outflow) | C49: =SUMIF('Monthly Detail'!$4:$4, '2025 Overview (Budget)'!C$19, 'Monthly Detail'!170:170) | D49: =SUMIF('Monthly Detail'!$4:$4, '2025 Overview (Budget)'!D$19, 'Monthly Detail'!170:170) | E49: =SUMIF('Monthly Detail'!$4:$4, '2025 Overview (Budget)'!E$19, 'Monthly Detail'!170:170) | F49: =SUMIF('Monthly Detail'!$4:$4, '2025 Overview (Budget)'!F$19, 'Monthly Detail'!170:170) | G49: =SUMIF('Monthly Detail'!$4:$4, '2025 Overview (Budget)'!G$19, 'Monthly Detail'!170:170) | H49: =SUMIF('Monthly Detail'!$4:$4, '2025 Overview (Budget)'!H$19, 'Monthly Detail'!170:170) | I49: =SUMIF('Monthly Detail'!$4:$4, '2025 Overview (Budget)'!I$19, 'Monthly Detail'!170:170) | J49: =SUMIF('Monthly Detail'!$4:$4, '2025 Overview (Budget)'!J$19, 'Monthly Detail'!170:170) | ... L49: =SUMIF('Monthly Detail'!$4:$4, '2025 Overview (Budget)'!L$19, 'Monthly Detail'!170:170) | M49: =+'2025 AOP'!M49 | N49: =+'2025 AOP'!N49
B50: Operating Cash Burn | C50: =-SUMIF('Monthly Detail'!$4:$4, '2025 Overview (Budget)'!C$19, 'Monthly Detail'!89:89) | D50: =-SUMIF('Monthly Detail'!$4:$4, '2025 Overview (Budget)'!D$19, 'Monthly Detail'!89:89) | E50: =-SUMIF('Monthly Detail'!$4:$4, '2025 Overview (Budget)'!E$19, 'Monthly Detail'!89:89) | F50: =-SUMIF('Monthly Detail'!$4:$4, '2025 Overview (Budget)'!F$19, 'Monthly Detail'!89:89) | G50: =-SUMIF('Monthly Detail'!$4:$4, '2025 Overview (Budget)'!G$19, 'Monthly Detail'!89:89) | H50: =-SUMIF('Monthly Detail'!$4:$4, '2025 Overview (Budget)'!H$19, 'Monthly Detail'!89:89) | I50: =-SUMIF('Monthly Detail'!$4:$4, '2025 Overview (Budget)'!I$19, 'Monthly Detail'!89:89) | J50: =-SUMIF('Monthly Detail'!$4:$4, '2025 Overview (Budget)'!J$19, 'Monthly Detail'!89:89) | ... L50: =-SUMIF('Monthly Detail'!$4:$4, '2025 Overview (Budget)'!L$19, 'Monthly Detail'!89:89) | M50: =+'2025 AOP'!M50 | N50: =+'2025 AOP'!N50
B51: Owner Cash Burn/Allowance | C51: =SUMIF('Monthly Detail'!$4:$4, '2025 Overview (Budget)'!C$19, 'Monthly Detail'!154:154) | D51: =SUMIF('Monthly Detail'!$4:$4, '2025 Overview (Budget)'!D$19, 'Monthly Detail'!154:154) | E51: =SUMIF('Monthly Detail'!$4:$4, '2025 Overview (Budget)'!E$19, 'Monthly Detail'!154:154) | F51: =SUMIF('Monthly Detail'!$4:$4, '2025 Overview (Budget)'!F$19, 'Monthly Detail'!154:154) | G51: =SUMIF('Monthly Detail'!$4:$4, '2025 Overview (Budget)'!G$19, 'Monthly Detail'!154:154) | H51: =SUMIF('Monthly Detail'!$4:$4, '2025 Overview (Budget)'!H$19, 'Monthly Detail'!154:154) | I51: =SUMIF('Monthly Detail'!$4:$4, '2025 Overview (Budget)'!I$19, 'Monthly Detail'!154:154) | J51: =SUMIF('Monthly Detail'!$4:$4, '2025 Overview (Budget)'!J$19, 'Monthly Detail'!154:154) | ... L51: =SUMIF('Monthly Detail'!$4:$4, '2025 Overview (Budget)'!L$19, 'Monthly Detail'!154:154) | M51: =+'2025 AOP'!M51 | N51: =+'2025 AOP'!N51
B52: Operating Cash Runway | C52: =+C46-SUM('Monthly Detail'!AC89:AN89)-SUM('Monthly Detail'!AC61:AN61) | D52: =+D46-SUM('Monthly Detail'!AD89:AO89)-SUM('Monthly Detail'!AD61:AO61) | E52: =+E46-SUM('Monthly Detail'!AE89:AP89)-SUM('Monthly Detail'!AE61:AP61) | F52: =+F46-SUM('Monthly Detail'!AF89:AQ89)-SUM('Monthly Detail'!AF61:AQ61) | G52: =+G46-SUM('Monthly Detail'!AG89:AR89)-SUM('Monthly Detail'!AG61:AR61) | H52: =+H46-SUM('Monthly Detail'!AH89:AS89)-SUM('Monthly Detail'!AH61:AS61) | I52: =+I46-SUM('Monthly Detail'!AI89:AT89)-SUM('Monthly Detail'!AI61:AT61) | J52: =+J46-SUM('Monthly Detail'!AJ89:AU89)-SUM('Monthly Detail'!AJ61:AU61) | ... L52: =+L46-SUM('Monthly Detail'!AL89:AW89)-SUM('Monthly Detail'!AL61:AW61) | M52: =+'2025 AOP'!M52 | N52: =+'2025 AOP'!N52
B53: Owner Cash Runway | C53: =+C48-SUM('Monthly Detail'!AC89:AN89)-SUM('Monthly Detail'!AC61:AN61) | D53: =+D48-SUM('Monthly Detail'!AD89:AO89)-SUM('Monthly Detail'!AD61:AO61) | E53: =+E48-SUM('Monthly Detail'!AE89:AP89)-SUM('Monthly Detail'!AE61:AP61) | F53: =+F48-SUM('Monthly Detail'!AF89:AQ89)-SUM('Monthly Detail'!AF61:AQ61) | G53: =+G48-SUM('Monthly Detail'!AG89:AR89)-SUM('Monthly Detail'!AG61:AR61) | H53: =+H48-SUM('Monthly Detail'!AH89:AS89)-SUM('Monthly Detail'!AH61:AS61) | I53: =+I48-SUM('Monthly Detail'!AI89:AT89)-SUM('Monthly Detail'!AI61:AT61) | J53: =+J48-SUM('Monthly Detail'!AJ89:AU89)-SUM('Monthly Detail'!AJ61:AU61) | ... L53: =+L48-SUM('Monthly Detail'!AL89:AW89)-SUM('Monthly Detail'!AL61:AW61) | M53: =+'2025 AOP'!M53 | N53: =+'2025 AOP'!N53
B54: Operating Cash Runway - Burn Rate | C54: =+C46/-C50 | D54: =+D46/-D50 | E54: =+E46/-E50 | F54: =+F46/-F50 | G54: =+G46/-G50 | H54: =+H46/-H50 | I54: =+I46/-I50 | J54: =+J46/-J50 | ... L54: =+L46/-L50 | M54: =-'2025 AOP'!M54 | N54: =-'2025 AOP'!N54
B55: Cash Runway - Owner Burn Rate | C55: =+IFERROR(C48/-C51, 0) | D55: =+IFERROR(D48/-D51, 0) | E55: =+IFERROR(E48/-E51, 0) | F55: =+IFERROR(F48/-F51, 0) | G55: =+IFERROR(G48/-G51, 0) | H55: =+IFERROR(H48/-H51, 0) | I55: =+IFERROR(I48/-I51, 0) | J55: =+IFERROR(J48/-J51, 0) | ... L55: =+IFERROR(L48/-L51, 0) | M55: =+'2025 AOP'!M55 | N55: =+'2025 AOP'!N55

Sheet 2025 Overview
B15: 2025 Overview
C18: January | D18: February | E18: March | F18: April | G18: May | H18: June | I18: July | J18: August | K18: September | L18: October | M18: November | N18: December | P18: Total
C19: 45688 | D19: 45716 | E19: 45747 | F19: 45777 | G19: 45808 | H19: 45838 | I19: 45869 | J19: 45900 | K19: 45930 | L19: 45961 | M19: 45991 | N19: 46022 | O19: 45322
B20: Service Income | C20: =SUMIF('Monthly Detail'!$4:$4, '2025 Overview'!C$19, 'Monthly Detail'!13:13) | D20: =SUMIF('Monthly Detail'!$4:$4, '2025 Overview'!D$19, 'Monthly Detail'!13:13) | E20: =SUMIF('Monthly Detail'!$4:$4, '2025 Overview'!E$19, 'Monthly Detail'!13:13) | F20: =SUMIF('Monthly Detail'!$4:$4, '2025 Overview'!F$19, 'Monthly Detail'!13:13) | G20: =SUMIF('Monthly Detail'!$4:$4, '2025 Overview'!G$19, 'Monthly Detail'!13:13) | H20: =SUMIF('Monthly Detail'!$4:$4, '2025 Overview'!H$19, 'Monthly Detail'!13:13) | I20: =SUMIF('Monthly Detail'!$4:$4, '2025 Overview'!I$19, 'Monthly Detail'!13:13) | J20: =SUMIF('Monthly Detail'!$4:$4, '2025 Overview'!J$19, 'Monthly Detail'!13:13) | ... N20: =SUMIF('Monthly Detail'!$4:$4, '2025 Overview'!N$19, 'Monthly Detail'!13:13) | P20: =SUM(C20:O20)
B21: Misc. | C21: =SUMIF('Monthly Detail'!$4:$4, '2025 Overview'!C$19, 'Monthly Detail'!12:12) | D21: =SUMIF('Monthly Detail'!$4:$4, '2025 Overview'!D$19, 'Monthly Detail'!12:12) | E21: =SUMIF('Monthly Detail'!$4:$4, '2025 Overview'!E$19, 'Monthly Detail'!12:12) | F21: =SUMIF('Monthly Detail'!$4:$4, '2025 Overview'!F$19, 'Monthly Detail'!12:12) | G21: =SUMIF('Monthly Detail'!$4:$4, '2025 Overview'!G$19, 'Monthly Detail'!12:12) | H21: =SUMIF('Monthly Detail'!$4:$4, '2025 Overview'!H$19, 'Monthly Detail'!12:12) | I21: =SUMIF('Monthly Detail'!$4:$4, '2025 Overview'!I$19, 'Monthly Detail'!12:12) | J21: =SUMIF('Monthly Detail'!$4:$4, '2025 Overview'!J$19, 'Monthly Detail'!12:12) | ... N21: =SUMIF('Monthly Detail'!$4:$4, '2025 Overview'!N$19, 'Monthly Detail'!12:12) | P21: =SUM(C21:O21)
B22: Total Income | C22: =SUM(C20:C21) | D22: =SUM(D20:D21) | E22: =SUM(E20:E21) | F22: =SUM(F20:F21) | G22: =SUM(G20:G21) | H22: =SUM(H20:H21) | I22: =SUM(I20:I21) | J22: =SUM(J20:J21) | ... N22: =SUM(N20:N21) | P22: =SUM(P20:P20)
B23: # of Appointments | C23: =SUMIF('Monthly Detail'!$4:$4, '2025 Overview'!C$19, 'Monthly Detail'!15:15) | D23: =SUMIF('Monthly Detail'!$4:$4, '2025 Overview'!D$19, 'Monthly Detail'!15:15) | E23: =SUMIF('Monthly Detail'!$4:$4, '2025 Overview'!E$19, 'Monthly Detail'!15:15) | F23: =SUMIF('Monthly Detail'!$4:$4, '2025 Overview'!F$19, 'Monthly Detail'!15:15) | G23: =SUMIF('Monthly Detail'!$4:$4, '2025 Overview'!G$19, 'Monthly Detail'!15:15) | H23: =SUMIF('Monthly Detail'!$4:$4, '2025 Overview'!H$19, 'Monthly Detail'!15:15) | I23: =SUMIF('Monthly Detail'!$4:$4, '2025 Overview'!I$19, 'Monthly Detail'!15:15) | J23: =SUMIF('Monthly Detail'!$4:$4, '2025 Overview'!J$19, 'Monthly Detail'!15:15) | ... N23: =SUMIF('Monthly Detail'!$4:$4, '2025 Overview'!N$19, 'Monthly Detail'!15:15) | P23: =+SUM(C23:N23)
B24: MRR | C24: =SUMIF('Monthly Detail'!$4:$4, '2025 Overview'!C$19, 'Monthly Detail'!41:41) | D24: =SUMIF('Monthly Detail'!$4:$4, '2025 Overview'!D$19, 'Monthly Detail'!41:41) | E24: =SUMIF('Monthly Detail'!$4:$4, '2025 Overview'!E$19, 'Monthly Detail'!41:41) | F24: =SUMIF('Monthly Detail'!$4:$4, '2025 Overview'!F$19, 'Monthly Detail'!41:41) | G24: =SUMIF('Monthly Detail'!$4:$4, '2025 Overview'!G$19, 'Monthly Detail'!41:41) | H24: =SUMIF('Monthly Detail'!$4:$4, '2025 Overview'!H$19, 'Monthly Detail'!41:41) | I24: =SUMIF('Monthly Detail'!$4:$4, '2025 Overview'!I$19, 'Monthly Detail'!41:41) | J24: =SUMIF('Monthly Detail'!$4:$4, '2025 Overview'!J$19, 'Monthly Detail'!41:41) | ... N24: =SUMIF('Monthly Detail'!$4:$4, '2025 Overview'!N$19, 'Monthly Detail'!41:41) | P24: =+AVERAGE(C24:N24)
B25: Recurring Client Base | C25: =SUMIF('Monthly Detail'!$4:$4, '2025 Overview'!C$19, 'Monthly Detail'!17:17) | D25: =SUMIF('Monthly Detail'!$4:$4, '2025 Overview'!D$19, 'Monthly Detail'!17:17) | E25: =SUMIF('Monthly Detail'!$4:$4, '2025 Overview'!E$19, 'Monthly Detail'!17:17) | F25: =SUMIF('Monthly Detail'!$4:$4, '2025 Overview'!F$19, 'Monthly Detail'!17:17) | G25: =SUMIF('Monthly Detail'!$4:$4, '2025 Overview'!G$19, 'Monthly Detail'!17:17) | H25: =SUMIF('Monthly Detail'!$4:$4, '2025 Overview'!H$19, 'Monthly Detail'!17:17) | I25: =SUMIF('Monthly Detail'!$4:$4, '2025 Overview'!I$19, 'Monthly Detail'!17:17) | J25: =SUMIF('Monthly Detail'!$4:$4, '2025 Overview'!J$19, 'Monthly Detail'!17:17) | ... N25: =SUMIF('Monthly Detail'!$4:$4, '2025 Overview'!N$19, 'Monthly Detail'!17:17)
B28: Software - COS | C28: =SUMIF('Monthly Detail'!$4:$4, '2025 Overview'!C$19, 'Monthly Detail'!58:58) | D28: =SUMIF('Monthly Detail'!$4:$4, '2025 Overview'!D$19, 'Monthly Detail'!58:58) | E28: =SUMIF('Monthly Detail'!$4:$4, '2025 Overview'!E$19, 'Monthly Detail'!58:58) | F28: =SUMIF('Monthly Detail'!$4:$4, '2025 Overview'!F$19, 'Monthly Detail'!58:58) | G28: =SUMIF('Monthly Detail'!$4:$4, '2025 Overview'!G$19, 'Monthly Detail'!58:58) | H28: =SUMIF('Monthly Detail'!$4:$4, '2025 Overview'!H$19, 'Monthly Detail'!58:58) | I28: =SUMIF('Monthly Detail'!$4:$4, '2025 Overview'!I$19, 'Monthly Detail'!58:58) | J28: =SUMIF('Monthly Detail'!$4:$4, '2025 Overview'!J$19, 'Monthly Detail'!58:58) | ... N28: =SUMIF('Monthly Detail'!$4:$4, '2025 Overview'!N$19, 'Monthly Detail'!58:58) | P28: =+SUM(C28:N28)
B29: Materials - COGS | C29: =SUMIF('Monthly Detail'!$4:$4, '2025 Overview'!C$19, 'Monthly Detail'!59:59) | D29: =SUMIF('Monthly Detail'!$4:$4, '2025 Overview'!D$19, 'Monthly Detail'!59:59) | E29: =SUMIF('Monthly Detail'!$4:$4, '2025 Overview'!E$19, 'Monthly Detail'!59:59) | F29: =SUMIF('Monthly Detail'!$4:$4, '2025 Overview'!F$19, 'Monthly Detail'!59:59) | G29: =SUMIF('Monthly Detail'!$4:$4, '2025 Overview'!G$19, 'Monthly Detail'!59:59) | H29: =SUMIF('Monthly Detail'!$4:$4, '2025 Overview'!H$19, 'Monthly Detail'!59:59) | I29: =SUMIF('Monthly Detail'!$4:$4, '2025 Overview'!I$19, 'Monthly Detail'!59:59) | J29: =SUMIF('Monthly Detail'!$4:$4, '2025 Overview'!J$19, 'Monthly Detail'!59:59) | ... N29: =SUMIF('Monthly Detail'!$4:$4, '2025 Overview'!N$19, 'Monthly Detail'!59:59) | P29: =+SUM(C29:N29)
B30: Contractors - COS | C30: =SUMIF('Monthly Detail'!$4:$4, '2025 Overview'!C$19, 'Monthly Detail'!60:60) | D30: =SUMIF('Monthly Detail'!$4:$4, '2025 Overview'!D$19, 'Monthly Detail'!60:60) | E30: =SUMIF('Monthly Detail'!$4:$4, '2025 Overview'!E$19, 'Monthly Detail'!60:60) | F30: =SUMIF('Monthly Detail'!$4:$4, '2025 Overview'!F$19, 'Monthly Detail'!60:60) | G30: =SUMIF('Monthly Detail'!$4:$4, '2025 Overview'!G$19, 'Monthly Detail'!60:60) | H30: =SUMIF('Monthly Detail'!$4:$4, '2025 Overview'!H$19, 'Monthly Detail'!60:60) | I30: =SUMIF('Monthly Detail'!$4:$4, '2025 Overview'!I$19, 'Monthly Detail'!60:60) | J30: =SUMIF('Monthly Detail'!$4:$4, '2025 Overview'!J$19, 'Monthly Detail'!60:60) | ... N30: =SUMIF('Monthly Detail'!$4:$4, '2025 Overview'!N$19, 'Monthly Detail'!60:60) | P30: =+SUM(C30:N30)
B31: Total Cost of Goods Sold (COGS) | C31: =SUM(C28:C30) | D31: =SUM(D28:D30) | E31: =SUM(E28:E30) | F31: =SUM(F28:F30) | G31: =SUM(G28:G30) | H31: =SUM(H28:H30) | I31: =SUM(I28:I30) | J31: =SUM(J28:J30) | ... N31: =SUM(N28:N30) | P31: =SUM(P28:P30)
B33: Gross Margin | C33: =+C22-C31 | D33: =+D22-D31 | E33: =+E22-E31 | F33: =+F22-F31 | G33: =+G22-G31 | H33: =+H22-H31 | I33: =+I22-I31 | J33: =+J22-J31 | ... N33: =+N22-N31 | P33: =+SUM(C33:N33)
B34: GM % | C34: =IFERROR(C33/C22, 0) | D34: =IFERROR(D33/D22, 0) | E34: =IFERROR(E33/E22, 0) | F34: =IFERROR(F33/F22, 0) | G34: =IFERROR(G33/G22, 0) | H34: =IFERROR(H33/H22, 0) | I34: =IFERROR(I33/I22, 0) | J34: =IFERROR(J33/J22, 0) | ... N34: =IFERROR(N33/N22, 0) | P34: =P33/P22
B36: General & Admintrative Expenses | C36: =SUMIF('Monthly Detail'!$4:$4, '2025 Overview'!C$19, 'Monthly Detail'!$89:$89)+SUMIF('Monthly Detail'!$4:$4, '2025 Overview'!C$19, 'Monthly Detail'!$90:$90) | D36: =SUMIF('Monthly Detail'!$4:$4, '2025 Overview'!D$19, 'Monthly Detail'!$89:$89)+SUMIF('Monthly Detail'!$4:$4, '2025 Overview'!D$19, 'Monthly Detail'!$90:$90) | E36: =SUMIF('Monthly Detail'!$4:$4, '2025 Overview'!E$19, 'Monthly Detail'!$89:$89)+SUMIF('Monthly Detail'!$4:$4, '2025 Overview'!E$19, 'Monthly Detail'!$90:$90) | F36: =SUMIF('Monthly Detail'!$4:$4, '2025 Overview'!F$19, 'Monthly Detail'!$89:$89)+SUMIF('Monthly Detail'!$4:$4, '2025 Overview'!F$19, 'Monthly Detail'!$90:$90) | G36: =SUMIF('Monthly Detail'!$4:$4, '2025 Overview'!G$19, 'Monthly Detail'!$89:$89)+SUMIF('Monthly Detail'!$4:$4, '2025 Overview'!G$19, 'Monthly Detail'!$90:$90) | H36: =SUMIF('Monthly Detail'!$4:$4, '2025 Overview'!H$19, 'Monthly Detail'!$89:$89)+SUMIF('Monthly Detail'!$4:$4, '2025 Overview'!H$19, 'Monthly Detail'!$90:$90) | I36: =SUMIF('Monthly Detail'!$4:$4, '2025 Overview'!I$19, 'Monthly Detail'!$89:$89)+SUMIF('Monthly Detail'!$4:$4, '2025 Overview'!I$19, 'Monthly Detail'!$90:$90) | J36: =SUMIF('Monthly Detail'!$4:$4, '2025 Overview'!J$19, 'Monthly Detail'!$89:$89)+SUMIF('Monthly Detail'!$4:$4, '2025 Overview'!J$19, 'Monthly Detail'!$90:$90) | ... N36: =SUMIF('Monthly Detail'!$4:$4, '2025 Overview'!N$19, 'Monthly Detail'!$89:$89)+SUMIF('Monthly Detail'!$4:$4, '2025 Overview'!N$19, 'Monthly Detail'!$90:$90) | P36: =SUM(C36:O36)
B37: Operating Expenses | C37: =SUM(C36:C36) | D37: =SUM(D36:D36) | E37: =SUM(E36:E36) | F37: =SUM(F36:F36) | G37: =SUM(G36:G36) | H37: =SUM(H36:H36) | I37: =SUM(I36:I36) | J37: =SUM(J36:J36) | ... N37: =SUM(N36:N36) | P37: =SUM(P36:P36)
B39: Net Operating Income (EBITDA) | C39: =C33-C37 | D39: =D33-D37 | E39: =E33-E37 | F39: =F33-F37 | G39: =G33-G37 | H39: =H33-H37 | I39: =I33-I37 | J39: =J33-J37 | ... N39: =N33-N37 | P39: =P33-P37
B40: EBITDA % | C40: =IFERROR(C39/C22, 0) | D40: =IFERROR(D39/D22, 0) | E40: =IFERROR(E39/E22, 0) | F40: =IFERROR(F39/F22, 0) | G40: =IFERROR(G39/G22, 0) | H40: =IFERROR(H39/H22, 0) | I40: =IFERROR(I39/I22, 0) | J40: =IFERROR(J39/J22, 0) | ... N40: =IFERROR(N39/N22, 0) | P40: =P39/P22
B42: Other Income / (Expense) | C42: =SUMIF('Monthly Detail'!$4:$4, '2025 Overview'!C$19, 'Monthly Detail'!95:95) | D42: =SUMIF('Monthly Detail'!$4:$4, '2025 Overview'!D$19, 'Monthly Detail'!95:95) | E42: =SUMIF('Monthly Detail'!$4:$4, '2025 Overview'!E$19, 'Monthly Detail'!95:95) | F42: =SUMIF('Monthly Detail'!$4:$4, '2025 Overview'!F$19, 'Monthly Detail'!95:95) | G42: =SUMIF('Monthly Detail'!$4:$4, '2025 Overview'!G$19, 'Monthly Detail'!95:95) | H42: =SUMIF('Monthly Detail'!$4:$4, '2025 Overview'!H$19, 'Monthly Detail'!95:95) | I42: =SUMIF('Monthly Detail'!$4:$4, '2025 Overview'!I$19, 'Monthly Detail'!95:95) | J42: =SUMIF('Monthly Detail'!$4:$4, '2025 Overview'!J$19, 'Monthly Detail'!95:95) | ... N42: =SUMIF('Monthly Detail'!$4:$4, '2025 Overview'!N$19, 'Monthly Detail'!95:95) | P42: =SUM(C42:O42)
B43: Net Income | C43: =C39+SUM(C42:C42) | D43: =D39+SUM(D42:D42) | E43: =E39+SUM(E42:E42) | F43: =F39+SUM(F42:F42) | G43: =G39+SUM(G42:G42) | H43: =H39+SUM(H42:H42) | I43: =I39+SUM(I42:I42) | J43: =J39+SUM(J42:J42) | ... N43: =N39+SUM(N42:N42) | P43: =P39+SUM(P42:P42)
B44: NI % | C44: =IFERROR(C43/C22, 0) | D44: =IFERROR(D43/D22, 0) | E44: =IFERROR(E43/E22, 0) | F44: =IFERROR(F43/F22, 0) | G44: =IFERROR(G43/G22, 0) | H44: =IFERROR(H43/H22, 0) | I44: =IFERROR(I43/I22, 0) | J44: =IFERROR(J43/J22, 0) | ... N44: =IFERROR(N43/N22, 0) | P44: =P43/P22
B46: Operating (Business) Cash | C46: =SUMIF('Monthly Detail'!$4:$4, '2025 Overview'!C$19, 'Monthly Detail'!112:112) | D46: =SUMIF('Monthly Detail'!$4:$4, '2025 Overview'!D$19, 'Monthly Detail'!112:112) | E46: =SUMIF('Monthly Detail'!$4:$4, '2025 Overview'!E$19, 'Monthly Detail'!112:112) | F46: =SUMIF('Monthly Detail'!$4:$4, '2025 Overview'!F$19, 'Monthly Detail'!112:112) | G46: =SUMIF('Monthly Detail'!$4:$4, '2025 Overview'!G$19, 'Monthly Detail'!112:112) | H46: =SUMIF('Monthly Detail'!$4:$4, '2025 Overview'!H$19, 'Monthly Detail'!112:112) | I46: =SUMIF('Monthly Detail'!$4:$4, '2025 Overview'!I$19, 'Monthly Detail'!112:112) | J46: =SUMIF('Monthly Detail'!$4:$4, '2025 Overview'!J$19, 'Monthly Detail'!112:112) | ... N46: =SUMIF('Monthly Detail'!$4:$4, '2025 Overview'!N$19, 'Monthly Detail'!112:112)
B47: Savings Cash | C47: =SUMIF('Monthly Detail'!$4:$4, '2025 Overview'!C$19, 'Monthly Detail'!106:106) | D47: =SUMIF('Monthly Detail'!$4:$4, '2025 Overview'!D$19, 'Monthly Detail'!106:106) | E47: =SUMIF('Monthly Detail'!$4:$4, '2025 Overview'!E$19, 'Monthly Detail'!106:106) | F47: =SUMIF('Monthly Detail'!$4:$4, '2025 Overview'!F$19, 'Monthly Detail'!106:106) | G47: =SUMIF('Monthly Detail'!$4:$4, '2025 Overview'!G$19, 'Monthly Detail'!106:106) | H47: =SUMIF('Monthly Detail'!$4:$4, '2025 Overview'!H$19, 'Monthly Detail'!106:106) | I47: =SUMIF('Monthly Detail'!$4:$4, '2025 Overview'!I$19, 'Monthly Detail'!106:106) | J47: =SUMIF('Monthly Detail'!$4:$4, '2025 Overview'!J$19, 'Monthly Detail'!106:106) | ... N47: =SUMIF('Monthly Detail'!$4:$4, '2025 Overview'!N$19, 'Monthly Detail'!106:106)
B48: Total Cash Balance | C48: =SUMIF('Monthly Detail'!$4:$4, '2025 Overview'!C$19, 'Monthly Detail'!173:173) | D48: =SUMIF('Monthly Detail'!$4:$4, '2025 Overview'!D$19, 'Monthly Detail'!173:173) | E48: =SUMIF('Monthly Detail'!$4:$4, '2025 Overview'!E$19, 'Monthly Detail'!173:173) | F48: =SUMIF('Monthly Detail'!$4:$4, '2025 Overview'!F$19, 'Monthly Detail'!173:173) | G48: =SUMIF('Monthly Detail'!$4:$4, '2025 Overview'!G$19, 'Monthly Detail'!173:173) | H48: =SUMIF('Monthly Detail'!$4:$4, '2025 Overview'!H$19, 'Monthly Detail'!173:173) | I48: =SUMIF('Monthly Detail'!$4:$4, '2025 Overview'!I$19, 'Monthly Detail'!173:173) | J48: =SUMIF('Monthly Detail'!$4:$4, '2025 Overview'!J$19, 'Monthly Detail'!173:173) | ... N48: =SUMIF('Monthly Detail'!$4:$4, '2025 Overview'!N$19, 'Monthly Detail'!173:173) | P48: =+(SUM(C43:E43)*0.153)-SUM('Monthly Detail'!AO69:AP69)
B49: Total Cash Inflow (Outflow) | C49: =SUMIF('Monthly Detail'!$4:$4, '2025 Overview'!C$19, 'Monthly Detail'!170:170) | D49: =SUMIF('Monthly Detail'!$4:$4, '2025 Overview'!D$19, 'Monthly Detail'!170:170) | E49: =SUMIF('Monthly Detail'!$4:$4, '2025 Overview'!E$19, 'Monthly Detail'!170:170) | F49: =SUMIF('Monthly Detail'!$4:$4, '2025 Overview'!F$19, 'Monthly Detail'!170:170) | G49: =SUMIF('Monthly Detail'!$4:$4, '2025 Overview'!G$19, 'Monthly Detail'!170:170) | H49: =SUMIF('Monthly Detail'!$4:$4, '2025 Overview'!H$19, 'Monthly Detail'!170:170) | I49: =SUMIF('Monthly Detail'!$4:$4, '2025 Overview'!I$19, 'Monthly Detail'!170:170) | J49: =SUMIF('Monthly Detail'!$4:$4, '2025 Overview'!J$19, 'Monthly Detail'!170:170) | ... N49: =SUMIF('Monthly Detail'!$4:$4, '2025 Overview'!N$19, 'Monthly Detail'!170:170) | P49: =+SUM(C43:H43)*0.15
B50: Operating Cash Burn | C50: =-SUMIF('Monthly Detail'!$4:$4, '2025 Overview'!C$19, 'Monthly Detail'!89:89) | D50: =-SUMIF('Monthly Detail'!$4:$4, '2025 Overview'!D$19, 'Monthly Detail'!89:89) | E50: =-SUMIF('Monthly Detail'!$4:$4, '2025 Overview'!E$19, 'Monthly Detail'!89:89) | F50: =-SUMIF('Monthly Detail'!$4:$4, '2025 Overview'!F$19, 'Monthly Detail'!89:89) | G50: =-SUMIF('Monthly Detail'!$4:$4, '2025 Overview'!G$19, 'Monthly Detail'!89:89) | H50: =-SUMIF('Monthly Detail'!$4:$4, '2025 Overview'!H$19, 'Monthly Detail'!89:89) | I50: =-SUMIF('Monthly Detail'!$4:$4, '2025 Overview'!I$19, 'Monthly Detail'!89:89) | J50: =-SUMIF('Monthly Detail'!$4:$4, '2025 Overview'!J$19, 'Monthly Detail'!89:89) | ... N50: =-SUMIF('Monthly Detail'!$4:$4, '2025 Overview'!N$19, 'Monthly Detail'!89:89) | P50: =+SUM('Monthly Detail'!AO69:AS69)
B51: Owner Cash Burn/Allowance | C51: =SUMIF('Monthly Detail'!$4:$4, '2025 Overview'!C$19, 'Monthly Detail'!154:154) | D51: =SUMIF('Monthly Detail'!$4:$4, '2025 Overview'!D$19, 'Monthly Detail'!154:154) | E51: =SUMIF('Monthly Detail'!$4:$4, '2025 Overview'!E$19, 'Monthly Detail'!154:154) | F51: =SUMIF('Monthly Detail'!$4:$4, '2025 Overview'!F$19, 'Monthly Detail'!154:154) | G51: =SUMIF('Monthly Detail'!$4:$4, '2025 Overview'!G$19, 'Monthly Detail'!154:154) | H51: =SUMIF('Monthly Detail'!$4:$4,'2025 Overview'!H$19,'Monthly Detail'!154:154)-SUMIF('Monthly Detail'!$4:$4,H19,'Monthly Detail'!68:68) | I51: =SUMIF('Monthly Detail'!$4:$4,'2025 Overview'!I$19,'Monthly Detail'!154:154)-SUMIF('Monthly Detail'!$4:$4,I19,'Monthly Detail'!68:68) | J51: =SUMIF('Monthly Detail'!$4:$4,'2025 Overview'!J$19,'Monthly Detail'!154:154)-SUMIF('Monthly Detail'!$4:$4,J19,'Monthly Detail'!68:68) | K51: =SUMIF('Monthly Detail'!$4:$4,'2025 Overview'!K$19,'Monthly Detail'!154:154)-SUMIF('Monthly Detail'!$4:$4,K19,'Monthly Detail'!68:68) | L51: =SUMIF('Monthly Detail'!$4:$4,'2025 Overview'!L$19,'Monthly Detail'!154:154)-SUMIF('Monthly Detail'!$4:$4,L19,'Monthly Detail'!68:68) | M51: =SUMIF('Monthly Detail'!$4:$4,'2025 Overview'!M$19,'Monthly Detail'!154:154)-SUMIF('Monthly Detail'!$4:$4,M19,'Monthly Detail'!68:68) | N51: =SUMIF('Monthly Detail'!$4:$4,'2025 Overview'!N$19,'Monthly Detail'!154:154)-SUMIF('Monthly Detail'!$4:$4,N19,'Monthly Detail'!68:68) | P51: =+P49-P50
B52: Operating Cash Runway | C52: =+C46-SUM('Monthly Detail'!AC89:AN89)-SUM('Monthly Detail'!AC61:AN61) | D52: =+D46-SUM('Monthly Detail'!AD89:AO89)-SUM('Monthly Detail'!AD61:AO61) | E52: =+E46-SUM('Monthly Detail'!AE89:AP89)-SUM('Monthly Detail'!AE61:AP61) | F52: =+F46-SUM('Monthly Detail'!AF89:AQ89)-SUM('Monthly Detail'!AF61:AQ61) | G52: =+G46-SUM('Monthly Detail'!AG89:AR89)-SUM('Monthly Detail'!AG61:AR61) | H52: =+H46-SUM('Monthly Detail'!AH89:AS89)-SUM('Monthly Detail'!AH61:AS61) | I52: =+I46-SUM('Monthly Detail'!AI89:AT89)-SUM('Monthly Detail'!AI61:AT61) | J52: =+J46-SUM('Monthly Detail'!AJ89:AU89)-SUM('Monthly Detail'!AJ61:AU61) | ... N52: =+N46-SUM('Monthly Detail'!AN89:AY89)-SUM('Monthly Detail'!AN61:AY61)
B53: Owner Cash Runway | C53: =+C48-SUM('Monthly Detail'!AC89:AN89)-SUM('Monthly Detail'!AC61:AN61) | D53: =+D48-SUM('Monthly Detail'!AD89:AO89)-SUM('Monthly Detail'!AD61:AO61) | E53: =+E48-SUM('Monthly Detail'!AE89:AP89)-SUM('Monthly Detail'!AE61:AP61) | F53: =+F48-SUM('Monthly Detail'!AF89:AQ89)-SUM('Monthly Detail'!AF61:AQ61) | G53: =+G48-SUM('Monthly Detail'!AG89:AR89)-SUM('Monthly Detail'!AG61:AR61) | H53: =+H48-SUM('Monthly Detail'!AH89:AS89)-SUM('Monthly Detail'!AH61:AS61) | I53: =+I48-SUM('Monthly Detail'!AI89:AT89)-SUM('Monthly Detail'!AI61:AT61) | J53: =+J48-SUM('Monthly Detail'!AJ89:AU89)-SUM('Monthly Detail'!AJ61:AU61) | ... N53: =+N48-SUM('Monthly Detail'!AN89:AY89)-SUM('Monthly Detail'!AN61:AY61)
B54: Operating Cash Runway - Burn Rate | C54: =+C46/-C50 | D54: =+D46/-D50 | E54: =+E46/-E50 | F54: =+F46/-F50 | G54: =+G46/-G50 | H54: =+H46/-H50 | I54: =+I46/-I50 | J54: =+J46/-J50 | ... N54: =+N46/-N50
B55: Cash Runway - Owner Burn Rate | C55: =+IFERROR(C48/-C51, 0) | D55: =+IFERROR(D48/-D51, 0) | E55: =+IFERROR(E48/-E51, 0) | F55: =+IFERROR(F48/-F51, 0) | G55: =+IFERROR(G48/-G51, 0) | H55: =+IFERROR(H48/-H51, 0) | I55: =+IFERROR(I48/-I51, 0) | J55: =+IFERROR(J48/-J51, 0) | ... N55: =+IFERROR(N48/-N51, 0)

Sheet 2025 AOP
B15: 2025 Overview
C18: January | D18: February | E18: March | F18: April | G18: May | H18: June | I18: July | J18: August | K18: September | L18: October | M18: November | N18: December | P18: Total
C19: 45688 | D19: 45716 | E19: 45747 | F19: 45777 | G19: 45808 | H19: 45838 | I19: 45869 | J19: 45900 | K19: 45930 | L19: 45961 | M19: 45991 | N19: 46022 | O19: 45322
B20: Service Income | C20: 7249.7138 | D20: 4913.4872 | E20: 6536.7151 | F20: 9380.6106 | G20: 10754.417 | H20: 10296.469 | I20: 8231.419 | J20: 7580.1793 | K20: 6911.5121 | L20: 7871.8411 | M20: 7017.7073 | N20: 8571.1673 | P20: 95315.238
B21: Misc. | C21: 0 | D21: 0 | E21: 0 | F21: 0 | G21: 0 | H21: 0 | I21: 0 | J21: 0 | K21: 0 | L21: 0 | M21: 0 | N21: 0 | P21: 0
B22: Total Income | C22: 7249.7138 | D22: 4913.4872 | E22: 6536.7151 | F22: 9380.6106 | G22: 10754.417 | H22: 10296.469 | I22: 8231.419 | J22: 7580.1793 | K22: 6911.5121 | L22: 7871.8411 | M22: 7017.7073 | N22: 8571.1673 | P22: 95315.238
B23: # of Appointments | C23: 80.370052 | D23: 59.794008 | E23: 75.759674 | F23: 108.72005 | G23: 130.30784 | H23: 113.65213 | I23: 95.401071 | J23: 92.036778 | K23: 76.462454 | L23: 91.23361 | M23: 85.852884 | N23: 94.608295 | P23: 1104.1988
B24: MRR | C24: 5375.6771 | D24: 3207.5442 | E24: 4505.4852 | F24: 6748.1072 | G24: 7779.5024 | H24: 7231.6338 | I24: 6123.8576 | J24: 5252.8868 | K24: 4808.0085 | L24: 5880.5453 | M24: 4643.0956 | N24: 6105.5718 | P24: 5638.493
B25: Recurring Client Base | C25: 40.158949 | D25: 33.93714 | E25: 40.724568 | F25: 55.996281 | G25: 66.743042 | H25: 59.955614 | I25: 47.511996 | J25: 49.208853 | K25: 40.724568 | L25: 45.24952 | M25: 48.077615 | N25: 49.208853
B28: Software - COS | C28: 214.68476 | D28: 145.50241 | E28: 193.57083 | F28: 277.78671 | G28: 318.46904 | H28: 304.9079 | I28: 243.75586 | J28: 224.47079 | K28: 204.66964 | L28: 233.10773 | M28: 207.81439 | N28: 253.81678 | P28: 2822.5568
B29: Materials - COGS | C29: 244.43671 | D29: 165.66677 | E29: 220.39672 | F29: 316.28361 | G29: 362.60387 | H29: 347.16337 | I29: 277.53661 | J29: 255.57893 | K29: 233.03366 | L29: 265.41282 | M29: 236.61421 | N29: 288.99182 | P29: 3213.7191
B30: Contractors - COS | C30: 0 | D30: 300 | E30: 540 | F30: 940.80078 | G30: 1179.6343 | H30: 980.02097 | I30: 381.01607 | J30: 540 | K30: 300 | L30: 558.50415 | M30: 540 | N30: 680.08064 | P30: 6940.0569
B31: Total Cost of Goods Sold (COGS) | C31: 459.12148 | D31: 611.16918 | E31: 953.96755 | F31: 1534.8711 | G31: 1860.7072 | H31: 1632.0922 | I31: 902.30854 | J31: 1020.0497 | K31: 737.7033 | L31: 1057.0247 | M31: 984.4286 | N31: 1222.8892 | P31: 12976.333
B33: Gross Margin | C33: 6790.5923 | D33: 4302.318 | E33: 5582.7475 | F33: 7845.7395 | G33: 8893.7095 | H33: 8664.3768 | I33: 7329.1104 | J33: 6560.1295 | K33: 6173.8088 | L33: 6814.8164 | M33: 6033.2787 | N33: 7348.278 | P33: 82338.906
B34: GM % | C34: 0.9366704 | D34: 0.87561397 | E34: 0.8540601 | F34: 0.83637834 | G34: 0.82698204 | H34: 0.8414901 | I34: 0.89038238 | J34: 0.86543198 | K34: 0.89326456 | L34: 0.86572078 | M34: 0.85972219 | N34: 0.85732524 | P34: 0.86385878
B36: General & Admintrative Expenses | C36: 2422.1893 | D36: 6297.7867 | E36: 6297.7867 | F36: 6297.7867 | G36: 6297.7867 | H36: 6347.7867 | I36: 6297.7867 | J36: 6297.7867 | K36: 6297.7867 | L36: 6402.7867 | M36: 6297.7867 | N36: 6297.7867 | P36: 71852.843
B37: Operating Expenses | C37: 2422.1893 | D37: 6297.7867 | E37: 6297.7867 | F37: 6297.7867 | G37: 6297.7867 | H37: 6347.7867 | I37: 6297.7867 | J37: 6297.7867 | K37: 6297.7867 | L37: 6402.7867 | M37: 6297.7867 | N37: 6297.7867 | P37: 71852.843
B39: Net Operating Income (EBITDA) | C39: 4368.403 | D39: -1995.4687 | E39: -715.03914 | F39: 1547.9528 | G39: 2595.9228 | H39: 2316.5901 | I39: 1031.3238 | J39: 262.34287 | K39: -123.97782 | L39: 412.0297 | M39: -264.50799 | N39: 1050.4914 | P39: 10486.063
