Workbook

Sheet 1

Sheet Annual Summary
D17: 2023 | E17: =+D17+1 -> 2024 | F17: =+E17+1 -> 2025 | G17: =+F17+1 -> 2026 | H17: =+G17+1 -> 2027 | I17: =+H17+1 -> 2028 | J17: =+I17+1 -> 2029 | K17: =+J17+1 -> 2030
C19: Service Income | D19: =SUMIF('Monthly Detail'!$1:$1,'Annual Summary'!D$17, 'Monthly Detail'!9:9) -> 0 | E19: =SUMIF('Monthly Detail'!$1:$1,'Annual Summary'!E$17, 'Monthly Detail'!9:9) -> 79769.25 | F19: =SUMIF('Monthly Detail'!$1:$1,'Annual Summary'!F$17, 'Monthly Detail'!9:9) -> 82031.193 | G19: =SUMIF('Monthly Detail'!$1:$1,'Annual Summary'!G$17, 'Monthly Detail'!9:9) -> 113510.87 | H19: =SUMIF('Monthly Detail'!$1:$1,'Annual Summary'!H$17, 'Monthly Detail'!9:9) -> 128937.72 | I19: =SUMIF('Monthly Detail'!$1:$1,'Annual Summary'!I$17, 'Monthly Detail'!9:9) -> 138359.44 | J19: =SUMIF('Monthly Detail'!$1:$1,'Annual Summary'!J$17, 'Monthly Detail'!9:9) -> 150416.49 | K19: =SUMIF('Monthly Detail'!$1:$1,'Annual Summary'!K$17, 'Monthly Detail'!9:9) -> 164244.7
C20: Misc | D20: =SUMIF('Monthly Detail'!$1:$1,'Annual Summary'!D$17, 'Monthly Detail'!12:12) -> 0 | E20: =SUMIF('Monthly Detail'!$1:$1,'Annual Summary'!E$17, 'Monthly Detail'!12:12) -> 0 | F20: =SUMIF('Monthly Detail'!$1:$1,'Annual Summary'!F$17, 'Monthly Detail'!12:12) -> 0 | G20: =SUMIF('Monthly Detail'!$1:$1,'Annual Summary'!G$17, 'Monthly Detail'!12:12) -> 0 | H20: =SUMIF('Monthly Detail'!$1:$1,'Annual Summary'!H$17, 'Monthly Detail'!12:12) -> 0 | I20: =SUMIF('Monthly Detail'!$1:$1,'Annual Summary'!I$17, 'Monthly Detail'!12:12) -> 0 | J20: =SUMIF('Monthly Detail'!$1:$1,'Annual Summary'!J$17, 'Monthly Detail'!12:12) -> 0 | K20: =SUMIF('Monthly Detail'!$1:$1,'Annual Summary'!K$17, 'Monthly Detail'!12:12) -> 0
C21: Total Income | D21: =SUM(D19:D20) -> 0 | E21: =SUM(E19:E20) -> 79769.25 | F21: =SUM(F19:F20) -> 82031.193 | G21: =SUM(G19:G20) -> 113510.87 | H21: =SUM(H19:H20) -> 128937.72 | I21: =SUM(I19:I20) -> 138359.44 | J21: =SUM(J19:J20) -> 150416.49 | K21: =SUM(K19:K20) -> 164244.7
C22: # of Appointments | D22: =SUMIF('Monthly Detail'!$1:$1,'Annual Summary'!D$17, 'Monthly Detail'!15:15) -> 1088 | E22: =SUMIF('Monthly Detail'!$1:$1,'Annual Summary'!E$17, 'Monthly Detail'!15:15) -> 833 | F22: =SUMIF('Monthly Detail'!$1:$1,'Annual Summary'!F$17, 'Monthly Detail'!15:15) -> 823.83791 | G22: =SUMIF('Monthly Detail'!$1:$1,'Annual Summary'!G$17, 'Monthly Detail'!15:15) -> 997.16095 | H22: =SUMIF('Monthly Detail'!$1:$1,'Annual Summary'!H$17, 'Monthly Detail'!15:15) -> 1076.9747 | I22: =SUMIF('Monthly Detail'!$1:$1,'Annual Summary'!I$17, 'Monthly Detail'!15:15) -> 1102.8888 | J22: =SUMIF('Monthly Detail'!$1:$1,'Annual Summary'!J$17, 'Monthly Detail'!15:15) -> 1138.7201 | K22: =SUMIF('Monthly Detail'!$1:$1,'Annual Summary'!K$17, 'Monthly Detail'!15:15) -> 1186.4584
C23: MRR | D23: =AVERAGEIF('Monthly Detail'!$1:$1,'Annual Summary'!D$17, 'Monthly Detail'!41:41) -> 0 | E23: =AVERAGEIF('Monthly Detail'!$1:$1,'Annual Summary'!E$17, 'Monthly Detail'!41:41) -> 3744.252 | F23: =AVERAGEIF('Monthly Detail'!$1:$1,'Annual Summary'!F$17, 'Monthly Detail'!41:41) -> 4298.4094 | G23: =AVERAGEIF('Monthly Detail'!$1:$1,'Annual Summary'!G$17, 'Monthly Detail'!41:41) -> 6602.9901 | H23: =AVERAGEIF('Monthly Detail'!$1:$1,'Annual Summary'!H$17, 'Monthly Detail'!41:41) -> 7494.9596 | I23: =AVERAGEIF('Monthly Detail'!$1:$1,'Annual Summary'!I$17, 'Monthly Detail'!41:41) -> 8040.0702 | J23: =AVERAGEIF('Monthly Detail'!$1:$1,'Annual Summary'!J$17, 'Monthly Detail'!41:41) -> 8743.7632 | K23: =AVERAGEIF('Monthly Detail'!$1:$1,'Annual Summary'!K$17, 'Monthly Detail'!41:41) -> 9548.028
C24: Recurring Client Base | D24: =AVERAGEIF('Monthly Detail'!$1:$1,'Annual Summary'!D$17, 'Monthly Detail'!17:17) -> 72.75 | E24: =AVERAGEIF('Monthly Detail'!$1:$1,'Annual Summary'!E$17, 'Monthly Detail'!17:17) -> 29.333333 | F24: =AVERAGEIF('Monthly Detail'!$1:$1,'Annual Summary'!F$17, 'Monthly Detail'!17:17) -> 32.715731 | G24: =AVERAGEIF('Monthly Detail'!$1:$1,'Annual Summary'!G$17, 'Monthly Detail'!17:17) -> 44.013187 | H24: =AVERAGEIF('Monthly Detail'!$1:$1,'Annual Summary'!H$17, 'Monthly Detail'!17:17) -> 47.561091 | I24: =AVERAGEIF('Monthly Detail'!$1:$1,'Annual Summary'!I$17, 'Monthly Detail'!17:17) -> 48.711763 | J24: =AVERAGEIF('Monthly Detail'!$1:$1,'Annual Summary'!J$17, 'Monthly Detail'!17:17) -> 50.293936 | K24: =AVERAGEIF('Monthly Detail'!$1:$1,'Annual Summary'!K$17, 'Monthly Detail'!17:17) -> 52.403501
C25: YOY Compounded Growth % | E25: - | F25: =(F21/E21)-1 -> 0.028356071 | G25: =(G21/F21)-1 -> 0.38375255 | H25: =(H21/G21)-1 -> 0.13590636 | I25: =(I21/H21)-1 -> 0.073071833 | J25: =(J21/I21)-1 -> 0.087142953 | K25: =(K21/J21)-1 -> 0.091932834
C27: Materials - COGS | D27: =SUMIF('Monthly Detail'!$1:$1,'Annual Summary'!D$17, 'Monthly Detail'!58:58) -> 0 | E27: =SUMIF('Monthly Detail'!$1:$1,'Annual Summary'!E$17, 'Monthly Detail'!58:58) -> 2199.12 | F27: =SUMIF('Monthly Detail'!$1:$1,'Annual Summary'!F$17, 'Monthly Detail'!58:58) -> 2649.577 | G27: =SUMIF('Monthly Detail'!$1:$1,'Annual Summary'!G$17, 'Monthly Detail'!58:58) -> 3895.7285 | H27: =SUMIF('Monthly Detail'!$1:$1,'Annual Summary'!H$17, 'Monthly Detail'!58:58) -> 4425.1828 | I27: =SUMIF('Monthly Detail'!$1:$1,'Annual Summary'!I$17, 'Monthly Detail'!58:58) -> 4748.539 | J27: =SUMIF('Monthly Detail'!$1:$1,'Annual Summary'!J$17, 'Monthly Detail'!58:58) -> 5162.3407 | K27: =SUMIF('Monthly Detail'!$1:$1,'Annual Summary'!K$17, 'Monthly Detail'!58:58) -> 5636.9293
C28: Software - COS | D28: =SUMIF('Monthly Detail'!$1:$1,'Annual Summary'!D$17, 'Monthly Detail'!59:59) -> 0 | E28: =SUMIF('Monthly Detail'!$1:$1,'Annual Summary'!E$17, 'Monthly Detail'!59:59) -> 3885.61 | F28: =SUMIF('Monthly Detail'!$1:$1,'Annual Summary'!F$17, 'Monthly Detail'!59:59) -> 7064.2451 | G28: =SUMIF('Monthly Detail'!$1:$1,'Annual Summary'!G$17, 'Monthly Detail'!59:59) -> 10985.43 | H28: =SUMIF('Monthly Detail'!$1:$1,'Annual Summary'!H$17, 'Monthly Detail'!59:59) -> 12478.42 | I28: =SUMIF('Monthly Detail'!$1:$1,'Annual Summary'!I$17, 'Monthly Detail'!59:59) -> 13390.241 | J28: =SUMIF('Monthly Detail'!$1:$1,'Annual Summary'!J$17, 'Monthly Detail'!59:59) -> 14557.106 | K28: =SUMIF('Monthly Detail'!$1:$1,'Annual Summary'!K$17, 'Monthly Detail'!59:59) -> 15895.382
C29: Contractors - COS | D29: =SUMIF('Monthly Detail'!$1:$1,'Annual Summary'!D$17, 'Monthly Detail'!60:60) -> 0 | E29: =SUMIF('Monthly Detail'!$1:$1,'Annual Summary'!E$17, 'Monthly Detail'!60:60) -> 4126 | F29: =SUMIF('Monthly Detail'!$1:$1,'Annual Summary'!F$17, 'Monthly Detail'!60:60) -> 1087.4616 | G29: =SUMIF('Monthly Detail'!$1:$1,'Annual Summary'!G$17, 'Monthly Detail'!60:60) -> 16577.435 | H29: =SUMIF('Monthly Detail'!$1:$1,'Annual Summary'!H$17, 'Monthly Detail'!60:60) -> 19131.508 | I29: =SUMIF('Monthly Detail'!$1:$1,'Annual Summary'!I$17, 'Monthly Detail'!60:60) -> 19873.575 | J29: =SUMIF('Monthly Detail'!$1:$1,'Annual Summary'!J$17, 'Monthly Detail'!60:60) -> 21094.466 | K29: =SUMIF('Monthly Detail'!$1:$1,'Annual Summary'!K$17, 'Monthly Detail'!60:60) -> 22521.559
C30: Total Cost of Goods Sold (COGS) | D30: =SUM(D27:D29) -> 0 | E30: =SUM(E27:E29) -> 10210.73 | F30: =SUM(F27:F29) -> 10801.284 | G30: =SUM(G27:G29) -> 31458.594 | H30: =SUM(H27:H29) -> 36035.11 | I30: =SUM(I27:I29) -> 38012.355 | J30: =SUM(J27:J29) -> 40813.913 | K30: =SUM(K27:K29) -> 44053.871
C32: Gross Margin | D32: =D21-D30 -> 0 | E32: =E21-E30 -> 69558.52 | F32: =F21-F30 -> 71229.909 | G32: =G21-G30 -> 82052.278 | H32: =H21-H30 -> 92902.611 | I32: =I21-I30 -> 100347.08 | J32: =J21-J30 -> 109602.57 | K32: =K21-K30 -> 120190.83
C33: GM % | D33: =+D32/D21 -> #DIV/0! | E33: =+E32/E21 -> 0.87199667 | F33: =+F32/F21 -> 0.86832712 | G33: =+G32/G21 -> 0.72285832 | H33: =+H32/H21 -> 0.72052313 | I33: =+I32/I21 -> 0.72526374 | J33: =+J32/J21 -> 0.72866064 | K33: =+K32/K21 -> 0.73177904
C35: General & Admintrative Expenses | D35: =SUMIF('Monthly Detail'!$1:$1,'Annual Summary'!D$17, 'Monthly Detail'!$89:$89) -> 0 | E35: =SUMIF('Monthly Detail'!$1:$1,'Annual Summary'!E$17, 'Monthly Detail'!$89:$89)+SUMIF('Monthly Detail'!$1:$1,'Annual Summary'!E$17, 'Monthly Detail'!$90:$90) -> 22587.09 | F35: =SUMIF('Monthly Detail'!$1:$1,'Annual Summary'!F$17, 'Monthly Detail'!$89:$89)+SUMIF('Monthly Detail'!$1:$1,'Annual Summary'!F$17, 'Monthly Detail'!$90:$90) -> 44835.533 | G35: =SUMIF('Monthly Detail'!$1:$1,'Annual Summary'!G$17, 'Monthly Detail'!$89:$89)+SUMIF('Monthly Detail'!$1:$1,'Annual Summary'!G$17, 'Monthly Detail'!$90:$90) -> 65746.482 | H35: =SUMIF('Monthly Detail'!$1:$1,'Annual Summary'!H$17, 'Monthly Detail'!$89:$89)+SUMIF('Monthly Detail'!$1:$1,'Annual Summary'!H$17, 'Monthly Detail'!$90:$90) -> 70324.804 | I35: =SUMIF('Monthly Detail'!$1:$1,'Annual Summary'!I$17, 'Monthly Detail'!$89:$89)+SUMIF('Monthly Detail'!$1:$1,'Annual Summary'!I$17, 'Monthly Detail'!$90:$90) -> 75294.834 | J35: =SUMIF('Monthly Detail'!$1:$1,'Annual Summary'!J$17, 'Monthly Detail'!$89:$89) -> 80692.436 | K35: =SUMIF('Monthly Detail'!$1:$1,'Annual Summary'!K$17, 'Monthly Detail'!$89:$89) -> 86556.896
C36: Operating Expense | D36: =SUM(D35:D35) -> 0 | E36: =SUM(E35:E35) -> 22587.09 | F36: =SUM(F35:F35) -> 44835.533 | G36: =SUM(G35:G35) -> 65746.482 | H36: =SUM(H35:H35) -> 70324.804 | I36: =SUM(I35:I35) -> 75294.834 | J36: =SUM(J35:J35) -> 80692.436 | K36: =SUM(K35:K35) -> 86556.896
C38: Net Operating Income (EBITDA) | D38: =D32-D36 -> 0 | E38: =E32-E36 -> 46971.43 | F38: =F32-F36 -> 26394.376 | G38: =G32-G36 -> 16305.796 | H38: =H32-H36 -> 22577.806 | I38: =I32-I36 -> 25052.248 | J38: =J32-J36 -> 28910.137 | K38: =K32-K36 -> 33633.934
C39: EBITDA % | D39: =D38/D21 -> #DIV/0! | E39: =E38/E21 -> 0.58884131 | F39: =F38/F21 -> 0.32176023 | G39: =G38/G21 -> 0.14364964 | H39: =H38/H21 -> 0.17510629 | I39: =I38/I21 -> 0.18106642 | J39: =J38/J21 -> 0.19220059 | K39: =K38/K21 -> 0.20477942
C41: Other Income / (Expense) | D41: =SUMIF('Monthly Detail'!$1:$1,'Annual Summary'!D$17, 'Monthly Detail'!95:95) -> 0 | E41: =SUMIF('Monthly Detail'!$1:$1,'Annual Summary'!E$17, 'Monthly Detail'!95:95) -> 0 | F41: =SUMIF('Monthly Detail'!$1:$1,'Annual Summary'!F$17, 'Monthly Detail'!95:95) -> 29.08 | G41: =SUMIF('Monthly Detail'!$1:$1,'Annual Summary'!G$17, 'Monthly Detail'!95:95) -> 19.44 | H41: =SUMIF('Monthly Detail'!$1:$1,'Annual Summary'!H$17, 'Monthly Detail'!95:95) -> 19.44 | I41: =SUMIF('Monthly Detail'!$1:$1,'Annual Summary'!I$17, 'Monthly Detail'!95:95) -> 19.44 | J41: =SUMIF('Monthly Detail'!$1:$1,'Annual Summary'!J$17, 'Monthly Detail'!95:95) -> 19.44 | K41: =SUMIF('Monthly Detail'!$1:$1,'Annual Summary'!K$17, 'Monthly Detail'!95:95) -> 19.44
C42: Net Income | D42: =D38+D41 -> 0 | E42: =E38+E41 -> 46971.43 | F42: =F38+F41 -> 26423.456 | G42: =G38+G41 -> 16325.236 | H42: =H38+H41 -> 22597.246 | I42: =I38+I41 -> 25071.688 | J42: =J38+J41 -> 28929.577 | K42: =K38+K41 -> 33653.374
C43: NI % | D43: =D42/D21 -> #DIV/0! | E43: =E42/E21 -> 0.58884131 | F43: =F42/F21 -> 0.32211473 | G43: =G42/G21 -> 0.1438209 | H43: =H42/H21 -> 0.17525706 | I43: =I42/I21 -> 0.18120692 | J43: =J42/J21 -> 0.19232983 | K43: =K42/K21 -> 0.20489778
C44: Estimated Tax Burden | D44: =+IF(D42>0, D42*0.25, 0) -> 0 | E44: =+IF(E42>0, E42*0.25, 0) -> 11742.858 | F44: =+IF(F42>0, F42*0.25, 0) -> 6605.8639 | G44: =+IF(G42>0, G42*0.25, 0) -> 4081.3091 | H44: =+IF(H42>0, H42*0.25, 0) -> 5649.3116 | I44: =+IF(I42>0, I42*0.25, 0) -> 6267.9219 | J44: =+IF(J42>0, J42*0.25, 0) -> 7232.3943 | K44: =+IF(K42>0, K42*0.25, 0) -> 8413.3435
C45: Cash Balance | D45: #VALUE! | E45: =+SUMIF('Monthly Detail'!$4:$4, DATE(E17, 12, 31),'Monthly Detail'!$173:$173) -> 1426 | F45: =+SUMIF('Monthly Detail'!$4:$4, DATE(F17, 12, 31),'Monthly Detail'!$173:$173) -> 6291.9628 | G45: =+SUMIF('Monthly Detail'!$4:$4, DATE(G17, 12, 31),'Monthly Detail'!$173:$173) -> 20692.205 | H45: =+SUMIF('Monthly Detail'!$4:$4, DATE(H17, 12, 31),'Monthly Detail'!$173:$173) -> 41468.659 | I45: =+SUMIF('Monthly Detail'!$4:$4, DATE(I17, 12, 31),'Monthly Detail'!$173:$173) -> 64748.761 | J45: =+SUMIF('Monthly Detail'!$4:$4, DATE(J17, 12, 31),'Monthly Detail'!$173:$173) -> 91846.04 | K45: =+SUMIF('Monthly Detail'!$4:$4, DATE(K17, 12, 31),'Monthly Detail'!$173:$173) -> 123652.21

Sheet 2023 Overview
C10: =TEXT('Monthly Detail'!D4,"mmmm") -> January | D10: =TEXT('Monthly Detail'!E4,"mmmm") -> February | E10: =TEXT('Monthly Detail'!F4,"mmmm") -> March | F10: =TEXT('Monthly Detail'!G4,"mmmm") -> April | G10: =TEXT('Monthly Detail'!H4,"mmmm") -> May | H10: =TEXT('Monthly Detail'!I4,"mmmm") -> June | I10: =TEXT('Monthly Detail'!J4,"mmmm") -> July | J10: =TEXT('Monthly Detail'!K4,"mmmm") -> August | ... N10: =TEXT('Monthly Detail'!O4,"mmmm") -> December | P10: Total
C11: 44957 | D11: 44985 | E11: 45016 | F11: 45046 | G11: 45077 | H11: 45107 | I11: 45138 | J11: 45169 | K11: 45199 | L11: 45230 | M11: 45260 | N11: 45291 | O11: 45322
B12: Service Income | C12: =SUMIF('Monthly Detail'!$4:$4, '2023 Overview'!C$11, 'Monthly Detail'!9:9) -> 0 | D12: =SUMIF('Monthly Detail'!$4:$4, '2023 Overview'!D$11, 'Monthly Detail'!9:9) -> 0 | E12: =SUMIF('Monthly Detail'!$4:$4, '2023 Overview'!E$11, 'Monthly Detail'!9:9) -> 0 | F12: =SUMIF('Monthly Detail'!$4:$4, '2023 Overview'!F$11, 'Monthly Detail'!9:9) -> 0 | G12: =SUMIF('Monthly Detail'!$4:$4, '2023 Overview'!G$11, 'Monthly Detail'!9:9) -> 0 | H12: =SUMIF('Monthly Detail'!$4:$4, '2023 Overview'!H$11, 'Monthly Detail'!9:9) -> 0 | I12: =SUMIF('Monthly Detail'!$4:$4, '2023 Overview'!I$11, 'Monthly Detail'!9:9) -> 0 | J12: =SUMIF('Monthly Detail'!$4:$4, '2023 Overview'!J$11, 'Monthly Detail'!9:9) -> 0 | ... N12: =SUMIF('Monthly Detail'!$4:$4, '2023 Overview'!N$11, 'Monthly Detail'!9:9) -> 0 | P12: =SUM(C12:O12) -> 0
B13: Misc. | C13: =SUMIF('Monthly Detail'!$4:$4, '2023 Overview'!C$11, 'Monthly Detail'!12:12) -> 0 | D13: =SUMIF('Monthly Detail'!$4:$4, '2023 Overview'!D$11, 'Monthly Detail'!12:12) -> 0 | E13: =SUMIF('Monthly Detail'!$4:$4, '2023 Overview'!E$11, 'Monthly Detail'!12:12) -> 0 | F13: =SUMIF('Monthly Detail'!$4:$4, '2023 Overview'!F$11, 'Monthly Detail'!12:12) -> 0 | G13: =SUMIF('Monthly Detail'!$4:$4, '2023 Overview'!G$11, 'Monthly Detail'!12:12) -> 0 | H13: =SUMIF('Monthly Detail'!$4:$4, '2023 Overview'!H$11, 'Monthly Detail'!12:12) -> 0 | I13: =SUMIF('Monthly Detail'!$4:$4, '2023 Overview'!I$11, 'Monthly Detail'!12:12) -> 0 | J13: =SUMIF('Monthly Detail'!$4:$4, '2023 Overview'!J$11, 'Monthly Detail'!12:12) -> 0 | ... N13: =SUMIF('Monthly Detail'!$4:$4, '2023 Overview'!N$11, 'Monthly Detail'!12:12) -> 0
B14: Total Income | C14: =SUM(C12:C13) -> 0 | D14: =SUM(D12:D13) -> 0 | E14: =SUM(E12:E13) -> 0 | F14: =SUM(F12:F13) -> 0 | G14: =SUM(G12:G13) -> 0 | H14: =SUM(H12:H13) -> 0 | I14: =SUM(I12:I13) -> 0 | J14: =SUM(J12:J13) -> 0 | ... N14: =SUM(N12:N13) -> 0 | P14: =SUM(P12:P12) -> 0
B16: Gross Margin | C16: =C14 -> 0 | D16: =D14 -> 0 | E16: =E14 -> 0 | F16: =F14 -> 0 | G16: =G14 -> 0 | H16: =H14 -> 0 | I16: =I14 -> 0 | J16: =J14 -> 0 | ... N16: =N14 -> 0 | P16: =P14 -> 0
B17: GM % | C17: =C16/C14 -> #DIV/0! | D17: =D16/D14 -> #DIV/0! | E17: =E16/E14 -> #DIV/0! | F17: =F16/F14 -> #DIV/0! | G17: =G16/G14 -> #DIV/0! | H17: =H16/H14 -> #DIV/0! | I17: =I16/I14 -> #DIV/0! | J17: =J16/J14 -> #DIV/0! | ... N17: =N16/N14 -> #DIV/0! | P17: =P16/P14 -> #DIV/0!
B19: General & Admintrative Expenses | C19: =SUMIF('Monthly Detail'!$4:$4, '2023 Overview'!C$11, 'Monthly Detail'!$89:$89) -> 0 | D19: =SUMIF('Monthly Detail'!$4:$4, '2023 Overview'!D$11, 'Monthly Detail'!$89:$89) -> 0 | E19: =SUMIF('Monthly Detail'!$4:$4, '2023 Overview'!E$11, 'Monthly Detail'!$89:$89) -> 0 | F19: =SUMIF('Monthly Detail'!$4:$4, '2023 Overview'!F$11, 'Monthly Detail'!$89:$89) -> 0 | G19: =SUMIF('Monthly Detail'!$4:$4, '2023 Overview'!G$11, 'Monthly Detail'!$89:$89) -> 0 | H19: =SUMIF('Monthly Detail'!$4:$4, '2023 Overview'!H$11, 'Monthly Detail'!$89:$89) -> 0 | I19: =SUMIF('Monthly Detail'!$4:$4, '2023 Overview'!I$11, 'Monthly Detail'!$89:$89) -> 0 | J19: =SUMIF('Monthly Detail'!$4:$4, '2023 Overview'!J$11, 'Monthly Detail'!$89:$89) -> 0 | ... N19: =SUMIF('Monthly Detail'!$4:$4, '2023 Overview'!N$11, 'Monthly Detail'!$89:$89) -> 0 | P19: =SUM(C19:O19) -> 0
B20: Operating Expenses | C20: =SUM(C19:C19) -> 0 | D20: =SUM(D19:D19) -> 0 | E20: =SUM(E19:E19) -> 0 | F20: =SUM(F19:F19) -> 0 | G20: =SUM(G19:G19) -> 0 | H20: =SUM(H19:H19) -> 0 | I20: =SUM(I19:I19) -> 0 | J20: =SUM(J19:J19) -> 0 | ... N20: =SUM(N19:N19) -> 0 | P20: =SUM(P19:P19) -> 0
B22: Net Operating Income (EBITDA) | C22: =C16-C20 -> 0 | D22: =D16-D20 -> 0 | E22: =E16-E20 -> 0 | F22: =F16-F20 -> 0 | G22: =G16-G20 -> 0 | H22: =H16-H20 -> 0 | I22: =I16-I20 -> 0 | J22: =J16-J20 -> 0 | ... N22: =N16-N20 -> 0 | P22: =P16-P20 -> 0
B23: EBITDA % | C23: =C22/C14 -> #DIV/0! | D23: =D22/D14 -> #DIV/0! | E23: =E22/E14 -> #DIV/0! | F23: =F22/F14 -> #DIV/0! | G23: =G22/G14 -> #DIV/0! | H23: =H22/H14 -> #DIV/0! | I23: =I22/I14 -> #DIV/0! | J23: =J22/J14 -> #DIV/0! | ... N23: =N22/N14 -> #DIV/0! | P23: =P22/P14 -> #DIV/0!
B25: Other Income / (Expense) | C25: =SUMIF('Monthly Detail'!$4:$4, '2023 Overview'!C$11, 'Monthly Detail'!95:95) -> 0 | D25: =SUMIF('Monthly Detail'!$4:$4, '2023 Overview'!D$11, 'Monthly Detail'!95:95) -> 0 | E25: =SUMIF('Monthly Detail'!$4:$4, '2023 Overview'!E$11, 'Monthly Detail'!95:95) -> 0 | F25: =SUMIF('Monthly Detail'!$4:$4, '2023 Overview'!F$11, 'Monthly Detail'!95:95) -> 0 | G25: =SUMIF('Monthly Detail'!$4:$4, '2023 Overview'!G$11, 'Monthly Detail'!95:95) -> 0 | H25: =SUMIF('Monthly Detail'!$4:$4, '2023 Overview'!H$11, 'Monthly Detail'!95:95) -> 0 | I25: =SUMIF('Monthly Detail'!$4:$4, '2023 Overview'!I$11, 'Monthly Detail'!95:95) -> 0 | J25: =SUMIF('Monthly Detail'!$4:$4, '2023 Overview'!J$11, 'Monthly Detail'!95:95) -> 0 | ... N25: =SUMIF('Monthly Detail'!$4:$4, '2023 Overview'!N$11, 'Monthly Detail'!95:95) -> 0 | P25: =SUM(C25:O25) -> 0
B26: Net Income | C26: =C22+SUM(C25:C25) -> 0 | D26: =D22+SUM(D25:D25) -> 0 | E26: =E22+SUM(E25:E25) -> 0 | F26: =F22+SUM(F25:F25) -> 0 | G26: =G22+SUM(G25:G25) -> 0 | H26: =H22+SUM(H25:H25) -> 0 | I26: =I22+SUM(I25:I25) -> 0 | J26: =J22+SUM(J25:J25) -> 0 | ... N26: =N22+SUM(N25:N25) -> 0 | P26: =P22+SUM(P25:P25) -> 0
B27: NI % | C27: =C26/C14 -> #DIV/0! | D27: =D26/D14 -> #DIV/0! | E27: =E26/E14 -> #DIV/0! | F27: =F26/F14 -> #DIV/0! | G27: =G26/G14 -> #DIV/0! | H27: =H26/H14 -> #DIV/0! | I27: =I26/I14 -> #DIV/0! | J27: =J26/J14 -> #DIV/0! | ... N27: =N26/N14 -> #DIV/0! | P27: =P26/P14 -> #DIV/0!
B29: Operating Cash | C29: =SUMIF('Monthly Detail'!$4:$4, '2023 Overview'!C$11, 'Monthly Detail'!173:173) -> 0 | D29: =SUMIF('Monthly Detail'!$4:$4, '2023 Overview'!D$11, 'Monthly Detail'!173:173) -> 0 | E29: =SUMIF('Monthly Detail'!$4:$4, '2023 Overview'!E$11, 'Monthly Detail'!173:173) -> 0 | F29: =SUMIF('Monthly Detail'!$4:$4, '2023 Overview'!F$11, 'Monthly Detail'!173:173) -> 0 | G29: =SUMIF('Monthly Detail'!$4:$4, '2023 Overview'!G$11, 'Monthly Detail'!173:173) -> 0 | H29: =SUMIF('Monthly Detail'!$4:$4, '2023 Overview'!H$11, 'Monthly Detail'!173:173) -> 0 | I29: =SUMIF('Monthly Detail'!$4:$4, '2023 Overview'!I$11, 'Monthly Detail'!173:173) -> 0 | J29: =SUMIF('Monthly Detail'!$4:$4, '2023 Overview'!J$11, 'Monthly Detail'!173:173) -> 0 | ... N29: =SUMIF('Monthly Detail'!$4:$4, '2023 Overview'!N$11, 'Monthly Detail'!173:173) -> 0
B30: Cash Inflow (Outflow) | C30: =SUMIF('Monthly Detail'!$4:$4, '2023 Overview'!C$11, 'Monthly Detail'!170:170) -> 0 | D30: =SUMIF('Monthly Detail'!$4:$4, '2023 Overview'!D$11, 'Monthly Detail'!170:170) -> 0 | E30: =SUMIF('Monthly Detail'!$4:$4, '2023 Overview'!E$11, 'Monthly Detail'!170:170) -> 0 | F30: =SUMIF('Monthly Detail'!$4:$4, '2023 Overview'!F$11, 'Monthly Detail'!170:170) -> 0 | G30: =SUMIF('Monthly Detail'!$4:$4, '2023 Overview'!G$11, 'Monthly Detail'!170:170) -> 0 | H30: =SUMIF('Monthly Detail'!$4:$4, '2023 Overview'!H$11, 'Monthly Detail'!170:170) -> 0 | I30: =SUMIF('Monthly Detail'!$4:$4, '2023 Overview'!I$11, 'Monthly Detail'!170:170) -> 0 | J30: =SUMIF('Monthly Detail'!$4:$4, '2023 Overview'!J$11, 'Monthly Detail'!170:170) -> 0 | ... N30: =SUMIF('Monthly Detail'!$4:$4, '2023 Overview'!N$11, 'Monthly Detail'!170:170) -> 0

Sheet 2025 Overview (Budget)
B15: 2025 Overview (Annual Operating Plan)
C18: January | D18: February | E18: March | F18: April | G18: May | H18: June | I18: July | J18: August | K18: September | L18: October | M18: November | N18: December | P18: Total
C19: 45688 | D19: 45716 | E19: 45747 | F19: 45777 | G19: 45808 | H19: 45838 | I19: 45869 | J19: 45900 | K19: 45930 | L19: 45961 | M19: 45991 | N19: 46022 | O19: 45322
B20: Service Income | C20: =SUMIF('Monthly Detail'!$4:$4, '2025 Overview (Budget)'!C$19, 'Monthly Detail'!13:13) -> 6721.05 | D20: =SUMIF('Monthly Detail'!$4:$4, '2025 Overview (Budget)'!D$19, 'Monthly Detail'!13:13) -> 6501.14 | E20: =SUMIF('Monthly Detail'!$4:$4, '2025 Overview (Budget)'!E$19, 'Monthly Detail'!13:13) -> 7108.5 | F20: =SUMIF('Monthly Detail'!$4:$4, '2025 Overview (Budget)'!F$19, 'Monthly Detail'!13:13) -> 7861.75 | G20: =SUMIF('Monthly Detail'!$4:$4, '2025 Overview (Budget)'!G$19, 'Monthly Detail'!13:13) -> 7877.62 | H20: =SUMIF('Monthly Detail'!$4:$4, '2025 Overview (Budget)'!H$19, 'Monthly Detail'!13:13) -> 6887.45 | I20: =SUMIF('Monthly Detail'!$4:$4, '2025 Overview (Budget)'!I$19, 'Monthly Detail'!13:13) -> 7418.55 | J20: =SUMIF('Monthly Detail'!$4:$4, '2025 Overview (Budget)'!J$19, 'Monthly Detail'!13:13) -> 7653.35 | ... M20: =SUMIF('Monthly Detail'!$4:$4, '2025 Overview (Budget)'!M$19, 'Monthly Detail'!13:13) -> 5263 | N20: =+'2025 AOP'!N20 -> 8571.1673 | P20: =SUM(C20:O20) -> 85032.277
B21: Misc. | C21: =SUMIF('Monthly Detail'!$4:$4, '2025 Overview (Budget)'!C$19, 'Monthly Detail'!12:12) -> 0 | D21: =SUMIF('Monthly Detail'!$4:$4, '2025 Overview (Budget)'!D$19, 'Monthly Detail'!12:12) -> 0 | E21: =SUMIF('Monthly Detail'!$4:$4, '2025 Overview (Budget)'!E$19, 'Monthly Detail'!12:12) -> 0 | F21: =SUMIF('Monthly Detail'!$4:$4, '2025 Overview (Budget)'!F$19, 'Monthly Detail'!12:12) -> 0 | G21: =SUMIF('Monthly Detail'!$4:$4, '2025 Overview (Budget)'!G$19, 'Monthly Detail'!12:12) -> 0 | H21: =SUMIF('Monthly Detail'!$4:$4, '2025 Overview (Budget)'!H$19, 'Monthly Detail'!12:12) -> 0 | I21: =SUMIF('Monthly Detail'!$4:$4, '2025 Overview (Budget)'!I$19, 'Monthly Detail'!12:12) -> 0 | J21: =SUMIF('Monthly Detail'!$4:$4, '2025 Overview (Budget)'!J$19, 'Monthly Detail'!12:12) -> 0 | ... M21: =SUMIF('Monthly Detail'!$4:$4, '2025 Overview (Budget)'!M$19, 'Monthly Detail'!12:12) -> 0 | N21: =+'2025 AOP'!N21 -> 0 | P21: =SUM(C21:O21) -> 0
B22: Total Income | C22: =SUM(C20:C21) -> 6721.05 | D22: =SUM(D20:D21) -> 6501.14 | E22: =SUM(E20:E21) -> 7108.5 | F22: =SUM(F20:F21) -> 7861.75 | G22: =SUM(G20:G21) -> 7877.62 | H22: =SUM(H20:H21) -> 6887.45 | I22: =SUM(I20:I21) -> 7418.55 | J22: =SUM(J20:J21) -> 7653.35 | ... M22: =SUM(M20:M21) -> 5263 | N22: =+'2025 AOP'!N22 -> 8571.1673 | P22: =SUM(P20:P20) -> 85032.277
B23: # of Appointments | C23: =SUMIF('Monthly Detail'!$4:$4, '2025 Overview (Budget)'!C$19, 'Monthly Detail'!15:15) -> 66 | D23: =SUMIF('Monthly Detail'!$4:$4, '2025 Overview (Budget)'!D$19, 'Monthly Detail'!15:15) -> 69 | E23: =SUMIF('Monthly Detail'!$4:$4, '2025 Overview (Budget)'!E$19, 'Monthly Detail'!15:15) -> 68 | F23: =SUMIF('Monthly Detail'!$4:$4, '2025 Overview (Budget)'!F$19, 'Monthly Detail'!15:15) -> 82 | G23: =SUMIF('Monthly Detail'!$4:$4, '2025 Overview (Budget)'!G$19, 'Monthly Detail'!15:15) -> 83 | H23: =SUMIF('Monthly Detail'!$4:$4, '2025 Overview (Budget)'!H$19, 'Monthly Detail'!15:15) -> 72 | I23: =SUMIF('Monthly Detail'!$4:$4, '2025 Overview (Budget)'!I$19, 'Monthly Detail'!15:15) -> 76 | J23: =SUMIF('Monthly Detail'!$4:$4, '2025 Overview (Budget)'!J$19, 'Monthly Detail'!15:15) -> 73 | ... M23: =SUMIF('Monthly Detail'!$4:$4, '2025 Overview (Budget)'!M$19, 'Monthly Detail'!15:15) -> 57 | N23: =+'2025 AOP'!N23 -> 94.608295 | P23: =+SUM(C23:N23) -> 874.60829
B24: MRR | C24: =SUMIF('Monthly Detail'!$4:$4, '2025 Overview (Budget)'!C$19, 'Monthly Detail'!41:41) -> 4460.105 | D24: =SUMIF('Monthly Detail'!$4:$4, '2025 Overview (Budget)'!D$19, 'Monthly Detail'!41:41) -> 4123.6763 | E24: =SUMIF('Monthly Detail'!$4:$4, '2025 Overview (Budget)'!E$19, 'Monthly Detail'!41:41) -> 3775.4392 | F24: =SUMIF('Monthly Detail'!$4:$4, '2025 Overview (Budget)'!F$19, 'Monthly Detail'!41:41) -> 4062.1519 | G24: =SUMIF('Monthly Detail'!$4:$4, '2025 Overview (Budget)'!G$19, 'Monthly Detail'!41:41) -> 4083.8286 | H24: =SUMIF('Monthly Detail'!$4:$4, '2025 Overview (Budget)'!H$19, 'Monthly Detail'!41:41) -> 4773.1964 | I24: =SUMIF('Monthly Detail'!$4:$4, '2025 Overview (Budget)'!I$19, 'Monthly Detail'!41:41) -> 4270.3349 | J24: =SUMIF('Monthly Detail'!$4:$4, '2025 Overview (Budget)'!J$19, 'Monthly Detail'!41:41) -> 4966.1738 | ... M24: =SUMIF('Monthly Detail'!$4:$4, '2025 Overview (Budget)'!M$19, 'Monthly Detail'!41:41) -> 3575.4406 | N24: =+'2025 AOP'!N24 -> 6105.5718 | P24: =+AVERAGE(C24:N24) -> 4488.4881
B25: Recurring Client Base | C25: =SUMIF('Monthly Detail'!$4:$4, '2025 Overview (Budget)'!C$19, 'Monthly Detail'!17:17) -> 35 | D25: =SUMIF('Monthly Detail'!$4:$4, '2025 Overview (Budget)'!D$19, 'Monthly Detail'!17:17) -> 32 | E25: =SUMIF('Monthly Detail'!$4:$4, '2025 Overview (Budget)'!E$19, 'Monthly Detail'!17:17) -> 31 | F25: =SUMIF('Monthly Detail'!$4:$4, '2025 Overview (Budget)'!F$19, 'Monthly Detail'!17:17) -> 30 | G25: =SUMIF('Monthly Detail'!$4:$4, '2025 Overview (Budget)'!G$19, 'Monthly Detail'!17:17) -> 38 | H25: =SUMIF('Monthly Detail'!$4:$4, '2025 Overview (Budget)'!H$19, 'Monthly Detail'!17:17) -> 37 | I25: =SUMIF('Monthly Detail'!$4:$4, '2025 Overview (Budget)'!I$19, 'Monthly Detail'!17:17) -> 34 | J25: =SUMIF('Monthly Detail'!$4:$4, '2025 Overview (Budget)'!J$19, 'Monthly Detail'!17:17) -> 32 | ... M25: =SUMIF('Monthly Detail'!$4:$4, '2025 Overview (Budget)'!M$19, 'Monthly Detail'!17:17) -> 31 | N25: =+'2025 AOP'!N25 -> 49.208853
B28: Software - COS | C28: =SUMIF('Monthly Detail'!$4:$4, '2025 Overview (Budget)'!C$19, 'Monthly Detail'!58:58) -> 197.3 | D28: =SUMIF('Monthly Detail'!$4:$4, '2025 Overview (Budget)'!D$19, 'Monthly Detail'!58:58) -> 202.11 | E28: =SUMIF('Monthly Detail'!$4:$4, '2025 Overview (Budget)'!E$19, 'Monthly Detail'!58:58) -> 214.54 | F28: =SUMIF('Monthly Detail'!$4:$4, '2025 Overview (Budget)'!F$19, 'Monthly Detail'!58:58) -> 247.79 | G28: =SUMIF('Monthly Detail'!$4:$4, '2025 Overview (Budget)'!G$19, 'Monthly Detail'!58:58) -> 240.23 | H28: =SUMIF('Monthly Detail'!$4:$4, '2025 Overview (Budget)'!H$19, 'Monthly Detail'!58:58) -> 182.1 | I28: =SUMIF('Monthly Detail'!$4:$4, '2025 Overview (Budget)'!I$19, 'Monthly Detail'!58:58) -> 216.6 | J28: =SUMIF('Monthly Detail'!$4:$4, '2025 Overview (Budget)'!J$19, 'Monthly Detail'!58:58) -> 205.55 | ... M28: =SUMIF('Monthly Detail'!$4:$4, '2025 Overview (Budget)'!M$19, 'Monthly Detail'!58:58) -> 248.07 | N28: =+'2025 AOP'!N28 -> 253.81678 | P28: =+SUM(C28:N28) -> 2712.2268
B29: Materials - COGS | C29: =SUMIF('Monthly Detail'!$4:$4, '2025 Overview (Budget)'!C$19, 'Monthly Detail'!59:59) -> 249.98 | D29: =SUMIF('Monthly Detail'!$4:$4, '2025 Overview (Budget)'!D$19, 'Monthly Detail'!59:59) -> 497.5 | E29: =SUMIF('Monthly Detail'!$4:$4, '2025 Overview (Budget)'!E$19, 'Monthly Detail'!59:59) -> 810.15 | F29: =SUMIF('Monthly Detail'!$4:$4, '2025 Overview (Budget)'!F$19, 'Monthly Detail'!59:59) -> 352.78 | G29: =SUMIF('Monthly Detail'!$4:$4, '2025 Overview (Budget)'!G$19, 'Monthly Detail'!59:59) -> 754.25 | H29: =SUMIF('Monthly Detail'!$4:$4, '2025 Overview (Budget)'!H$19, 'Monthly Detail'!59:59) -> 503.73 | I29: =SUMIF('Monthly Detail'!$4:$4, '2025 Overview (Budget)'!I$19, 'Monthly Detail'!59:59) -> 588.11 | J29: =SUMIF('Monthly Detail'!$4:$4, '2025 Overview (Budget)'!J$19, 'Monthly Detail'!59:59) -> 768.16 | ... M29: =SUMIF('Monthly Detail'!$4:$4, '2025 Overview (Budget)'!M$19, 'Monthly Detail'!59:59) -> 528.58 | N29: =+'2025 AOP'!N29 -> 288.99182 | P29: =+SUM(C29:N29) -> 6814.1718
B30: Contractors - COS | C30: =SUMIF('Monthly Detail'!$4:$4, '2025 Overview (Budget)'!C$19, 'Monthly Detail'!60:60) -> 50 | D30: =SUMIF('Monthly Detail'!$4:$4, '2025 Overview (Budget)'!D$19, 'Monthly Detail'!60:60) -> 45 | E30: =SUMIF('Monthly Detail'!$4:$4, '2025 Overview (Budget)'!E$19, 'Monthly Detail'!60:60) -> 0 | F30: =SUMIF('Monthly Detail'!$4:$4, '2025 Overview (Budget)'!F$19, 'Monthly Detail'!60:60) -> 0 | G30: =SUMIF('Monthly Detail'!$4:$4, '2025 Overview (Budget)'!G$19, 'Monthly Detail'!60:60) -> 629 | H30: =SUMIF('Monthly Detail'!$4:$4, '2025 Overview (Budget)'!H$19, 'Monthly Detail'!60:60) -> 0 | I30: =SUMIF('Monthly Detail'!$4:$4, '2025 Overview (Budget)'!I$19, 'Monthly Detail'!60:60) -> 0 | J30: =SUMIF('Monthly Detail'!$4:$4, '2025 Overview (Budget)'!J$19, 'Monthly Detail'!60:60) -> 0 | ... M30: =SUMIF('Monthly Detail'!$4:$4, '2025 Overview (Budget)'!M$19, 'Monthly Detail'!60:60) -> 0 | N30: =+'2025 AOP'!N30 -> 680.08064 | P30: =+SUM(C30:N30) -> 1434.0806
B31: Total Cost of Goods Sold (COGS) | C31: =SUM(C28:C30) -> 497.28 | D31: =SUM(D28:D30) -> 744.61 | E31: =SUM(E28:E30) -> 1024.69 | F31: =SUM(F28:F30) -> 600.57 | G31: =SUM(G28:G30) -> 1623.48 | H31: =SUM(H28:H30) -> 685.83 | I31: =SUM(I28:I30) -> 804.71 | J31: =SUM(J28:J30) -> 973.71 | ... N31: =SUM(N28:N30) -> 1222.8892 | P31: =SUM(P28:P30) -> 10960.479
B33: Gross Margin | C33: =+C22-C31 -> 6223.77 | D33: =+D22-D31 -> 5756.53 | E33: =+E22-E31 -> 6083.81 | F33: =+F22-F31 -> 7261.18 | G33: =+G22-G31 -> 6254.14 | H33: =+H22-H31 -> 6201.62 | I33: =+I22-I31 -> 6613.84 | J33: =+J22-J31 -> 6679.64 | ... N33: =+N22-N31 -> 7348.278 | P33: =+SUM(C33:N33) -> 74071.798
B34: GM % | C34: =IFERROR(C33/C22, 0) -> 0.92601156 | D34: =IFERROR(D33/D22, 0) -> 0.8854647 | E34: =IFERROR(E33/E22, 0) -> 0.85585004 | F34: =IFERROR(F33/F22, 0) -> 0.92360861 | G34: =IFERROR(G33/G22, 0) -> 0.79391237 | H34: =IFERROR(H33/H22, 0) -> 0.90042323 | I34: =IFERROR(I33/I22, 0) -> 0.89152732 | J34: =IFERROR(J33/J22, 0) -> 0.87277336 | ... N34: =IFERROR(N33/N22, 0) -> 0.85732524 | P34: =P33/P22 -> 0.87110213
B36: General & Admintrative Expenses | C36: =SUMIF('Monthly Detail'!$4:$4, '2025 Overview (Budget)'!C$19, 'Monthly Detail'!$89:$89) -> 2161.9 | D36: =SUMIF('Monthly Detail'!$4:$4, '2025 Overview (Budget)'!D$19, 'Monthly Detail'!$89:$89) -> 3618.11 | E36: =SUMIF('Monthly Detail'!$4:$4, '2025 Overview (Budget)'!E$19, 'Monthly Detail'!$89:$89) -> 3644.83 | F36: =SUMIF('Monthly Detail'!$4:$4, '2025 Overview (Budget)'!F$19, 'Monthly Detail'!$89:$89) -> 5164.2 | G36: =SUMIF('Monthly Detail'!$4:$4, '2025 Overview (Budget)'!G$19, 'Monthly Detail'!$89:$89) -> 3990.04 | H36: =SUMIF('Monthly Detail'!$4:$4, '2025 Overview (Budget)'!H$19, 'Monthly Detail'!$89:$89) -> 3355.51 | I36: =SUMIF('Monthly Detail'!$4:$4, '2025 Overview (Budget)'!I$19, 'Monthly Detail'!$89:$89) -> 3680.41 | J36: =SUMIF('Monthly Detail'!$4:$4, '2025 Overview (Budget)'!J$19, 'Monthly Detail'!$89:$89) -> 3609.26 | K36: =SUMIF('Monthly Detail'!$4:$4, '2025 Overview (Budget)'!K$19, 'Monthly Detail'!$89:$89) -> 3143.78 | L36: =SUMIF('Monthly Detail'!$4:$4, '2025 Overview'!L$19, 'Monthly Detail'!$89:$89)+SUMIF('Monthly Detail'!$4:$4, '2025 Overview'!L$19, 'Monthly Detail'!$90:$90) -> 3847.73 | M36: =SUMIF('Monthly Detail'!$4:$4, '2025 Overview'!M$19, 'Monthly Detail'!$89:$89)+SUMIF('Monthly Detail'!$4:$4, '2025 Overview'!M$19, 'Monthly Detail'!$90:$90) -> 3504.03 | N36: =+'2025 AOP'!N36 -> 6297.7867 | P36: =SUM(C36:O36) -> 46017.587
B37: Operating Expenses | C37: =SUM(C36:C36) -> 2161.9 | D37: =SUM(D36:D36) -> 3618.11 | E37: =SUM(E36:E36) -> 3644.83 | F37: =SUM(F36:F36) -> 5164.2 | G37: =SUM(G36:G36) -> 3990.04 | H37: =SUM(H36:H36) -> 3355.51 | I37: =SUM(I36:I36) -> 3680.41 | J37: =SUM(J36:J36) -> 3609.26 | ... N37: =SUM(N36:N36) -> 6297.7867 | P37: =SUM(P36:P36) -> 46017.587
B39: Net Operating Income (EBITDA) | C39: =C33-C37 -> 4061.87 | D39: =D33-D37 -> 2138.42 | E39: =E33-E37 -> 2438.98 | F39: =F33-F37 -> 2096.98 | G39: =G33-G37 -> 2264.1 | H39: =H33-H37 -> 2846.11 | I39: =I33-I37 -> 2933.43 | J39: =J33-J37 -> 3070.38 | ... N39: =N33-N37 -> 1050.4914 | P39: =P33-P37 -> 28054.211
B40: EBITDA % | C40: =IFERROR(C39/C22, 0) -> 0.60435051 | D40: =IFERROR(D39/D22, 0) -> 0.32893 | E40: =IFERROR(E39/E22, 0) -> 0.34310755 | F40: =IFERROR(F39/F22, 0) -> 0.26673196 | G40: =IFERROR(G39/G22, 0) -> 0.28740914 | H40: =IFERROR(H39/H22, 0) -> 0.41323131 | I40: =IFERROR(I39/I22, 0) -> 0.39541824 | J40: =IFERROR(J39/J22, 0) -> 0.40118118 | ... N40: =IFERROR(N39/N22, 0) -> 0.12256106 | P40: =P39/P22 -> 0.32992426
B42: Other Income / (Expense) | C42: =SUMIF('Monthly Detail'!$4:$4, '2025 Overview (Budget)'!C$19, 'Monthly Detail'!95:95) -> 0 | D42: =SUMIF('Monthly Detail'!$4:$4, '2025 Overview (Budget)'!D$19, 'Monthly Detail'!95:95) -> 0 | E42: =SUMIF('Monthly Detail'!$4:$4, '2025 Overview (Budget)'!E$19, 'Monthly Detail'!95:95) -> 2.35 | F42: =SUMIF('Monthly Detail'!$4:$4, '2025 Overview (Budget)'!F$19, 'Monthly Detail'!95:95) -> 3.21 | G42: =SUMIF('Monthly Detail'!$4:$4, '2025 Overview (Budget)'!G$19, 'Monthly Detail'!95:95) -> 4.3 | H42: =SUMIF('Monthly Detail'!$4:$4, '2025 Overview (Budget)'!H$19, 'Monthly Detail'!95:95) -> 3.94 | I42: =SUMIF('Monthly Detail'!$4:$4, '2025 Overview (Budget)'!I$19, 'Monthly Detail'!95:95) -> 4.21 | J42: =SUMIF('Monthly Detail'!$4:$4, '2025 Overview (Budget)'!J$19, 'Monthly Detail'!95:95) -> 3.44 | ... M42: =SUMIF('Monthly Detail'!$4:$4, '2025 Overview (Budget)'!M$19, 'Monthly Detail'!95:95) -> 1.62 | N42: =SUMIF('Monthly Detail'!$4:$4, '2025 Overview (Budget)'!N$19, 'Monthly Detail'!130:130) -> 0 | P42: =SUM(C42:O42) -> 27.46
B43: Net Income | C43: =C39+SUM(C42:C42) -> 4061.87 | D43: =D39+SUM(D42:D42) -> 2138.42 | E43: =E39+SUM(E42:E42) -> 2441.33 | F43: =F39+SUM(F42:F42) -> 2100.19 | G43: =G39+SUM(G42:G42) -> 2268.4 | H43: =H39+SUM(H42:H42) -> 2850.05 | I43: =I39+SUM(I42:I42) -> 2937.64 | J43: =J39+SUM(J42:J42) -> 3073.82 | ... N43: =N39+SUM(N42:N42) -> 1050.4914 | P43: =P39+SUM(P42:P42) -> 28081.671
B44: NI % | C44: =IFERROR(C43/C22, 0) -> 0.60435051 | D44: =IFERROR(D43/D22, 0) -> 0.32893 | E44: =IFERROR(E43/E22, 0) -> 0.34343814 | F44: =IFERROR(F43/F22, 0) -> 0.26714027 | G44: =IFERROR(G43/G22, 0) -> 0.28795499 | H44: =IFERROR(H43/H22, 0) -> 0.41380337 | I44: =IFERROR(I43/I22, 0) -> 0.39598574 | J44: =IFERROR(J43/J22, 0) -> 0.40163066 | ... N44: =IFERROR(N43/N22, 0) -> 0.12256106 | P44: =P43/P22 -> 0.3302472
B46: Operating (Business) Cash | C46: =SUMIF('Monthly Detail'!$4:$4, '2025 Overview (Budget)'!C$19, 'Monthly Detail'!112:112) -> 1326.208 | D46: =SUMIF('Monthly Detail'!$4:$4, '2025 Overview (Budget)'!D$19, 'Monthly Detail'!112:112) -> 1606.7285 | E46: =SUMIF('Monthly Detail'!$4:$4, '2025 Overview (Budget)'!E$19, 'Monthly Detail'!112:112) -> 2203.006 | F46: =SUMIF('Monthly Detail'!$4:$4, '2025 Overview (Budget)'!F$19, 'Monthly Detail'!112:112) -> 2800.369 | G46: =SUMIF('Monthly Detail'!$4:$4, '2025 Overview (Budget)'!G$19, 'Monthly Detail'!112:112) -> 4253.561 | H46: =SUMIF('Monthly Detail'!$4:$4, '2025 Overview (Budget)'!H$19, 'Monthly Detail'!112:112) -> 4362.1695 | I46: =SUMIF('Monthly Detail'!$4:$4, '2025 Overview (Budget)'!I$19, 'Monthly Detail'!112:112) -> 4312.256 | J46: =SUMIF('Monthly Detail'!$4:$4, '2025 Overview (Budget)'!J$19, 'Monthly Detail'!112:112) -> 4650.8085 | ... M46: =SUMIF('Monthly Detail'!$4:$4, '2025 Overview (Budget)'!M$19, 'Monthly Detail'!112:112) -> 3478.683 | N46: =+'2025 AOP'!N46 -> 1694.3507
B47: Savings Cash | C47: =SUMIF('Monthly Detail'!$4:$4, '2025 Overview (Budget)'!C$19, 'Monthly Detail'!106:106) -> 45.02 | D47: =SUMIF('Monthly Detail'!$4:$4, '2025 Overview (Budget)'!D$19, 'Monthly Detail'!106:106) -> 68.56 | E47: =SUMIF('Monthly Detail'!$4:$4, '2025 Overview (Budget)'!E$19, 'Monthly Detail'!106:106) -> 0.03 | F47: =SUMIF('Monthly Detail'!$4:$4, '2025 Overview (Budget)'!F$19, 'Monthly Detail'!106:106) -> 9.57 | G47: =SUMIF('Monthly Detail'!$4:$4, '2025 Overview (Budget)'!G$19, 'Monthly Detail'!106:106) -> 150.5 | H47: =SUMIF('Monthly Detail'!$4:$4, '2025 Overview (Budget)'!H$19, 'Monthly Detail'!106:106) -> 17.12 | I47: =SUMIF('Monthly Detail'!$4:$4, '2025 Overview (Budget)'!I$19, 'Monthly Detail'!106:106) -> 50.77 | J47: =SUMIF('Monthly Detail'!$4:$4, '2025 Overview (Budget)'!J$19, 'Monthly Detail'!106:106) -> 0.77 | ... M47: =SUMIF('Monthly Detail'!$4:$4, '2025 Overview (Budget)'!M$19, 'Monthly Detail'!106:106) -> 0.77 | N47: =+'2025 AOP'!N47 -> 28.95
B48: Total Cash Balance | C48: =SUMIF('Monthly Detail'!$4:$4, '2025 Overview (Budget)'!C$19, 'Monthly Detail'!173:173) -> 2040.32 | D48: =SUMIF('Monthly Detail'!$4:$4, '2025 Overview (Budget)'!D$19, 'Monthly Detail'!173:173) -> 2471.89 | E48: =SUMIF('Monthly Detail'!$4:$4, '2025 Overview (Budget)'!E$19, 'Monthly Detail'!173:173) -> 3389.24 | F48: =SUMIF('Monthly Detail'!$4:$4, '2025 Overview (Budget)'!F$19, 'Monthly Detail'!173:173) -> 4308.26 | G48: =SUMIF('Monthly Detail'!$4:$4, '2025 Overview (Budget)'!G$19, 'Monthly Detail'!173:173) -> 6543.94 | H48: =SUMIF('Monthly Detail'!$4:$4, '2025 Overview (Budget)'!H$19, 'Monthly Detail'!173:173) -> 6711.03 | I48: =SUMIF('Monthly Detail'!$4:$4, '2025 Overview (Budget)'!I$19, 'Monthly Detail'!173:173) -> 6634.24 | J48: =SUMIF('Monthly Detail'!$4:$4, '2025 Overview (Budget)'!J$19, 'Monthly Detail'!173:173) -> 7155.09 | ... M48: =SUMIF('Monthly Detail'!$4:$4, '2025 Overview (Budget)'!M$19, 'Monthly Detail'!173:173) -> 5351.82 | N48: =+'2025 AOP'!N48 -> 2606.6934
B49: Total Cash Inflow (Outflow) | C49: =SUMIF('Monthly Detail'!$4:$4, '2025 Overview (Budget)'!C$19, 'Monthly Detail'!170:170) -> 614.32 | D49: =SUMIF('Monthly Detail'!$4:$4, '2025 Overview (Budget)'!D$19, 'Monthly Detail'!170:170) -> 431.57 | E49: =SUMIF('Monthly Detail'!$4:$4, '2025 Overview (Budget)'!E$19, 'Monthly Detail'!170:170) -> 917.35 | F49: =SUMIF('Monthly Detail'!$4:$4, '2025 Overview (Budget)'!F$19, 'Monthly Detail'!170:170) -> 919.02 | G49: =SUMIF('Monthly Detail'!$4:$4, '2025 Overview (Budget)'!G$19, 'Monthly Detail'!170:170) -> 2235.68 | H49: =SUMIF('Monthly Detail'!$4:$4, '2025 Overview (Budget)'!H$19, 'Monthly Detail'!170:170) -> 167.09 | I49: =SUMIF('Monthly Detail'!$4:$4, '2025 Overview (Budget)'!I$19, 'Monthly Detail'!170:170) -> -76.79 | J49: =SUMIF('Monthly Detail'!$4:$4, '2025 Overview (Budget)'!J$19, 'Monthly Detail'!170:170) -> 520.85 | ... M49: =SUMIF('Monthly Detail'!$4:$4, '2025 Overview (Budget)'!M$19, 'Monthly Detail'!170:170) -> -523.8 | N49: =+'2025 AOP'!N49 -> -500.55389
B50: Operating Cash Burn | C50: =-SUMIF('Monthly Detail'!$4:$4, '2025 Overview (Budget)'!C$19, 'Monthly Detail'!89:89) -> -2161.9 | D50: =-SUMIF('Monthly Detail'!$4:$4, '2025 Overview (Budget)'!D$19, 'Monthly Detail'!89:89) -> -3618.11 | E50: =-SUMIF('Monthly Detail'!$4:$4, '2025 Overview (Budget)'!E$19, 'Monthly Detail'!89:89) -> -3644.83 | F50: =-SUMIF('Monthly Detail'!$4:$4, '2025 Overview (Budget)'!F$19, 'Monthly Detail'!89:89) -> -5164.2 | G50: =-SUMIF('Monthly Detail'!$4:$4, '2025 Overview (Budget)'!G$19, 'Monthly Detail'!89:89) -> -3990.04 | H50: =-SUMIF('Monthly Detail'!$4:$4, '2025 Overview (Budget)'!H$19, 'Monthly Detail'!89:89) -> -3355.51 | I50: =-SUMIF('Monthly Detail'!$4:$4, '2025 Overview (Budget)'!I$19, 'Monthly Detail'!89:89) -> -3680.41 | J50: =-SUMIF('Monthly Detail'!$4:$4, '2025 Overview (Budget)'!J$19, 'Monthly Detail'!89:89) -> -3609.26 | ... M50: =-SUMIF('Monthly Detail'!$4:$4, '2025 Overview (Budget)'!M$19, 'Monthly Detail'!89:89) -> -3504.03 | N50: =+'2025 AOP'!N50 -> 6297.7867
B51: Owner Cash Burn/Allowance | C51: =SUMIF('Monthly Detail'!$4:$4, '2025 Overview (Budget)'!C$19, 'Monthly Detail'!154:154) -> -3116.58 | D51: =SUMIF('Monthly Detail'!$4:$4, '2025 Overview (Budget)'!D$19, 'Monthly Detail'!154:154) -> -1624.48 | E51: =SUMIF('Monthly Detail'!$4:$4, '2025 Overview (Budget)'!E$19, 'Monthly Detail'!154:154) -> -1433.72 | F51: =SUMIF('Monthly Detail'!$4:$4, '2025 Overview (Budget)'!F$19, 'Monthly Detail'!154:154) -> -1790.11 | G51: =SUMIF('Monthly Detail'!$4:$4, '2025 Overview (Budget)'!G$19, 'Monthly Detail'!154:154) -> -774.65 | H51: =SUMIF('Monthly Detail'!$4:$4, '2025 Overview (Budget)'!H$19, 'Monthly Detail'!154:154) -> -2413.31 | I51: =SUMIF('Monthly Detail'!$4:$4, '2025 Overview (Budget)'!I$19, 'Monthly Detail'!154:154) -> -3588.01 | J51: =SUMIF('Monthly Detail'!$4:$4, '2025 Overview (Budget)'!J$19, 'Monthly Detail'!154:154) -> -2335.22 | ... M51: =SUMIF('Monthly Detail'!$4:$4, '2025 Overview (Budget)'!M$19, 'Monthly Detail'!154:154) -> -1648.71 | N51: =+'2025 AOP'!N51 -> -1500
B52: Operating Cash Runway | C52: =+C46-SUM('Monthly Detail'!AC89:AN89)-SUM('Monthly Detail'!AC61:AN61) -> -32667.032 | D52: =+D46-SUM('Monthly Detail'!AD89:AO89)-SUM('Monthly Detail'!AD61:AO61) -> -35245.302 | E52: =+E46-SUM('Monthly Detail'!AE89:AP89)-SUM('Monthly Detail'!AE61:AP61) -> -37994.724 | F52: =+F46-SUM('Monthly Detail'!AF89:AQ89)-SUM('Monthly Detail'!AF61:AQ61) -> -41616.711 | G52: =+G46-SUM('Monthly Detail'!AG89:AR89)-SUM('Monthly Detail'!AG61:AR61) -> -41691.299 | H52: =+H46-SUM('Monthly Detail'!AH89:AS89)-SUM('Monthly Detail'!AH61:AS61) -> -42111.731 | I52: =+I46-SUM('Monthly Detail'!AI89:AT89)-SUM('Monthly Detail'!AI61:AT61) -> -44079.774 | J52: =+J46-SUM('Monthly Detail'!AJ89:AU89)-SUM('Monthly Detail'!AJ61:AU61) -> -44785.641 | ... M52: =+M46-SUM('Monthly Detail'!AM89:AX89)-SUM('Monthly Detail'!AM61:AX61) -> -49486.637 | N52: =+'2025 AOP'!N52 -> -83134.825
B53: Owner Cash Runway | C53: =+C48-SUM('Monthly Detail'!AC89:AN89)-SUM('Monthly Detail'!AC61:AN61) -> -31952.92 | D53: =+D48-SUM('Monthly Detail'!AD89:AO89)-SUM('Monthly Detail'!AD61:AO61) -> -34380.14 | E53: =+E48-SUM('Monthly Detail'!AE89:AP89)-SUM('Monthly Detail'!AE61:AP61) -> -36808.49 | F53: =+F48-SUM('Monthly Detail'!AF89:AQ89)-SUM('Monthly Detail'!AF61:AQ61) -> -40108.82 | G53: =+G48-SUM('Monthly Detail'!AG89:AR89)-SUM('Monthly Detail'!AG61:AR61) -> -39400.92 | H53: =+H48-SUM('Monthly Detail'!AH89:AS89)-SUM('Monthly Detail'!AH61:AS61) -> -39762.87 | I53: =+I48-SUM('Monthly Detail'!AI89:AT89)-SUM('Monthly Detail'!AI61:AT61) -> -41757.79 | J53: =+J48-SUM('Monthly Detail'!AJ89:AU89)-SUM('Monthly Detail'!AJ61:AU61) -> -42281.36 | ... M53: =+M48-SUM('Monthly Detail'!AM89:AX89)-SUM('Monthly Detail'!AM61:AX61) -> -47613.5 | N53: =+'2025 AOP'!N53 -> -82222.482
B54: Operating Cash Runway - Burn Rate | C54: =+C46/-C50 -> 0.61344558 | D54: =+D46/-D50 -> 0.44407951 | E54: =+E46/-E50 -> 0.60441941 | F54: =+F46/-F50 -> 0.54226579 | G54: =+G46/-G50 -> 1.0660447 | H54: =+H46/-H50 -> 1.3000019 | I54: =+I46/-I50 -> 1.1716782 | J54: =+J46/-J50 -> 1.2885767 | ... M54: =+M46/-M50 -> 0.99276633 | N54: =-'2025 AOP'!N54 -> 0.26903907
B55: Cash Runway - Owner Burn Rate | C55: =+IFERROR(C48/-C51, 0) -> 0.65466633 | D55: =+IFERROR(D48/-D51, 0) -> 1.52165 | E55: =+IFERROR(E48/-E51, 0) -> 2.3639483 | F55: =+IFERROR(F48/-F51, 0) -> 2.4067013 | G55: =+IFERROR(G48/-G51, 0) -> 8.4476086 | H55: =+IFERROR(H48/-H51, 0) -> 2.7808404 | I55: =+IFERROR(I48/-I51, 0) -> 1.8490027 | J55: =+IFERROR(J48/-J51, 0) -> 3.0639897 | ... M55: =+IFERROR(M48/-M51, 0) -> 3.2460651 | N55: =+'2025 AOP'!N55 -> 1.7377956

Sheet 2025 Overview
B15: 2025 Overview
C18: January | D18: February | E18: March | F18: April | G18: May | H18: June | I18: July | J18: August | K18: September | L18: October | M18: November | N18: December | P18: Total
C19: 45688 | D19: 45716 | E19: 45747 | F19: 45777 | G19: 45808 | H19: 45838 | I19: 45869 | J19: 45900 | K19: 45930 | L19: 45961 | M19: 45991 | N19: 46022 | O19: 45322
B20: Service Income | C20: =SUMIF('Monthly Detail'!$4:$4, '2025 Overview'!C$19, 'Monthly Detail'!13:13) -> 6721.05 | D20: =SUMIF('Monthly Detail'!$4:$4, '2025 Overview'!D$19, 'Monthly Detail'!13:13) -> 6501.14 | E20: =SUMIF('Monthly Detail'!$4:$4, '2025 Overview'!E$19, 'Monthly Detail'!13:13) -> 7108.5 | F20: =SUMIF('Monthly Detail'!$4:$4, '2025 Overview'!F$19, 'Monthly Detail'!13:13) -> 7861.75 | G20: =SUMIF('Monthly Detail'!$4:$4, '2025 Overview'!G$19, 'Monthly Detail'!13:13) -> 7877.62 | H20: =SUMIF('Monthly Detail'!$4:$4, '2025 Overview'!H$19, 'Monthly Detail'!13:13) -> 6887.45 | I20: =SUMIF('Monthly Detail'!$4:$4, '2025 Overview'!I$19, 'Monthly Detail'!13:13) -> 7418.55 | J20: =SUMIF('Monthly Detail'!$4:$4, '2025 Overview'!J$19, 'Monthly Detail'!13:13) -> 7653.35 | ... N20: =SUMIF('Monthly Detail'!$4:$4, '2025 Overview'!N$19, 'Monthly Detail'!13:13) -> 5570.0825 | P20: =SUM(C20:O20) -> 82031.193
B21: Misc. | C21: =SUMIF('Monthly Detail'!$4:$4, '2025 Overview'!C$19, 'Monthly Detail'!12:12) -> 0 | D21: =SUMIF('Monthly Detail'!$4:$4, '2025 Overview'!D$19, 'Monthly Detail'!12:12) -> 0 | E21: =SUMIF('Monthly Detail'!$4:$4, '2025 Overview'!E$19, 'Monthly Detail'!12:12) -> 0 | F21: =SUMIF('Monthly Detail'!$4:$4, '2025 Overview'!F$19, 'Monthly Detail'!12:12) -> 0 | G21: =SUMIF('Monthly Detail'!$4:$4, '2025 Overview'!G$19, 'Monthly Detail'!12:12) -> 0 | H21: =SUMIF('Monthly Detail'!$4:$4, '2025 Overview'!H$19, 'Monthly Detail'!12:12) -> 0 | I21: =SUMIF('Monthly Detail'!$4:$4, '2025 Overview'!I$19, 'Monthly Detail'!12:12) -> 0 | J21: =SUMIF('Monthly Detail'!$4:$4, '2025 Overview'!J$19, 'Monthly Detail'!12:12) -> 0 | ... N21: =SUMIF('Monthly Detail'!$4:$4, '2025 Overview'!N$19, 'Monthly Detail'!12:12) -> 0 | P21: =SUM(C21:O21) -> 0
B22: Total Income | C22: =SUM(C20:C21) -> 6721.05 | D22: =SUM(D20:D21) -> 6501.14 | E22: =SUM(E20:E21) -> 7108.5 | F22: =SUM(F20:F21) -> 7861.75 | G22: =SUM(G20:G21) -> 7877.62 | H22: =SUM(H20:H21) -> 6887.45 | I22: =SUM(I20:I21) -> 7418.55 | J22: =SUM(J20:J21) -> 7653.35 | ... N22: =SUM(N20:N21) -> 5570.0825 | P22: =SUM(P20:P20) -> 82031.193
B23: # of Appointments | C23: =SUMIF('Monthly Detail'!$4:$4, '2025 Overview'!C$19, 'Monthly Detail'!15:15) -> 66 | D23: =SUMIF('Monthly Detail'!$4:$4, '2025 Overview'!D$19, 'Monthly Detail'!15:15) -> 69 | E23: =SUMIF('Monthly Detail'!$4:$4, '2025 Overview'!E$19, 'Monthly Detail'!15:15) -> 68 | F23: =SUMIF('Monthly Detail'!$4:$4, '2025 Overview'!F$19, 'Monthly Detail'!15:15) -> 82 | G23: =SUMIF('Monthly Detail'!$4:$4, '2025 Overview'!G$19, 'Monthly Detail'!15:15) -> 83 | H23: =SUMIF('Monthly Detail'!$4:$4, '2025 Overview'!H$19, 'Monthly Detail'!15:15) -> 72 | I23: =SUMIF('Monthly Detail'!$4:$4, '2025 Overview'!I$19, 'Monthly Detail'!15:15) -> 76 | J23: =SUMIF('Monthly Detail'!$4:$4, '2025 Overview'!J$19, 'Monthly Detail'!15:15) -> 73 | ... N23: =SUMIF('Monthly Detail'!$4:$4, '2025 Overview'!N$19, 'Monthly Detail'!15:15) -> 43.837906 | P23: =+SUM(C23:N23) -> 823.83791
B24: MRR | C24: =SUMIF('Monthly Detail'!$4:$4, '2025 Overview'!C$19, 'Monthly Detail'!41:41) -> 4460.105 | D24: =SUMIF('Monthly Detail'!$4:$4, '2025 Overview'!D$19, 'Monthly Detail'!41:41) -> 4123.6763 | E24: =SUMIF('Monthly Detail'!$4:$4, '2025 Overview'!E$19, 'Monthly Detail'!41:41) -> 3775.4392 | F24: =SUMIF('Monthly Detail'!$4:$4, '2025 Overview'!F$19, 'Monthly Detail'!41:41) -> 4062.1519 | G24: =SUMIF('Monthly Detail'!$4:$4, '2025 Overview'!G$19, 'Monthly Detail'!41:41) -> 4083.8286 | H24: =SUMIF('Monthly Detail'!$4:$4, '2025 Overview'!H$19, 'Monthly Detail'!41:41) -> 4773.1964 | I24: =SUMIF('Monthly Detail'!$4:$4, '2025 Overview'!I$19, 'Monthly Detail'!41:41) -> 4270.3349 | J24: =SUMIF('Monthly Detail'!$4:$4, '2025 Overview'!J$19, 'Monthly Detail'!41:41) -> 4966.1738 | ... N24: =SUMIF('Monthly Detail'!$4:$4, '2025 Overview'!N$19, 'Monthly Detail'!41:41) -> 3824.6282 | P24: =+AVERAGE(C24:N24) -> 4298.4094
B25: Recurring Client Base | C25: =SUMIF('Monthly Detail'!$4:$4, '2025 Overview'!C$19, 'Monthly Detail'!17:17) -> 35 | D25: =SUMIF('Monthly Detail'!$4:$4, '2025 Overview'!D$19, 'Monthly Detail'!17:17) -> 32 | E25: =SUMIF('Monthly Detail'!$4:$4, '2025 Overview'!E$19, 'Monthly Detail'!17:17) -> 31 | F25: =SUMIF('Monthly Detail'!$4:$4, '2025 Overview'!F$19, 'Monthly Detail'!17:17) -> 30 | G25: =SUMIF('Monthly Detail'!$4:$4, '2025 Overview'!G$19, 'Monthly Detail'!17:17) -> 38 | H25: =SUMIF('Monthly Detail'!$4:$4, '2025 Overview'!H$19, 'Monthly Detail'!17:17) -> 37 | I25: =SUMIF('Monthly Detail'!$4:$4, '2025 Overview'!I$19, 'Monthly Detail'!17:17) -> 34 | J25: =SUMIF('Monthly Detail'!$4:$4, '2025 Overview'!J$19, 'Monthly Detail'!17:17) -> 32 | ... N25: =SUMIF('Monthly Detail'!$4:$4, '2025 Overview'!N$19, 'Monthly Detail'!17:17) -> 23.588767
B28: Software - COS | C28: =SUMIF('Monthly Detail'!$4:$4, '2025 Overview'!C$19, 'Monthly Detail'!58:58) -> 197.3 | D28: =SUMIF('Monthly Detail'!$4:$4, '2025 Overview'!D$19, 'Monthly Detail'!58:58) -> 202.11 | E28: =SUMIF('Monthly Detail'!$4:$4, '2025 Overview'!E$19, 'Monthly Detail'!58:58) -> 214.54 | F28: =SUMIF('Monthly Detail'!$4:$4, '2025 Overview'!F$19, 'Monthly Detail'!58:58) -> 247.79 | G28: =SUMIF('Monthly Detail'!$4:$4, '2025 Overview'!G$19, 'Monthly Detail'!58:58) -> 240.23 | H28: =SUMIF('Monthly Detail'!$4:$4, '2025 Overview'!H$19, 'Monthly Detail'!58:58) -> 182.1 | I28: =SUMIF('Monthly Detail'!$4:$4, '2025 Overview'!I$19, 'Monthly Detail'!58:58) -> 216.6 | J28: =SUMIF('Monthly Detail'!$4:$4, '2025 Overview'!J$19, 'Monthly Detail'!58:58) -> 205.55 | ... N28: =SUMIF('Monthly Detail'!$4:$4, '2025 Overview'!N$19, 'Monthly Detail'!58:58) -> 191.16697 | P28: =+SUM(C28:N28) -> 2649.577
B29: Materials - COGS | C29: =SUMIF('Monthly Detail'!$4:$4, '2025 Overview'!C$19, 'Monthly Detail'!59:59) -> 249.98 | D29: =SUMIF('Monthly Detail'!$4:$4, '2025 Overview'!D$19, 'Monthly Detail'!59:59) -> 497.5 | E29: =SUMIF('Monthly Detail'!$4:$4, '2025 Overview'!E$19, 'Monthly Detail'!59:59) -> 810.15 | F29: =SUMIF('Monthly Detail'!$4:$4, '2025 Overview'!F$19, 'Monthly Detail'!59:59) -> 352.78 | G29: =SUMIF('Monthly Detail'!$4:$4, '2025 Overview'!G$19, 'Monthly Detail'!59:59) -> 754.25 | H29: =SUMIF('Monthly Detail'!$4:$4, '2025 Overview'!H$19, 'Monthly Detail'!59:59) -> 503.73 | I29: =SUMIF('Monthly Detail'!$4:$4, '2025 Overview'!I$19, 'Monthly Detail'!59:59) -> 588.11 | J29: =SUMIF('Monthly Detail'!$4:$4, '2025 Overview'!J$19, 'Monthly Detail'!59:59) -> 768.16 | ... N29: =SUMIF('Monthly Detail'!$4:$4, '2025 Overview'!N$19, 'Monthly Detail'!59:59) -> 539.06513 | P29: =+SUM(C29:N29) -> 7064.2451
B30: Contractors - COS | C30: =SUMIF('Monthly Detail'!$4:$4, '2025 Overview'!C$19, 'Monthly Detail'!60:60) -> 50 | D30: =SUMIF('Monthly Detail'!$4:$4, '2025 Overview'!D$19, 'Monthly Detail'!60:60) -> 45 | E30: =SUMIF('Monthly Detail'!$4:$4, '2025 Overview'!E$19, 'Monthly Detail'!60:60) -> 0 | F30: =SUMIF('Monthly Detail'!$4:$4, '2025 Overview'!F$19, 'Monthly Detail'!60:60) -> 0 | G30: =SUMIF('Monthly Detail'!$4:$4, '2025 Overview'!G$19, 'Monthly Detail'!60:60) -> 629 | H30: =SUMIF('Monthly Detail'!$4:$4, '2025 Overview'!H$19, 'Monthly Detail'!60:60) -> 0 | I30: =SUMIF('Monthly Detail'!$4:$4, '2025 Overview'!I$19, 'Monthly Detail'!60:60) -> 0 | J30: =SUMIF('Monthly Detail'!$4:$4, '2025 Overview'!J$19, 'Monthly Detail'!60:60) -> 0 | ... N30: =SUMIF('Monthly Detail'!$4:$4, '2025 Overview'!N$19, 'Monthly Detail'!60:60) -> 333.46155 | P30: =+SUM(C30:N30) -> 1087.4616
B31: Total Cost of Goods Sold (COGS) | C31: =SUM(C28:C30) -> 497.28 | D31: =SUM(D28:D30) -> 744.61 | E31: =SUM(E28:E30) -> 1024.69 | F31: =SUM(F28:F30) -> 600.57 | G31: =SUM(G28:G30) -> 1623.48 | H31: =SUM(H28:H30) -> 685.83 | I31: =SUM(I28:I30) -> 804.71 | J31: =SUM(J28:J30) -> 973.71 | ... N31: =SUM(N28:N30) -> 1063.6936 | P31: =SUM(P28:P30) -> 10801.284
B33: Gross Margin | C33: =+C22-C31 -> 6223.77 | D33: =+D22-D31 -> 5756.53 | E33: =+E22-E31 -> 6083.81 | F33: =+F22-F31 -> 7261.18 | G33: =+G22-G31 -> 6254.14 | H33: =+H22-H31 -> 6201.62 | I33: =+I22-I31 -> 6613.84 | J33: =+J22-J31 -> 6679.64 | ... N33: =+N22-N31 -> 4506.3889 | P33: =+SUM(C33:N33) -> 71229.909
B34: GM % | C34: =IFERROR(C33/C22, 0) -> 0.92601156 | D34: =IFERROR(D33/D22, 0) -> 0.8854647 | E34: =IFERROR(E33/E22, 0) -> 0.85585004 | F34: =IFERROR(F33/F22, 0) -> 0.92360861 | G34: =IFERROR(G33/G22, 0) -> 0.79391237 | H34: =IFERROR(H33/H22, 0) -> 0.90042323 | I34: =IFERROR(I33/I22, 0) -> 0.89152732 | J34: =IFERROR(J33/J22, 0) -> 0.87277336 | ... N34: =IFERROR(N33/N22, 0) -> 0.80903449 | P34: =P33/P22 -> 0.86832712
B36: General & Admintrative Expenses | C36: =SUMIF('Monthly Detail'!$4:$4, '2025 Overview'!C$19, 'Monthly Detail'!$89:$89)+SUMIF('Monthly Detail'!$4:$4, '2025 Overview'!C$19, 'Monthly Detail'!$90:$90) -> 2161.9 | D36: =SUMIF('Monthly Detail'!$4:$4, '2025 Overview'!D$19, 'Monthly Detail'!$89:$89)+SUMIF('Monthly Detail'!$4:$4, '2025 Overview'!D$19, 'Monthly Detail'!$90:$90) -> 3618.11 | E36: =SUMIF('Monthly Detail'!$4:$4, '2025 Overview'!E$19, 'Monthly Detail'!$89:$89)+SUMIF('Monthly Detail'!$4:$4, '2025 Overview'!E$19, 'Monthly Detail'!$90:$90) -> 3644.83 | F36: =SUMIF('Monthly Detail'!$4:$4, '2025 Overview'!F$19, 'Monthly Detail'!$89:$89)+SUMIF('Monthly Detail'!$4:$4, '2025 Overview'!F$19, 'Monthly Detail'!$90:$90) -> 5164.2 | G36: =SUMIF('Monthly Detail'!$4:$4, '2025 Overview'!G$19, 'Monthly Detail'!$89:$89)+SUMIF('Monthly Detail'!$4:$4, '2025 Overview'!G$19, 'Monthly Detail'!$90:$90) -> 3990.04 | H36: =SUMIF('Monthly Detail'!$4:$4, '2025 Overview'!H$19, 'Monthly Detail'!$89:$89)+SUMIF('Monthly Detail'!$4:$4, '2025 Overview'!H$19, 'Monthly Detail'!$90:$90) -> 3355.51 | I36: =SUMIF('Monthly Detail'!$4:$4, '2025 Overview'!I$19, 'Monthly Detail'!$89:$89)+SUMIF('Monthly Detail'!$4:$4, '2025 Overview'!I$19, 'Monthly Detail'!$90:$90) -> 3680.41 | J36: =SUMIF('Monthly Detail'!$4:$4, '2025 Overview'!J$19, 'Monthly Detail'!$89:$89)+SUMIF('Monthly Detail'!$4:$4, '2025 Overview'!J$19, 'Monthly Detail'!$90:$90) -> 3609.26 | ... N36: =SUMIF('Monthly Detail'!$4:$4, '2025 Overview'!N$19, 'Monthly Detail'!$89:$89)+SUMIF('Monthly Detail'!$4:$4, '2025 Overview'!N$19, 'Monthly Detail'!$90:$90) -> 5115.7333 | P36: =SUM(C36:O36) -> 44835.533
B37: Operating Expenses | C37: =SUM(C36:C36) -> 2161.9 | D37: =SUM(D36:D36) -> 3618.11 | E37: =SUM(E36:E36) -> 3644.83 | F37: =SUM(F36:F36) -> 5164.2 | G37: =SUM(G36:G36) -> 3990.04 | H37: =SUM(H36:H36) -> 3355.51 | I37: =SUM(I36:I36) -> 3680.41 | J37: =SUM(J36:J36) -> 3609.26 | ... N37: =SUM(N36:N36) -> 5115.7333 | P37: =SUM(P36:P36) -> 44835.533
B39: Net Operating Income (EBITDA) | C39: =C33-C37 -> 4061.87 | D39: =D33-D37 -> 2138.42 | E39: =E33-E37 -> 2438.98 | F39: =F33-F37 -> 2096.98 | G39: =G33-G37 -> 2264.1 | H39: =H33-H37 -> 2846.11 | I39: =I33-I37 -> 2933.43 | J39: =J33-J37 -> 3070.38 | ... N39: =N33-N37 -> -609.34447 | P39: =P33-P37 -> 26394.376
B40: EBITDA % | C40: =IFERROR(C39/C22, 0) -> 0.60435051 | D40: =IFERROR(D39/D22, 0) -> 0.32893 | E40: =IFERROR(E39/E22, 0) -> 0.34310755 | F40: =IFERROR(F39/F22, 0) -> 0.26673196 | G40: =IFERROR(G39/G22, 0) -> 0.28740914 | H40: =IFERROR(H39/H22, 0) -> 0.41323131 | I40: =IFERROR(I39/I22, 0) -> 0.39541824 | J40: =IFERROR(J39/J22, 0) -> 0.40118118 | ... N40: =IFERROR(N39/N22, 0) -> -0.10939595 | P40: =P39/P22 -> 0.32176023
B42: Other Income / (Expense) | C42: =SUMIF('Monthly Detail'!$4:$4, '2025 Overview'!C$19, 'Monthly Detail'!95:95) -> 0 | D42: =SUMIF('Monthly Detail'!$4:$4, '2025 Overview'!D$19, 'Monthly Detail'!95:95) -> 0 | E42: =SUMIF('Monthly Detail'!$4:$4, '2025 Overview'!E$19, 'Monthly Detail'!95:95) -> 2.35 | F42: =SUMIF('Monthly Detail'!$4:$4, '2025 Overview'!F$19, 'Monthly Detail'!95:95) -> 3.21 | G42: =SUMIF('Monthly Detail'!$4:$4, '2025 Overview'!G$19, 'Monthly Detail'!95:95) -> 4.3 | H42: =SUMIF('Monthly Detail'!$4:$4, '2025 Overview'!H$19, 'Monthly Detail'!95:95) -> 3.94 | I42: =SUMIF('Monthly Detail'!$4:$4, '2025 Overview'!I$19, 'Monthly Detail'!95:95) -> 4.21 | J42: =SUMIF('Monthly Detail'!$4:$4, '2025 Overview'!J$19, 'Monthly Detail'!95:95) -> 3.44 | ... N42: =SUMIF('Monthly Detail'!$4:$4, '2025 Overview'!N$19, 'Monthly Detail'!95:95) -> 1.62 | P42: =SUM(C42:O42) -> 29.08
B43: Net Income | C43: =C39+SUM(C42:C42) -> 4061.87 | D43: =D39+SUM(D42:D42) -> 2138.42 | E43: =E39+SUM(E42:E42) -> 2441.33 | F43: =F39+SUM(F42:F42) -> 2100.19 | G43: =G39+SUM(G42:G42) -> 2268.4 | H43: =H39+SUM(H42:H42) -> 2850.05 | I43: =I39+SUM(I42:I42) -> 2937.64 | J43: =J39+SUM(J42:J42) -> 3073.82 | ... N43: =N39+SUM(N42:N42) -> -607.72447 | P43: =P39+SUM(P42:P42) -> 26423.456
B44: NI % | C44: =IFERROR(C43/C22, 0) -> 0.60435051 | D44: =IFERROR(D43/D22, 0) -> 0.32893 | E44: =IFERROR(E43/E22, 0) -> 0.34343814 | F44: =IFERROR(F43/F22, 0) -> 0.26714027 | G44: =IFERROR(G43/G22, 0) -> 0.28795499 | H44: =IFERROR(H43/H22, 0) -> 0.41380337 | I44: =IFERROR(I43/I22, 0) -> 0.39598574 | J44: =IFERROR(J43/J22, 0) -> 0.40163066 | ... N44: =IFERROR(N43/N22, 0) -> -0.10910511 | P44: =P43/P22 -> 0.32211473
B46: Operating (Business) Cash | C46: =SUMIF('Monthly Detail'!$4:$4, '2025 Overview'!C$19, 'Monthly Detail'!112:112) -> 1326.208 | D46: =SUMIF('Monthly Detail'!$4:$4, '2025 Overview'!D$19, 'Monthly Detail'!112:112) -> 1606.7285 | E46: =SUMIF('Monthly Detail'!$4:$4, '2025 Overview'!E$19, 'Monthly Detail'!112:112) -> 2203.006 | F46: =SUMIF('Monthly Detail'!$4:$4, '2025 Overview'!F$19, 'Monthly Detail'!112:112) -> 2800.369 | G46: =SUMIF('Monthly Detail'!$4:$4, '2025 Overview'!G$19, 'Monthly Detail'!112:112) -> 4253.561 | H46: =SUMIF('Monthly Detail'!$4:$4, '2025 Overview'!H$19, 'Monthly Detail'!112:112) -> 4362.1695 | I46: =SUMIF('Monthly Detail'!$4:$4, '2025 Overview'!I$19, 'Monthly Detail'!112:112) -> 4312.256 | J46: =SUMIF('Monthly Detail'!$4:$4, '2025 Overview'!J$19, 'Monthly Detail'!112:112) -> 4650.8085 | ... N46: =SUMIF('Monthly Detail'!$4:$4, '2025 Overview'!N$19, 'Monthly Detail'!112:112) -> 4089.7758
B47: Savings Cash | C47: =SUMIF('Monthly Detail'!$4:$4, '2025 Overview'!C$19, 'Monthly Detail'!106:106) -> 45.02 | D47: =SUMIF('Monthly Detail'!$4:$4, '2025 Overview'!D$19, 'Monthly Detail'!106:106) -> 68.56 | E47: =SUMIF('Monthly Detail'!$4:$4, '2025 Overview'!E$19, 'Monthly Detail'!106:106) -> 0.03 | F47: =SUMIF('Monthly Detail'!$4:$4, '2025 Overview'!F$19, 'Monthly Detail'!106:106) -> 9.57 | G47: =SUMIF('Monthly Detail'!$4:$4, '2025 Overview'!G$19, 'Monthly Detail'!106:106) -> 150.5 | H47: =SUMIF('Monthly Detail'!$4:$4, '2025 Overview'!H$19, 'Monthly Detail'!106:106) -> 17.12 | I47: =SUMIF('Monthly Detail'!$4:$4, '2025 Overview'!I$19, 'Monthly Detail'!106:106) -> 50.77 | J47: =SUMIF('Monthly Detail'!$4:$4, '2025 Overview'!J$19, 'Monthly Detail'!106:106) -> 0.77 | ... N47: =SUMIF('Monthly Detail'!$4:$4, '2025 Overview'!N$19, 'Monthly Detail'!106:106) -> 0.77
B48: Total Cash Balance | C48: =SUMIF('Monthly Detail'!$4:$4, '2025 Overview'!C$19, 'Monthly Detail'!173:173) -> 2040.32 | D48: =SUMIF('Monthly Detail'!$4:$4, '2025 Overview'!D$19, 'Monthly Detail'!173:173) -> 2471.89 | E48: =SUMIF('Monthly Detail'!$4:$4, '2025 Overview'!E$19, 'Monthly Detail'!173:173) -> 3389.24 | F48: =SUMIF('Monthly Detail'!$4:$4, '2025 Overview'!F$19, 'Monthly Detail'!173:173) -> 4308.26 | G48: =SUMIF('Monthly Detail'!$4:$4, '2025 Overview'!G$19, 'Monthly Detail'!173:173) -> 6543.94 | H48: =SUMIF('Monthly Detail'!$4:$4, '2025 Overview'!H$19, 'Monthly Detail'!173:173) -> 6711.03 | I48: =SUMIF('Monthly Detail'!$4:$4, '2025 Overview'!I$19, 'Monthly Detail'!173:173) -> 6634.24 | J48: =SUMIF('Monthly Detail'!$4:$4, '2025 Overview'!J$19, 'Monthly Detail'!173:173) -> 7155.09 | ... N48: =SUMIF('Monthly Detail'!$4:$4, '2025 Overview'!N$19, 'Monthly Detail'!173:173) -> 6291.9628 | P48: =+(SUM(C43:E43)*0.153)-SUM('Monthly Detail'!AO69:AP69) -> 1114.2779
